Workbook

Sheet LM
A2: LISTADO MAESTRO DE MANTENIMIENTOS
A4: EQUIPO | C4: % | D4: PLANTA
A5: 01 | B5: Sistema de Control de Emisiones (Horno Granulador) | C5: ='01'!AC6 -> 0 | D5: PLANTA 1
A6: 02 | B6: Sistema de Control de Emisiones (Molino) | C6: ='02'!AC6 -> 0.0039370079
A7: 03 | B7: Mezcladora Planta 1 | C7: ='03'!AC6 -> 0
A8: 04 | B8: Olla Granuladora Planta | C8: ='04'!AC6 -> 0
A9: 05 | B9: Tubo Secador | C9: ='05'!AC6 -> 0
A10: 06 | B10: Quemador | C10: ='06'!AC6 -> 0
A11: 07 | B11: Separador de Finos | C11: ='07'!AC6 -> 0
A12: 08 | B12: Molino | C12: ='08'!AC6 -> 0
A13: 09 | B13: Tubo Enfriador | C13: ='09'!AC6 -> 0
A14: 10 | B14: Bandas Transportadoras | C14: ='10'!AC6 -> 0
A16: 11 | B16: Mezcladora Planta 2 | C16: ='11'!AC6 -> 0 | D16: PLANTA 2
A17: 12 | B17: Olla Granuladora 2 | C17: ='12'!AC6 -> 0
A18: 13 | B18: Tubo Secador | C18: ='13'!AC6 -> 0
A19: 14 | B19: Quemador | C19: ='14'!AC6 -> 0
A20: 15 | B20: Separador de Finos | C20: ='15'!AC6 -> 0
A21: 16 | B21: Molino | C21: ='16'!AC6 -> 0
A22: 17 | B22: Tubo Enfriador | C22: ='17'!AC6 -> 0
A23: 18 | B23: Bandas Transportadoras | C23: ='18'!AC6 -> 0
A25: 19 | B25: Montacargas HIUNDAY 45D-9S | C25: ='19'!AC6 -> #DIV/0! | D25: MONTACARGAS
A26: 20 | B26: Montacargas HIUNDAY 45D-S7E | C26: ='20'!AC6 -> #DIV/0!
A27: 21 | B27: Montacargas CATERPILLAR | C27: ='21'!AC6 -> #DIV/0!

Sheet 01
D1: SISTEMA DE GESTIÓN INTEGRAL HOJA DE VIDA Y MANTENIMIENTO DE SISTEMAS DE CONTROL DE EMISIONES | AE1: SC
AE2: SS
D3: CODIGO: RC-SI55 | P3: VERSIÓN: 0
B6: ID. SISTEMA | E6: 01 | F6: Fuente 1: SISTEMA DE CONTROL DE EMISIONES (HORNO GRANULADOR) | AC6: =AVERAGE(I20:AF31) -> 0
A8: INFORMACION GENERAL
R9: FOTOGRAFIA SISTEMA DE CONTROL
B10: Marca | D10: INDIMARCK RIELLO RS70 | G10: Altura Chimenea | K10: 7 Metros
B11: Fecha Fabricación | D11: 2022 | G11: Diámetro Chimenea | K11: 0,370 Metros
B12: Tío de Ducto | D12: Circular | G12: Distancia A | K12: 3.5
B13: Tipo de Combustible | D13: Gas Propano | G13: Distancia B | K13: 0.19
B14: Horas operación/día | D14: 16 Horas | G14: Plataforma | K14: SI
B15: Sistema de Control | D15: Ciclón | G15: Escalera de Acceso | K15: NO
A17: MANTENIMIENTO PREVENTIVO 2025 Marque con "0" los tiempos en los que se programará el mantenimiento; marque "1" cuando los mantenimientos se hayan cumplido | AC17: CARGUE DE EVIDENCIAS
A19: ACTIIDAD | I19: ENE | K19: FEB | M19: MAR | O19: ABR | Q19: MAY | S19: JUN | U19: JUL | W19: AGO | Y19: SEP | AA19: OCT | AC19: NOV | AE19: DIC
A20: Engrase de Rodamientos de la Turbina | G20: Semanal | I20: S1 | J20: S2 | K20: S1 | L20: S2 | M20: S1 | N20: S2 | O20: 0 | P20: 0 | Q20: 0 | R20: 0 | S20: 0 | T20: 0 | U20: 0 | V20: 0 | W20: 0 | X20: 0 | Y20: 0 | Z20: 0 | AA20: 0 | AB20: 0 | AC20: 0 | AD20: 0 | AE20: 0 | AF20: 0
I21: S3 | J21: S4 | K21: S3 | L21: S4 | M21: S3 | N21: S4 | O21: 0 | P21: 0 | Q21: 0 | R21: 0 | S21: 0 | T21: 0 | U21: 0 | V21: 0 | W21: 0 | X21: 0 | Y21: 0 | Z21: 0 | AA21: 0 | AB21: 0 | AC21: 0 | AD21: 0 | AE21: 0 | AF21: 0
A22: Limpieza de Ventilador | G22: Semanal | I22: S1 | J22: S2 | K22: S1 | L22: S2 | M22: S1 | N22: S2 | O22: 0 | P22: 0 | Q22: 0 | R22: 0 | S22: 0 | T22: 0 | U22: 0 | V22: 0 | W22: 0 | X22: 0 | Y22: 0 | Z22: 0 | AA22: 0 | AB22: 0 | AC22: 0 | AD22: 0 | AE22: 0 | AF22: 0
I23: S3 | J23: S4 | K23: S3 | L23: S4 | M23: S3 | N23: S4 | O23: 0 | P23: 0 | Q23: 0 | R23: 0 | S23: 0 | T23: 0 | U23: 0 | V23: 0 | W23: 0 | X23: 0 | Y23: 0 | Z23: 0 | AA23: 0 | AB23: 0 | AC23: 0 | AD23: 0 | AE23: 0 | AF23: 0
A24: Limpieza de Ciclón | G24: Semanal | I24: S1 | J24: S2 | K24: S1 | L24: S2 | M24: S1 | N24: S2 | O24: 0 | P24: 0 | Q24: 0 | R24: 0 | S24: 0 | T24: 0 | U24: 0 | V24: 0 | W24: 0 | X24: 0 | Y24: 0 | Z24: 0 | AA24: 0 | AB24: 0 | AC24: 0 | AD24: 0 | AE24: 0 | AF24: 0
I25: S3 | J25: S4 | K25: S3 | L25: S4 | M25: S3 | N25: S4 | O25: 0 | P25: 0 | Q25: 0 | R25: 0 | S25: 0 | T25: 0 | U25: 0 | V25: 0 | W25: 0 | X25: 0 | Y25: 0 | Z25: 0 | AA25: 0 | AB25: 0 | AC25: 0 | AD25: 0 | AE25: 0 | AF25: 0
A26: Cambio de Valvulina | G26: Semestral | I26: S1 | J26: S2 | K26: S1 | L26: S2 | M26: S1 | N26: S2 | O26: 0 | P26: 0 | Q26: 0 | R26: 0 | S26: 0 | T26: 0 | U26: 0 | V26: 0 | W26: 0 | X26: 0 | Y26: 0 | Z26: 0 | AA26: 0 | AB26: 0 | AC26: 0 | AD26: 0 | AE26: 0 | AF26: 0
I27: S3 | J27: S4 | K27: S3 | L27: S4 | M27: S3 | N27: S4 | O27: 0 | P27: 0 | Q27: 0 | R27: 0 | S27: 0 | T27: 0 | U27: 0 | V27: 0 | W27: 0 | X27: 0 | Y27: 0 | Z27: 0 | AA27: 0 | AB27: 0 | AC27: 0 | AD27: 0 | AE27: 0 | AF27: 0
A28: Revisión de Correas del Ciclón | G28: QUINCENAL | I28: S1 | J28: S2 | K28: S1 | L28: S2 | M28: S1 | N28: S2 | O28: S1 | P28: S2 | Q28: S1 | R28: 0 | S28: S1 | T28: 0 | U28: S1 | V28: 0 | W28: S1 | X28: 0 | Y28: S1 | Z28: 0 | AA28: S1 | AB28: 0 | AC28: S1 | AD28: 0 | AE28: S1 | AF28: 0
I29: S3 | J29: S4 | K29: S3 | L29: S4 | M29: S3 | N29: S4 | O29: S3 | P29: 0 | Q29: S3 | R29: 0 | S29: S3 | T29: 0 | U29: S3 | V29: 0 | W29: S3 | X29: 0 | Y29: S3 | Z29: 0 | AA29: S3 | AB29: 0 | AC29: S3 | AD29: 0 | AE29: S3 | AF29: 0
A30: Revisión de Tuberías | G30: Bimensual | I30: S1 | J30: S2 | K30: S1 | L30: S2 | M30: S1 | N30: S2 | O30: S1 | P30: S2 | Q30: S1 | R30: S2 | S30: S1 | T30: S2 | U30: S1 | V30: S2 | W30: S1 | X30: S2 | Y30: S1 | Z30: S2 | AA30: S1 | AB30: S2 | AC30: S1 | AD30: S2 | AE30: S1 | AF30: S2
I31: S3 | J31: S4 | K31: S3 | L31: S4 | M31: S3 | N31: S4 | O31: S3 | P31: 0 | Q31: S3 | R31: S4 | S31: S3 | T31: 0 | U31: S3 | V31: S4 | W31: S3 | X31: 0 | Y31: S3 | Z31: S4 | AA31: S3 | AB31: 0 | AC31: S3 | AD31: S4 | AE31: S3 | AF31: 0
B33: RELACION DEL MANTENIMIENTOS CORRECTIVOS / PREVENTIVOS
B34: N° | C34: FECHA | D34: PROVEEDOR | G34: TIPO MTO | I34: INTERVENCIÓN | M34: DETALLES DEL MANTENIIMIENTO | AA34: RESPONSABLE
G35: PV | H35: CT | I35: Int. | K35: Ext.
B36: M1
B37: M2
B38: M3
B39: M4
B40: M5
B41: M6
B42: M7
B43: M8

Sheet 02
D1: SISTEMA DE GESTIÓN INTEGRAL HOJA DE VIDA Y MANTENIMIENTO DE SISTEMAS DE CONTROL DE EMISIONES | AE1: SC
AE2: SS
D3: CODIGO: RC-SI55 | P3: VERSIÓN: 0
B6: ID. SISTEMA | E6: 02 | F6: Fuente 1: SISTEMA DE CONTROL DE EMISIONES (MOLINO) | AC6: =AVERAGE(I20:AF35) -> 0.0039370079
A8: INFORMACION GENERAL
R9: FOTOGRAFIA SISTEMA DE CONTROL
B10: Marca | D10: No identifica | G10: Altura Chimenea | K10: 7,32 Metros
B11: Fecha Fabricación | D11: 2022 | G11: Diámetro Chimenea | K11: 0.388
B12: Tío de Ducto | D12: Circular | G12: Distancia A | K12: 4.02
B13: Tipo de Combustible | D13: Gas Propano | G13: Distancia B | K13: 0.9
B14: Horas operación/día | D14: 16 Horas | G14: Plataforma | K14: SI
B15: Sistema de Control | D15: Filtro de Talegas | G15: Escalera de Acceso | K15: NO
A17: CARGUE DE EVIDENCIAS | E17: CARGUE DE EVIDENCIAS | I17: CARGUE DE EVIDENCIAS | M17: CARGUE DE EVIDENCIAS | Q17: CARGUE DE EVIDENCIAS | U17: CARGUE DE EVIDENCIAS | Y17: CARGUE DE EVIDENCIAS | AC17: CARGUE DE EVIDENCIAS
A19: ACTIIDAD | I19: ENE | K19: FEB | M19: MAR | O19: ABR | Q19: MAY | S19: JUN | U19: JUL | W19: AGO | Y19: SEP | AA19: OCT | AC19: NOV | AE19: DIC
A20: Engrase de rodamientos de la turbina | G20: Semanal | I20: S1 | J20: S2 | K20: S1 | L20: S2 | M20: S1 | N20: S2 | O20: 0 | P20: 0 | Q20: 0 | R20: 0 | S20: 0 | T20: 0 | U20: 0 | V20: 0 | W20: 0 | X20: 0 | Y20: 0 | Z20: 0 | AA20: 0 | AB20: 0 | AC20: 0 | AD20: 0 | AE20: 0 | AF20: 0
I21: S3 | J21: S4 | K21: S3 | L21: S4 | M21: S3 | N21: S4 | O21: 0 | P21: 0 | Q21: 0 | R21: 0 | S21: 0 | T21: 0 | U21: 0 | V21: 0 | W21: 0 | X21: 0 | Y21: 0 | Z21: 0 | AA21: 0 | AB21: 0 | AC21: 0 | AD21: 0 | AE21: 0 | AF21: 0
A22: Limpieza de Ventilador de turbina | G22: Semanal | I22: S1 | J22: S2 | K22: S1 | L22: S2 | M22: S1 | N22: S2 | O22: 0 | P22: 0 | Q22: 0 | R22: 0 | S22: 0 | T22: 0 | U22: 0 | V22: 0 | W22: 0 | X22: 0 | Y22: 0 | Z22: 0 | AA22: 0 | AB22: 0 | AC22: 0 | AD22: 0 | AE22: 0 | AF22: 0
I23: S3 | J23: S4 | K23: S3 | L23: S4 | M23: S3 | N23: S4 | O23: 0 | P23: 0 | Q23: 0 | R23: 0 | S23: 0 | T23: 0 | U23: 0 | V23: 0 | W23: 0 | X23: 0 | Y23: 0 | Z23: 0 | AA23: 0 | AB23: 0 | AC23: 0 | AD23: 0 | AE23: 0 | AF23: 0
A24: Limpieza de Compresor | G24: Semanal | I24: S1 | J24: S2 | K24: S1 | L24: S2 | M24: S1 | N24: S2 | O24: 0 | P24: 0 | Q24: 0 | R24: 0 | S24: 0 | T24: 0 | U24: 0 | V24: 0 | W24: 0 | X24: 0 | Y24: 0 | Z24: 0 | AA24: 0 | AB24: 0 | AC24: 0 | AD24: 0 | AE24: 0 | AF24: 0
I25: S3 | J25: S4 | K25: S3 | L25: S4 | M25: S3 | N25: S4 | O25: 0 | P25: 0 | Q25: 0 | R25: 0 | S25: 0 | T25: 0 | U25: 0 | V25: 0 | W25: 0 | X25: 0 | Y25: 0 | Z25: 0 | AA25: 0 | AB25: 0 | AC25: 0 | AD25: 0 | AE25: 0 | AF25: 0
A26: Cambio de Aceite | G26: Semestral | I26: S1 | J26: S2 | K26: S1 | L26: 1 | M26: S1 | N26: S2 | O26: S1 | P26: S2 | Q26: S1 | R26: S2 | S26: S1 | T26: S2 | U26: S1 | V26: S2 | W26: S1 | X26: 0 | Y26: S1 | Z26: S2 | AA26: S1 | AB26: S2 | AC26: S1 | AD26: S2 | AE26: S1 | AF26: S2
I27: S3 | J27: S4 | K27: S3 | L27: S4 | M27: S3 | N27: S4 | O27: S3 | P27: S4 | Q27: S3 | R27: S4 | S27: S3 | T27: S4 | U27: S3 | V27: S4 | W27: S3 | X27: S4 | Y27: S3 | Z27: S4 | AA27: S3 | AB27: S4 | AC27: S3 | AD27: S4 | AE27: S3 | AF27: S4
A28: Cambio de filtros de talega | G28: Semanal | I28: S1 | J28: S2 | K28: S1 | L28: S2 | M28: S1 | N28: S2 | O28: 0 | P28: 0 | Q28: 0 | R28: 0 | S28: 0 | T28: 0 | U28: 0 | V28: 0 | W28: 0 | X28: 0 | Y28: 0 | Z28: 0 | AA28: 0 | AB28: 0 | AC28: 0 | AD28: 0 | AE28: 0 | AF28: 0
I29: S3 | J29: S4 | K29: S3 | L29: S4 | M29: S3 | N29: S4 | O29: 0 | P29: 0 | Q29: 0 | R29: 0 | S29: 0 | T29: 0 | U29: 0 | V29: 0 | W29: 0 | X29: 0 | Y29: 0 | Z29: 0 | AA29: 0 | AB29: 0 | AC29: 0 | AD29: 0 | AE29: 0 | AF29: 0
A30: Limpieza de campanas de extracción | G30: Semanal | I30: S1 | J30: S2 | K30: S1 | L30: S2 | M30: S1 | N30: S2 | O30: 0 | P30: 0 | Q30: 0 | R30: 0 | S30: 0 | T30: 0 | U30: 0 | V30: 0 | W30: 0 | X30: 0 | Y30: 0 | Z30: 0 | AA30: 0 | AB30: 0 | AC30: 0 | AD30: 0 | AE30: 0 | AF30: 0
I31: S3 | J31: S4 | K31: S3 | L31: S4 | M31: S3 | N31: S4 | O31: 0 | P31: 0 | Q31: 0 | R31: 0 | S31: 0 | T31: 0 | U31: 0 | V31: 0 | W31: 0 | X31: 0 | Y31: 0 | Z31: 0 | AA31: 0 | AB31: 0 | AC31: 0 | AD31: 0 | AE31: 0 | AF31: 0
A32: Limpieza del sistema eléctrico | G32: Diario | I32: S1 | J32: S2 | K32: S1 | L32: S2 | M32: S1 | N32: S2 | O32: 0 | P32: 0 | Q32: 0 | R32: 0 | S32: 0 | T32: 0 | U32: 0 | V32: 0 | W32: 0 | X32: 0 | Y32: 0 | Z32: 0 | AA32: 0 | AB32: 0 | AC32: 0 | AD32: 0 | AE32: 0 | AF32: 0
I33: S3 | J33: S4 | K33: S3 | L33: S4 | M33: S3 | N33: S4 | O33: 0 | P33: 0 | Q33: 0 | R33: 0 | S33: 0 | T33: 0 | U33: 0 | V33: 0 | W33: 0 | X33: 0 | Y33: 0 | Z33: 0 | AA33: 0 | AB33: 0 | AC33: 0 | AD33: 0 | AE33: 0 | AF33: 0
A34: Retiro de material acumulado por el filtro de talegas | G34: Diario | I34: S1 | J34: S2 | K34: S1 | L34: S2 | M34: S1 | N34: S2 | O34: 0 | P34: 0 | Q34: 0 | R34: 0 | S34: 0 | T34: 0 | U34: 0 | V34: 0 | W34: 0 | X34: 0 | Y34: 0 | Z34: 0 | AA34: 0 | AB34: 0 | AC34: 0 | AD34: 0 | AE34: 0 | AF34: 0
I35: S3 | J35: S4 | K35: S3 | L35: S4 | M35: S3 | N35: S4 | O35: 0 | P35: 0 | Q35: 0 | R35: 0 | S35: 0 | T35: 0 | U35: 0 | V35: 0 | W35: 0 | X35: 0 | Y35: 0 | Z35: 0 | AA35: 0 | AB35: 0 | AC35: 0 | AD35: 0 | AE35: 0 | AF35: 0
B37: RELACION DEL MANTENIMIENTOS CORRECTIVOS / PREVENTIVOS
B38: N° | C38: FECHA | D38: PROVEEDOR | G38: TIPO MTO | I38: INTERVENCIÓN | M38: DETALLES DEL MANTENIIMIENTO | AA38: RESPONSABLE
G39: PV | H39: CT | I39: Int. | K39: Ext.
B40: M1
B41: M2
B42: M3
B43: M4
B44: M5
B45: M6
B46: M7
...

Sheet 03
D1: SISTEMA DE GESTIÓN INTEGRAL HOJA DE VIDA Y MANTENIMIENTO DE SISTEMAS DE CONTROL DE EMISIONES | AE1: SC
AE2: SS
D3: CODIGO: RC-SI55 | P3: VERSIÓN: 0
B6: ID. SISTEMA | E6: 03 | F6: MEZCLADORA - PLANTA 1 | AC6: =AVERAGE(I20:AF25) -> 0
A8: INFORMACION GENERAL
R9: FOTOGRAFIA SISTEMA DE CONTROL
A17: MANTENIMIENTO PREVENTIVO 2025 Marque con "0" los tiempos en los que se programará el mantenimiento; marque "1" cuando los mantenimientos se hayan cumplido | AC17: CARGUE DE EVIDENCIAS
A19: ACTIIDAD | I19: ENE | K19: FEB | M19: MAR | O19: ABR | Q19: MAY | S19: JUN | U19: JUL | W19: AGO | Y19: SEP | AA19: OCT | AC19: NOV | AE19: DIC
A20: Engrase de Rodamientos | G20: Semanal | I20: S1 | J20: S2 | K20: S1 | L20: S2 | M20: S1 | N20: S2 | O20: 0 | P20: 0 | Q20: 0 | R20: 0 | S20: 0 | T20: 0 | U20: 0 | V20: 0 | W20: 0 | X20: 0 | Y20: 0 | Z20: 0 | AA20: 0 | AB20: 0 | AC20: 0 | AD20: 0 | AE20: 0 | AF20: 0
I21: S3 | J21: S4 | K21: S3 | L21: S4 | M21: S3 | N21: S4 | O21: 0 | P21: 0 | Q21: 0 | R21: 0 | S21: 0 | T21: 0 | U21: 0 | V21: 0 | W21: 0 | X21: 0 | Y21: 0 | Z21: 0 | AA21: 0 | AB21: 0 | AC21: 0 | AD21: 0 | AE21: 0 | AF21: 0
A22: Limpieza de Aspas | G22: Semanal | I22: S1 | J22: S2 | K22: S1 | L22: S2 | M22: S1 | N22: S2 | O22: 0 | P22: 0 | Q22: 0 | R22: 0 | S22: 0 | T22: 0 | U22: 0 | V22: 0 | W22: 0 | X22: 0 | Y22: 0 | Z22: 0 | AA22: 0 | AB22: 0 | AC22: 0 | AD22: 0 | AE22: 0 | AF22: 0
I23: S3 | J23: S4 | K23: S3 | L23: S4 | M23: S3 | N23: S4 | O23: 0 | P23: 0 | Q23: 0 | R23: 0 | S23: 0 | T23: 0 | U23: 0 | V23: 0 | W23: 0 | X23: 0 | Y23: 0 | Z23: 0 | AA23: 0 | AB23: 0 | AC23: 0 | AD23: 0 | AE23: 0 | AF23: 0
A24: Revisión y limpieza del circuito electrico | G24: Diario | I24: S1 | J24: S2 | K24: S1 | L24: S2 | M24: S1 | N24: S2 | O24: 0 | P24: 0 | Q24: 0 | R24: 0 | S24: 0 | T24: 0 | U24: 0 | V24: 0 | W24: 0 | X24: 0 | Y24: 0 | Z24: 0 | AA24: 0 | AB24: 0 | AC24: 0 | AD24: 0 | AE24: 0 | AF24: 0
I25: S3 | J25: S4 | K25: S3 | L25: S4 | M25: S3 | N25: S4 | O25: 0 | P25: 0 | Q25: 0 | R25: 0 | S25: 0 | T25: 0 | U25: 0 | V25: 0 | W25: 0 | X25: 0 | Y25: 0 | Z25: 0 | AA25: 0 | AB25: 0 | AC25: 0 | AD25: 0 | AE25: 0 | AF25: 0
I26: S1 | J26: S2 | K26: S1 | L26: S2 | M26: S1 | N26: S2 | O26: S1 | P26: S2 | Q26: S1 | R26: S2 | S26: S1 | T26: S2 | U26: S1 | V26: S2 | W26: S1 | X26: S2 | Y26: S1 | Z26: S2 | AA26: S1 | AB26: S2 | AC26: S1 | AD26: S2 | AE26: S1 | AF26: S2
I27: S3 | J27: S4 | K27: S3 | L27: S4 | M27: S3 | N27: S4 | O27: S3 | P27: S4 | Q27: S3 | R27: S4 | S27: S3 | T27: S4 | U27: S3 | V27: S4 | W27: S3 | X27: S4 | Y27: S3 | Z27: S4 | AA27: S3 | AB27: S4 | AC27: S3 | AD27: S4 | AE27: S3 | AF27: S4
I28: S1 | J28: S2 | K28: S1 | L28: S2 | M28: S1 | N28: S2 | O28: S1 | P28: S2 | Q28: S1 | R28: S2 | S28: S1 | T28: S2 | U28: S1 | V28: S2 | W28: S1 | X28: S2 | Y28: S1 | Z28: S2 | AA28: S1 | AB28: S2 | AC28: S1 | AD28: S2 | AE28: S1 | AF28: S2
I29: S3 | J29: S4 | K29: S3 | L29: S4 | M29: S3 | N29: S4 | O29: S3 | P29: S4 | Q29: S3 | R29: S4 | S29: S3 | T29: S4 | U29: S3 | V29: S4 | W29: S3 | X29: S4 | Y29: S3 | Z29: S4 | AA29: S3 | AB29: S4 | AC29: S3 | AD29: S4 | AE29: S3 | AF29: S4
I30: S1 | J30: S2 | K30: S1 | L30: S2 | M30: S1 | N30: S2 | O30: S1 | P30: S2 | Q30: S1 | R30: S2 | S30: S1 | T30: S2 | U30: S1 | V30: S2 | W30: S1 | X30: S2 | Y30: S1 | Z30: S2 | AA30: S1 | AB30: S2 | AC30: S1 | AD30: S2 | AE30: S1 | AF30: S2
I31: S3 | J31: S4 | K31: S3 | L31: S4 | M31: S3 | N31: S4 | O31: S3 | P31: S4 | Q31: S3 | R31: S4 | S31: S3 | T31: S4 | U31: S3 | V31: S4 | W31: S3 | X31: S4 | Y31: S3 | Z31: S4 | AA31: S3 | AB31: S4 | AC31: S3 | AD31: S4 | AE31: S3 | AF31: S4
I32: S9 | J32: S10 | K32: S9 | L32: S10 | M32: S9 | N32: S10 | O32: S9 | P32: S10 | Q32: S9 | R32: S10 | S32: S9 | T32: S10 | U32: S9 | V32: S10 | W32: S9 | X32: S10 | Y32: S9 | Z32: S10 | AA32: S9 | AB32: S10 | AC32: S9 | AD32: S10 | AE32: S9 | AF32: S10
I33: S11 | J33: S12 | K33: S11 | L33: S12 | M33: S11 | N33: S12 | O33: S11 | P33: S12 | Q33: S11 | R33: S12 | S33: S11 | T33: S12 | U33: S11 | V33: S12 | W33: S11 | X33: S12 | Y33: S11 | Z33: S12 | AA33: S11 | AB33: S12 | AC33: S11 | AD33: S12 | AE33: S11 | AF33: S12
I34: S1 | J34: S2 | K34: S1 | L34: S2 | M34: S1 | N34: S2 | O34: S1 | P34: S2 | Q34: S1 | R34: S2 | S34: S1 | T34: S2 | U34: S1 | V34: S2 | W34: S1 | X34: S2 | Y34: S1 | Z34: S2 | AA34: S1 | AB34: S2 | AC34: S1 | AD34: S2 | AE34: S1 | AF34: S2
I35: S3 | J35: S4 | K35: S3 | L35: S4 | M35: S3 | N35: S4 | O35: S3 | P35: S4 | Q35: S3 | R35: S4 | S35: S3 | T35: S4 | U35: S3 | V35: S4 | W35: S3 | X35: S4 | Y35: S3 | Z35: S4 | AA35: S3 | AB35: S4 | AC35: S3 | AD35: S4 | AE35: S3 | AF35: S4
B37: RELACION DEL MANTENIMIENTOS CORRECTIVOS / PREVENTIVOS | AA37: CARGUE DE EVIDENCIAS
B38: N° | C38: FECHA | D38: PROVEEDOR | G38: TIPO MTO | I38: INTERVENCIÓN | M38: DETALLES DEL MANTENIIMIENTO | AA38: RESPONSABLE VERIFICACIÓN
G39: PV | H39: CT | I39: Int. | K39: Ext.
B40: M1 | C40: 45726 | D40: Enrrique XXXX | H40: X | K40: X | M40: Se cambia el rotor de las aspas y rodamientos | AA40: Carlos Leal
B41: M2
B42: M3
B43: M4
B44: M5
B45: M6
B46: M7
B47: M8

Sheet 04
D1: SISTEMA DE GESTIÓN INTEGRAL HOJA DE VIDA Y MANTENIMIENTO DE SISTEMAS DE CONTROL DE EMISIONES | AE1: SC
AE2: SS
D3: CODIGO: RC-SI55 | P3: VERSIÓN: 0
B6: ID. SISTEMA | E6: 04 | F6: OLLA GRANULADORA - PLANTA 1 | AC6: =AVERAGE(I20:AF29) -> 0
A8: INFORMACION GENERAL
R9: FOTOGRAFIA SISTEMA DE CONTROL
B10: Marca
B11: Fecha Fabricación
B12: Tío de Ducto
B13: Tipo de Combustible
B14: Horas operación/día
A17: MANTENIMIENTO PREVENTIVO 2025 Marque con "0" los tiempos en los que se programará el mantenimiento; marque "1" cuando los mantenimientos se hayan cumplido | AC17: CARGUE DE EVIDENCIAS
A19: ACTIIDAD | I19: ENE | K19: FEB | M19: MAR | O19: ABR | Q19: MAY | S19: JUN | U19: JUL | W19: AGO | Y19: SEP | AA19: OCT | AC19: NOV | AE19: DIC
A20: Engrase de rodamientos | G20: Semanal | I20: S1 | J20: S2 | K20: S1 | L20: S2 | M20: S1 | N20: S2 | O20: 0 | P20: 0 | Q20: 0 | R20: 0 | S20: 0 | T20: 0 | U20: 0 | V20: 0 | W20: 0 | X20: 0 | Y20: 0 | Z20: 0 | AA20: 0 | AB20: 0 | AC20: 0 | AD20: 0 | AE20: 0 | AF20: 0
I21: S3 | J21: S4 | K21: S3 | L21: S4 | M21: S3 | N21: S4 | O21: 0 | P21: 0 | Q21: 0 | R21: 0 | S21: 0 | T21: 0 | U21: 0 | V21: 0 | W21: 0 | X21: 0 | Y21: 0 | Z21: 0 | AA21: 0 | AB21: 0 | AC21: 0 | AD21: 0 | AE21: 0 | AF21: 0
A22: Limpieza interna y externa de la olla | G22: Diario | I22: S1 | J22: S2 | K22: S1 | L22: S2 | M22: S1 | N22: S2 | O22: 0 | P22: 0 | Q22: 0 | R22: 0 | S22: 0 | T22: 0 | U22: 0 | V22: 0 | W22: 0 | X22: 0 | Y22: 0 | Z22: 0 | AA22: 0 | AB22: 0 | AC22: 0 | AD22: 0 | AE22: 0 | AF22: 0
I23: S3 | J23: S4 | K23: S3 | L23: S4 | M23: S3 | N23: S4 | O23: 0 | P23: 0 | Q23: 0 | R23: 0 | S23: 0 | T23: 0 | U23: 0 | V23: 0 | W23: 0 | X23: 0 | Y23: 0 | Z23: 0 | AA23: 0 | AB23: 0 | AC23: 0 | AD23: 0 | AE23: 0 | AF23: 0
A24: Revisión y limpieza de aspersores de agua | G24: Diario | I24: S1 | J24: S2 | K24: S1 | L24: S2 | M24: S1 | N24: S2 | O24: 0 | P24: 0 | Q24: 0 | R24: 0 | S24: 0 | T24: 0 | U24: 0 | V24: 0 | W24: 0 | X24: 0 | Y24: 0 | Z24: 0 | AA24: 0 | AB24: 0 | AC24: 0 | AD24: 0 | AE24: 0 | AF24: 0
I25: S3 | J25: S4 | K25: S3 | L25: S4 | M25: S3 | N25: S4 | O25: 0 | P25: 0 | Q25: 0 | R25: 0 | S25: 0 | T25: 0 | U25: 0 | V25: 0 | W25: 0 | X25: 0 | Y25: 0 | Z25: 0 | AA25: 0 | AB25: 0 | AC25: 0 | AD25: 0 | AE25: 0 | AF25: 0
A26: Revisión y limpieza del circuito electrico | G26: Diario | I26: S1 | J26: S2 | K26: S1 | L26: S2 | M26: S1 | N26: S2 | O26: 0 | P26: 0 | Q26: 0 | R26: 0 | S26: 0 | T26: 0 | U26: 0 | V26: 0 | W26: 0 | X26: 0 | Y26: 0 | Z26: 0 | AA26: 0 | AB26: 0 | AC26: 0 | AD26: 0 | AE26: 0 | AF26: 0
I27: S3 | J27: S4 | K27: S3 | L27: S4 | M27: S3 | N27: S4 | O27: 0 | P27: 0 | Q27: 0 | R27: 0 | S27: 0 | T27: 0 | U27: 0 | V27: 0 | W27: 0 | X27: 0 | Y27: 0 | Z27: 0 | AA27: 0 | AB27: 0 | AC27: 0 | AD27: 0 | AE27: 0 | AF27: 0
A28: Revisión general externa del sistena electrico del equipo | G28: Semestral | I28: S1 | J28: S2 | K28: S1 | L28: S2 | M28: S1 | N28: S2 | O28: S1 | P28: S2 | Q28: S1 | R28: 0 | S28: S1 | T28: S2 | U28: S1 | V28: S2 | W28: S1 | X28: S2 | Y28: S1 | Z28: S2 | AA28: S1 | AB28: S2 | AC28: S1 | AD28: 0 | AE28: S1 | AF28: S2
I29: S3 | J29: S4 | K29: S3 | L29: S4 | M29: S3 | N29: S4 | O29: S3 | P29: S4 | Q29: S3 | R29: S4 | S29: S3 | T29: S4 | U29: S3 | V29: S4 | W29: S3 | X29: S4 | Y29: S3 | Z29: S4 | AA29: S3 | AB29: S4 | AC29: S3 | AD29: S4 | AE29: S3 | AF29: S4
I30: S1 | J30: S2 | K30: S1 | L30: S2 | M30: S1 | N30: S2 | O30: S1 | P30: S2 | Q30: S1 | R30: S2 | S30: S1 | T30: S2 | U30: S1 | V30: S2 | W30: S1 | X30: S2 | Y30: S1 | Z30: S2 | AA30: S1 | AB30: S2 | AC30: S1 | AD30: S2 | AE30: S1 | AF30: S2
I31: S3 | J31: S4 | K31: S3 | L31: S4 | M31: S3 | N31: S4 | O31: S3 | P31: S4 | Q31: S3 | R31: S4 | S31: S3 | T31: S4 | U31: S3 | V31: S4 | W31: S3 | X31: S4 | Y31: S3 | Z31: S4 | AA31: S3 | AB31: S4 | AC31: S3 | AD31: S4 | AE31: S3 | AF31: S4
I32: S1 | J32: S2 | K32: S1 | L32: S2 | M32: S1 | N32: S2 | O32: S1 | P32: S2 | Q32: S1 | R32: S2 | S32: S1 | T32: S2 | U32: S1 | V32: S2 | W32: S1 | X32: S2 | Y32: S1 | Z32: S2 | AA32: S1 | AB32: S2 | AC32: S1 | AD32: S2 | AE32: S1 | AF32: S2
I33: S3 | J33: S4 | K33: S3 | L33: S4 | M33: S3 | N33: S4 | O33: S3 | P33: S4 | Q33: S3 | R33: S4 | S33: S3 | T33: S4 | U33: S3 | V33: S4 | W33: S3 | X33: S4 | Y33: S3 | Z33: S4 | AA33: S3 | AB33: S4 | AC33: S3 | AD33: S4 | AE33: S3 | AF33: S4
I34: S9 | J34: S10 | K34: S9 | L34: S10 | M34: S9 | N34: S10 | O34: S9 | P34: S10 | Q34: S9 | R34: S10 | S34: S9 | T34: S10 | U34: S9 | V34: S10 | W34: S9 | X34: S10 | Y34: S9 | Z34: S10 | AA34: S9 | AB34: S10 | AC34: S9 | AD34: S10 | AE34: S9 | AF34: S10
I35: S11 | J35: S12 | K35: S11 | L35: S12 | M35: S11 | N35: S12 | O35: S11 | P35: S12 | Q35: S11 | R35: S12 | S35: S11 | T35: S12 | U35: S11 | V35: S12 | W35: S11 | X35: S12 | Y35: S11 | Z35: S12 | AA35: S11 | AB35: S12 | AC35: S11 | AD35: S12 | AE35: S11 | AF35: S12
I36: S1 | J36: S2 | K36: S1 | L36: S2 | M36: S1 | N36: S2 | O36: S1 | P36: S2 | Q36: S1 | R36: S2 | S36: S1 | T36: S2 | U36: S1 | V36: S2 | W36: S1 | X36: S2 | Y36: S1 | Z36: S2 | AA36: S1 | AB36: S2 | AC36: S1 | AD36: S2 | AE36: S1 | AF36: S2
I37: S3 | J37: S4 | K37: S3 | L37: S4 | M37: S3 | N37: S4 | O37: S3 | P37: S4 | Q37: S3 | R37: S4 | S37: S3 | T37: S4 | U37: S3 | V37: S4 | W37: S3 | X37: S4 | Y37: S3 | Z37: S4 | AA37: S3 | AB37: S4 | AC37: S3 | AD37: S4 | AE37: S3 | AF37: S4
B39: RELACION DEL MANTENIMIENTOS CORRECTIVOS / PREVENTIVOS
B40: N° | C40: FECHA | D40: PROVEEDOR | G40: TIPO MTO | I40: INTERVENCIÓN | M40: DETALLES DEL MANTENIIMIENTO | AA40: RESPONSABLE
G41: PV | H41: CT | I41: Int. | K41: Ext.
B42: M1
B43: M2
B44: M3
B45: M4
B46: M5
B47: M6
...

Sheet 05
D1: SISTEMA DE GESTIÓN INTEGRAL HOJA DE VIDA Y MANTENIMIENTO DE SISTEMAS DE CONTROL DE EMISIONES | AE1: SC
AE2: SS
D3: CODIGO: RC-SI55 | P3: VERSIÓN: 0
B6: ID. SISTEMA | E6: 05 | F6: TUBO SECADOR - PLANTA 1 | AC6: =AVERAGE(I20:AF27) -> 0
A8: INFORMACION GENERAL
R9: FOTOGRAFIA SISTEMA DE CONTROL
B10: Marca
B11: Fecha Fabricación
B12: Tío de Ducto
B13: Tipo de Combustible
B14: Horas operación/día
A17: MANTENIMIENTO PREVENTIVO 2025 Marque con "0" los tiempos en los que se programará el mantenimiento; marque "1" cuando los mantenimientos se hayan cumplido | AC17: CARGUE DE EVIDENCIAS
A19: ACTIIDAD | I19: ENE | K19: FEB | M19: MAR | O19: ABR | Q19: MAY | S19: JUN | U19: JUL | W19: AGO | Y19: SEP | AA19: OCT | AC19: NOV | AE19: DIC
A20: Engrase de rodamientos | G20: Semanal | I20: S1 | J20: S2 | K20: S1 | L20: S2 | M20: S1 | N20: S2 | O20: S1 | P20: S2 | Q20: 0 | R20: 0 | S20: 0 | T20: 0 | U20: 0 | V20: 0 | W20: 0 | X20: 0 | Y20: 0 | Z20: 0 | AA20: 0 | AB20: 0 | AC20: 0 | AD20: 0 | AE20: 0 | AF20: 0
I21: S3 | J21: S4 | K21: S3 | L21: S4 | M21: S3 | N21: S4 | O21: S3 | P21: S4 | Q21: 0 | R21: 0 | S21: 0 | T21: 0 | U21: 0 | V21: 0 | W21: 0 | X21: 0 | Y21: 0 | Z21: 0 | AA21: 0 | AB21: 0 | AC21: 0 | AD21: 0 | AE21: 0 | AF21: 0
A22: Alineación de rodillos y patines | G22: Semanal | I22: S1 | J22: S2 | K22: S1 | L22: S2 | M22: S1 | N22: S2 | O22: S1 | P22: S2 | Q22: 0 | R22: 0 | S22: 0 | T22: 0 | U22: 0 | V22: 0 | W22: 0 | X22: 0 | Y22: 0 | Z22: 0 | AA22: 0 | AB22: 0 | AC22: 0 | AD22: 0 | AE22: 0 | AF22: 0
I23: S3 | J23: S4 | K23: S3 | L23: S4 | M23: S3 | N23: S4 | O23: S3 | P23: S4 | Q23: 0 | R23: 0 | S23: 0 | T23: 0 | U23: 0 | V23: 0 | W23: 0 | X23: 0 | Y23: 0 | Z23: 0 | AA23: 0 | AB23: 0 | AC23: 0 | AD23: 0 | AE23: 0 | AF23: 0
A24: Limpieza y engase de rodillos y patines | G24: Semanal | I24: S1 | J24: S2 | K24: S1 | L24: S2 | M24: S1 | N24: S2 | O24: S1 | P24: S2 | Q24: 0 | R24: 0 | S24: 0 | T24: 0 | U24: 0 | V24: 0 | W24: 0 | X24: 0 | Y24: 0 | Z24: 0 | AA24: 0 | AB24: 0 | AC24: 0 | AD24: 0 | AE24: 0 | AF24: 0
I25: S3 | J25: S4 | K25: S3 | L25: S4 | M25: S3 | N25: S4 | O25: S3 | P25: S4 | Q25: 0 | R25: 0 | S25: 0 | T25: 0 | U25: 0 | V25: 0 | W25: 0 | X25: 0 | Y25: 0 | Z25: 0 | AA25: 0 | AB25: 0 | AC25: 0 | AD25: 0 | AE25: 0 | AF25: 0
A26: Revisar recubrimiento del tubo secador | G26: Diario | I26: S1 | J26: S2 | K26: S1 | L26: S2 | M26: S1 | N26: S2 | O26: S1 | P26: S2 | Q26: 0 | R26: 0 | S26: 0 | T26: 0 | U26: 0 | V26: 0 | W26: 0 | X26: 0 | Y26: 0 | Z26: 0 | AA26: 0 | AB26: 0 | AC26: 0 | AD26: 0 | AE26: 0 | AF26: 0
I27: S3 | J27: S4 | K27: S3 | L27: S4 | M27: S3 | N27: S4 | O27: S3 | P27: S4 | Q27: 0 | R27: 0 | S27: 0 | T27: 0 | U27: 0 | V27: 0 | W27: 0 | X27: 0 | Y27: 0 | Z27: 0 | AA27: 0 | AB27: 0 | AC27: 0 | AD27: 0 | AE27: 0 | AF27: 0
I28: S1 | J28: S2 | K28: S1 | L28: S2 | M28: S1 | N28: S2 | O28: S1 | P28: S2 | Q28: S1 | R28: S2 | S28: S1 | T28: S2 | U28: S1 | V28: S2 | W28: S1 | X28: S2 | Y28: S1 | Z28: S2 | AA28: S1 | AB28: S2 | AC28: S1 | AD28: S2 | AE28: S1 | AF28: S2
I29: S3 | J29: S4 | K29: S3 | L29: S4 | M29: S3 | N29: S4 | O29: S3 | P29: S4 | Q29: S3 | R29: S4 | S29: S3 | T29: S4 | U29: S3 | V29: S4 | W29: S3 | X29: S4 | Y29: S3 | Z29: S4 | AA29: S3 | AB29: S4 | AC29: S3 | AD29: S4 | AE29: S3 | AF29: S4
I30: S1 | J30: S2 | K30: S1 | L30: S2 | M30: S1 | N30: S2 | O30: S1 | P30: S2 | Q30: S1 | R30: S2 | S30: S1 | T30: S2 | U30: S1 | V30: S2 | W30: S1 | X30: S2 | Y30: S1 | Z30: S2 | AA30: S1 | AB30: S2 | AC30: S1 | AD30: S2 | AE30: S1 | AF30: S2
I31: S3 | J31: S4 | K31: S3 | L31: S4 | M31: S3 | N31: S4 | O31: S3 | P31: S4 | Q31: S3 | R31: S4 | S31: S3 | T31: S4 | U31: S3 | V31: S4 | W31: S3 | X31: S4 | Y31: S3 | Z31: S4 | AA31: S3 | AB31: S4 | AC31: S3 | AD31: S4 | AE31: S3 | AF31: S4
I32: S1 | J32: S2 | K32: S1 | L32: S2 | M32: S1 | N32: S2 | O32: S1 | P32: S2 | Q32: S1 | R32: S2 | S32: S1 | T32: S2 | U32: S1 | V32: S2 | W32: S1 | X32: S2 | Y32: S1 | Z32: S2 | AA32: S1 | AB32: S2 | AC32: S1 | AD32: S2 | AE32: S1 | AF32: S2
I33: S3 | J33: S4 | K33: S3 | L33: S4 | M33: S3 | N33: S4 | O33: S3 | P33: S4 | Q33: S3 | R33: S4 | S33: S3 | T33: S4 | U33: S3 | V33: S4 | W33: S3 | X33: S4 | Y33: S3 | Z33: S4 | AA33: S3 | AB33: S4 | AC33: S3 | AD33: S4 | AE33: S3 | AF33: S4
I34: S1 | J34: S2 | K34: S1 | L34: S2 | M34: S1 | N34: S2 | O34: S1 | P34: S2 | Q34: S1 | R34: S2 | S34: S1 | T34: S2 | U34: S1 | V34: S2 | W34: S1 | X34: S2 | Y34: S1 | Z34: S2 | AA34: S1 | AB34: S2 | AC34: S1 | AD34: S2 | AE34: S1 | AF34: S2
I35: S3 | J35: S4 | K35: S3 | L35: S4 | M35: S3 | N35: S4 | O35: S3 | P35: S4 | Q35: S3 | R35: S4 | S35: S3 | T35: S4 | U35: S3 | V35: S4 | W35: S3 | X35: S4 | Y35: S3 | Z35: S4 | AA35: S3 | AB35: S4 | AC35: S3 | AD35: S4 | AE35: S3 | AF35: S4
I36: S1 | J36: S2 | K36: S1 | L36: S2 | M36: S1 | N36: S2 | O36: S1 | P36: S2 | Q36: S1 | R36: S2 | S36: S1 | T36: S2 | U36: S1 | V36: S2 | W36: S1 | X36: S2 | Y36: S1 | Z36: S2 | AA36: S1 | AB36: S2 | AC36: S1 | AD36: S2 | AE36: S1 | AF36: S2
I37: S3 | J37: S4 | K37: S3 | L37: S4 | M37: S3 | N37: S4 | O37: S3 | P37: S4 | Q37: S3 | R37: S4 | S37: S3 | T37: S4 | U37: S3 | V37: S4 | W37: S3 | X37: S4 | Y37: S3 | Z37: S4 | AA37: S3 | AB37: S4 | AC37: S3 | AD37: S4 | AE37: S3 | AF37: S4
B39: RELACION DEL MANTENIMIENTOS CORRECTIVOS / PREVENTIVOS
B40: N° | C40: FECHA | D40: PROVEEDOR | G40: TIPO MTO | I40: INTERVENCIÓN | M40: DETALLES DEL MANTENIIMIENTO | AA40: RESPONSABLE
G41: PV | H41: CT | I41: Int. | K41: Ext.
B42: M1
B43: M2
B44: M3
B45: M4
B46: M5
B47: M6
...

Sheet 06
D1: SISTEMA DE GESTIÓN INTEGRAL HOJA DE VIDA Y MANTENIMIENTO DE SISTEMAS DE CONTROL DE EMISIONES | AE1: SC
AE2: SS
D3: CODIGO: RC-SI55 | P3: VERSIÓN: 0
B6: ID. SISTEMA | E6: 06 | F6: QUEMADOR - PLANTA 1 | AC6: =AVERAGE(I20:AF23) -> 0
A8: INFORMACION GENERAL
R9: FOTOGRAFIA SISTEMA DE CONTROL
B10: Marca
B11: Fecha Fabricación
B12: Tío de Ducto
B13: Tipo de Combustible
B14: Horas operación/día
A17: MANTENIMIENTO PREVENTIVO 2025 Marque con "0" los tiempos en los que se programará el mantenimiento; marque "1" cuando los mantenimientos se hayan cumplido | AC17: CARGUE DE EVIDENCIAS
A19: ACTIIDAD | I19: ENE | K19: FEB | M19: MAR | O19: ABR | Q19: MAY | S19: JUN | U19: JUL | W19: AGO | Y19: SEP | AA19: OCT | AC19: NOV | AE19: DIC
A20: Limpieza general | G20: Diario | I20: S1 | J20: S2 | K20: S1 | L20: S2 | M20: S1 | N20: S2 | O20: 0 | P20: 0 | Q20: 0 | R20: 0 | S20: 0 | T20: 0 | U20: 0 | V20: 0 | W20: 0 | X20: 0 | Y20: 0 | Z20: 0 | AA20: 0 | AB20: 0 | AC20: 0 | AD20: 0 | AE20: 0 | AF20: 0
I21: S3 | J21: S4 | K21: S3 | L21: S4 | M21: S3 | N21: S4 | O21: 0 | P21: 0 | Q21: 0 | R21: 0 | S21: 0 | T21: 0 | U21: 0 | V21: 0 | W21: 0 | X21: 0 | Y21: 0 | Z21: 0 | AA21: 0 | AB21: 0 | AC21: 0 | AD21: 0 | AE21: 0 | AF21: 0
A22: Revisión y limpieza del circuito electrico | G22: Semanal | I22: S1 | J22: S2 | K22: S1 | L22: S2 | M22: S1 | N22: S2 | O22: 0 | P22: 0 | Q22: 0 | R22: 0 | S22: 0 | T22: 0 | U22: 0 | V22: 0 | W22: 0 | X22: 0 | Y22: 0 | Z22: 0 | AA22: 0 | AB22: 0 | AC22: 0 | AD22: 0 | AE22: 0 | AF22: 0
I23: S3 | J23: S4 | K23: S3 | L23: S4 | M23: S3 | N23: S4 | O23: 0 | P23: 0 | Q23: 0 | R23: 0 | S23: 0 | T23: 0 | U23: 0 | V23: 0 | W23: 0 | X23: 0 | Y23: 0 | Z23: 0 | AA23: 0 | AB23: 0 | AC23: 0 | AD23: 0 | AE23: 0 | AF23: 0
I24: S1 | J24: S2 | K24: S1 | L24: S2 | M24: S1 | N24: S2 | O24: S1 | P24: S2 | Q24: S1 | R24: S2 | S24: S1 | T24: S2 | U24: S1 | V24: S2 | W24: S1 | X24: S2 | Y24: S1 | Z24: S2 | AA24: S1 | AB24: S2 | AC24: S1 | AD24: S2 | AE24: S1 | AF24: S2
I25: S3 | J25: S4 | K25: S3 | L25: S4 | M25: S3 | N25: S4 | O25: S3 | P25: S4 | Q25: S3 | R25: S4 | S25: S3 | T25: S4 | U25: S3 | V25: S4 | W25: S3 | X25: S4 | Y25: S3 | Z25: S4 | AA25: S3 | AB25: S4 | AC25: S3 | AD25: S4 | AE25: S3 | AF25: S4
I26: S1 | J26: S2 | K26: S1 | L26: S2 | M26: S1 | N26: S2 | O26: S1 | P26: S2 | Q26: S1 | R26: S2 | S26: S1 | T26: S2 | U26: S1 | V26: S2 | W26: S1 | X26: S2 | Y26: S1 | Z26: S2 | AA26: S1 | AB26: S2 | AC26: S1 | AD26: S2 | AE26: S1 | AF26: S2
I27: S3 | J27: S4 | K27: S3 | L27: S4 | M27: S3 | N27: S4 | O27: S3 | P27: S4 | Q27: S3 | R27: S4 | S27: S3 | T27: S4 | U27: S3 | V27: S4 | W27: S3 | X27: S4 | Y27: S3 | Z27: S4 | AA27: S3 | AB27: S4 | AC27: S3 | AD27: S4 | AE27: S3 | AF27: S4
I28: S1 | J28: S2 | K28: S1 | L28: S2 | M28: S1 | N28: S2 | O28: S1 | P28: S2 | Q28: S1 | R28: S2 | S28: S1 | T28: S2 | U28: S1 | V28: S2 | W28: S1 | X28: S2 | Y28: S1 | Z28: S2 | AA28: S1 | AB28: S2 | AC28: S1 | AD28: S2 | AE28: S1 | AF28: S2
I29: S3 | J29: S4 | K29: S3 | L29: S4 | M29: S3 | N29: S4 | O29: S3 | P29: S4 | Q29: S3 | R29: S4 | S29: S3 | T29: S4 | U29: S3 | V29: S4 | W29: S3 | X29: S4 | Y29: S3 | Z29: S4 | AA29: S3 | AB29: S4 | AC29: S3 | AD29: S4 | AE29: S3 | AF29: S4
I30: S1 | J30: S2 | K30: S1 | L30: S2 | M30: S1 | N30: S2 | O30: S1 | P30: S2 | Q30: S1 | R30: S2 | S30: S1 | T30: S2 | U30: S1 | V30: S2 | W30: S1 | X30: S2 | Y30: S1 | Z30: S2 | AA30: S1 | AB30: S2 | AC30: S1 | AD30: S2 | AE30: S1 | AF30: S2
I31: S3 | J31: S4 | K31: S3 | L31: S4 | M31: S3 | N31: S4 | O31: S3 | P31: S4 | Q31: S3 | R31: S4 | S31: S3 | T31: S4 | U31: S3 | V31: S4 | W31: S3 | X31: S4 | Y31: S3 | Z31: S4 | AA31: S3 | AB31: S4 | AC31: S3 | AD31: S4 | AE31: S3 | AF31: S4
I32: S1 | J32: S2 | K32: S1 | L32: S2 | M32: S1 | N32: S2 | O32: S1 | P32: S2 | Q32: S1 | R32: S2 | S32: S1 | T32: S2 | U32: S1 | V32: S2 | W32: S1 | X32: S2 | Y32: S1 | Z32: S2 | AA32: S1 | AB32: S2 | AC32: S1 | AD32: S2 | AE32: S1 | AF32: S2
I33: S3 | J33: S4 | K33: S3 | L33: S4 | M33: S3 | N33: S4 | O33: S3 | P33: S4 | Q33: S3 | R33: S4 | S33: S3 | T33: S4 | U33: S3 | V33: S4 | W33: S3 | X33: S4 | Y33: S3 | Z33: S4 | AA33: S3 | AB33: S4 | AC33: S3 | AD33: S4 | AE33: S3 | AF33: S4
I34: S1 | J34: S2 | K34: S1 | L34: S2 | M34: S1 | N34: S2 | O34: S1 | P34: S2 | Q34: S1 | R34: S2 | S34: S1 | T34: S2 | U34: S1 | V34: S2 | W34: S1 | X34: S2 | Y34: S1 | Z34: S2 | AA34: S1 | AB34: S2 | AC34: S1 | AD34: S2 | AE34: S1 | AF34: S2
I35: S3 | J35: S4 | K35: S3 | L35: S4 | M35: S3 | N35: S4 | O35: S3 | P35: S4 | Q35: S3 | R35: S4 | S35: S3 | T35: S4 | U35: S3 | V35: S4 | W35: S3 | X35: S4 | Y35: S3 | Z35: S4 | AA35: S3 | AB35: S4 | AC35: S3 | AD35: S4 | AE35: S3 | AF35: S4
B37: RELACION DEL MANTENIMIENTOS CORRECTIVOS / PREVENTIVOS
B38: N° | C38: FECHA | D38: PROVEEDOR | G38: TIPO MTO | I38: INTERVENCIÓN | M38: DETALLES DEL MANTENIIMIENTO | AA38: RESPONSABLE
G39: PV | H39: CT | I39: Int. | K39: Ext.
B40: M1
B41: M2
B42: M3
B43: M4
B44: M5
B45: M6
B46: M7
B47: M8

Sheet 07
D1: SISTEMA DE GESTIÓN INTEGRAL HOJA DE VIDA Y MANTENIMIENTO DE SISTEMAS DE CONTROL DE EMISIONES | AE1: SC
AE2: SS
D3: CODIGO: RC-SI55 | P3: VERSIÓN: 0
B6: ID. SISTEMA | E6: 07 | F6: SEPARADOR DE FINOS - PLANTA 1 | AC6: =AVERAGE(I20:AF25) -> 0
A8: INFORMACION GENERAL
R9: FOTOGRAFIA SISTEMA DE CONTROL
B10: Marca
B11: Fecha Fabricación
B12: Tío de Ducto
B13: Tipo de Combustible
B14: Horas operación/día
A17: MANTENIMIENTO PREVENTIVO 2025 Marque con "0" los tiempos en los que se programará el mantenimiento; marque "1" cuando los mantenimientos se hayan cumplido | AC17: CARGUE DE EVIDENCIAS
A19: ACTIIDAD | I19: ENE | K19: FEB | M19: MAR | O19: ABR | Q19: MAY | S19: JUN | U19: JUL | W19: AGO | Y19: SEP | AA19: OCT | AC19: NOV | AE19: DIC
A20: Revisión y limpieza de mallas | G20: Semanal | I20: S1 | J20: S2 | K20: S1 | L20: S2 | M20: S1 | N20: S2 | O20: 0 | P20: 0 | Q20: 0 | R20: 0 | S20: 0 | T20: 0 | U20: 0 | V20: 0 | W20: 0 | X20: 0 | Y20: 0 | Z20: 0 | AA20: 0 | AB20: 0 | AC20: 0 | AD20: 0 | AE20: 0 | AF20: 0
I21: S3 | J21: S4 | K21: S3 | L21: S4 | M21: S3 | N21: S4 | O21: 0 | P21: 0 | Q21: 0 | R21: 0 | S21: 0 | T21: 0 | U21: 0 | V21: 0 | W21: 0 | X21: 0 | Y21: 0 | Z21: 0 | AA21: 0 | AB21: 0 | AC21: 0 | AD21: 0 | AE21: 0 | AF21: 0
A22: Engase de rodamientos | G22: Semanal | I22: S1 | J22: S2 | K22: S1 | L22: S2 | M22: S1 | N22: S2 | O22: 0 | P22: 0 | Q22: 0 | R22: 0 | S22: 0 | T22: 0 | U22: 0 | V22: 0 | W22: 0 | X22: 0 | Y22: 0 | Z22: 0 | AA22: 0 | AB22: 0 | AC22: 0 | AD22: 0 | AE22: 0 | AF22: 0
I23: S3 | J23: S4 | K23: S3 | L23: S4 | M23: S3 | N23: S4 | O23: 0 | P23: 0 | Q23: 0 | R23: 0 | S23: 0 | T23: 0 | U23: 0 | V23: 0 | W23: 0 | X23: 0 | Y23: 0 | Z23: 0 | AA23: 0 | AB23: 0 | AC23: 0 | AD23: 0 | AE23: 0 | AF23: 0
A24: Revisión y limpieza del circuito electrico | G24: Semanal | I24: S1 | J24: S2 | K24: S1 | L24: S2 | M24: S1 | N24: S2 | O24: 0 | P24: 0 | Q24: 0 | R24: 0 | S24: 0 | T24: 0 | U24: 0 | V24: 0 | W24: 0 | X24: 0 | Y24: 0 | Z24: 0 | AA24: 0 | AB24: 0 | AC24: 0 | AD24: 0 | AE24: 0 | AF24: 0
I25: S3 | J25: S4 | K25: S3 | L25: S4 | M25: S3 | N25: S4 | O25: 0 | P25: 0 | Q25: 0 | R25: 0 | S25: 0 | T25: 0 | U25: 0 | V25: 0 | W25: 0 | X25: 0 | Y25: 0 | Z25: 0 | AA25: 0 | AB25: 0 | AC25: 0 | AD25: 0 | AE25: 0 | AF25: 0
I26: S1 | J26: S2 | K26: S1 | L26: S2 | M26: S1 | N26: S2 | O26: S1 | P26: S2 | Q26: S1 | R26: S2 | S26: S1 | T26: S2 | U26: S1 | V26: S2 | W26: S1 | X26: S2 | Y26: S1 | Z26: S2 | AA26: S1 | AB26: S2 | AC26: S1 | AD26: S2 | AE26: S1 | AF26: S2
I27: S3 | J27: S4 | K27: S3 | L27: S4 | M27: S3 | N27: S4 | O27: S3 | P27: S4 | Q27: S3 | R27: S4 | S27: S3 | T27: S4 | U27: S3 | V27: S4 | W27: S3 | X27: S4 | Y27: S3 | Z27: S4 | AA27: S3 | AB27: S4 | AC27: S3 | AD27: S4 | AE27: S3 | AF27: S4
I28: S1 | J28: S2 | K28: S1 | L28: S2 | M28: S1 | N28: S2 | O28: S1 | P28: S2 | Q28: S1 | R28: S2 | S28: S1 | T28: S2 | U28: S1 | V28: S2 | W28: S1 | X28: S2 | Y28: S1 | Z28: S2 | AA28: S1 | AB28: S2 | AC28: S1 | AD28: S2 | AE28: S1 | AF28: S2
I29: S3 | J29: S4 | K29: S3 | L29: S4 | M29: S3 | N29: S4 | O29: S3 | P29: S4 | Q29: S3 | R29: S4 | S29: S3 | T29: S4 | U29: S3 | V29: S4 | W29: S3 | X29: S4 | Y29: S3 | Z29: S4 | AA29: S3 | AB29: S4 | AC29: S3 | AD29: S4 | AE29: S3 | AF29: S4
I30: S1 | J30: S2 | K30: S1 | L30: S2 | M30: S1 | N30: S2 | O30: S1 | P30: S2 | Q30: S1 | R30: S2 | S30: S1 | T30: S2 | U30: S1 | V30: S2 | W30: S1 | X30: S2 | Y30: S1 | Z30: S2 | AA30: S1 | AB30: S2 | AC30: S1 | AD30: S2 | AE30: S1 | AF30: S2
I31: S3 | J31: S4 | K31: S3 | L31: S4 | M31: S3 | N31: S4 | O31: S3 | P31: S4 | Q31: S3 | R31: S4 | S31: S3 | T31: S4 | U31: S3 | V31: S4 | W31: S3 | X31: S4 | Y31: S3 | Z31: S4 | AA31: S3 | AB31: S4 | AC31: S3 | AD31: S4 | AE31: S3 | AF31: S4
I32: S1 | J32: S2 | K32: S1 | L32: S2 | M32: S1 | N32: S2 | O32: S1 | P32: S2 | Q32: S1 | R32: S2 | S32: S1 | T32: S2 | U32: S1 | V32: S2 | W32: S1 | X32: S2 | Y32: S1 | Z32: S2 | AA32: S1 | AB32: S2 | AC32: S1 | AD32: S2 | AE32: S1 | AF32: S2
I33: S3 | J33: S4 | K33: S3 | L33: S4 | M33: S3 | N33: S4 | O33: S3 | P33: S4 | Q33: S3 | R33: S4 | S33: S3 | T33: S4 | U33: S3 | V33: S4 | W33: S3 | X33: S4 | Y33: S3 | Z33: S4 | AA33: S3 | AB33: S4 | AC33: S3 | AD33: S4 | AE33: S3 | AF33: S4
I34: S1 | J34: S2 | K34: S1 | L34: S2 | M34: S1 | N34: S2 | O34: S1 | P34: S2 | Q34: S1 | R34: S2 | S34: S1 | T34: S2 | U34: S1 | V34: S2 | W34: S1 | X34: S2 | Y34: S1 | Z34: S2 | AA34: S1 | AB34: S2 | AC34: S1 | AD34: S2 | AE34: S1 | AF34: S2
I35: S3 | J35: S4 | K35: S3 | L35: S4 | M35: S3 | N35: S4 | O35: S3 | P35: S4 | Q35: S3 | R35: S4 | S35: S3 | T35: S4 | U35: S3 | V35: S4 | W35: S3 | X35: S4 | Y35: S3 | Z35: S4 | AA35: S3 | AB35: S4 | AC35: S3 | AD35: S4 | AE35: S3 | AF35: S4
B37: RELACION DEL MANTENIMIENTOS CORRECTIVOS / PREVENTIVOS
B38: N° | C38: FECHA | D38: PROVEEDOR | G38: TIPO MTO | I38: INTERVENCIÓN | M38: DETALLES DEL MANTENIIMIENTO | AA38: RESPONSABLE
G39: PV | H39: CT | I39: Int. | K39: Ext.
B40: M1
B41: M2
B42: M3
B43: M4
B44: M5
B45: M6
B46: M7
B47: M8

Sheet 08
D1: SISTEMA DE GESTIÓN INTEGRAL HOJA DE VIDA Y MANTENIMIENTO DE SISTEMAS DE CONTROL DE EMISIONES | AE1: SC
AE2: SS
D3: CODIGO: RC-SI55 | P3: VERSIÓN: 0
B6: ID. SISTEMA | E6: 08 | F6: MOLINO - PLANTA 1 | AC6: =AVERAGE(I20:AF27) -> 0
A8: INFORMACION GENERAL
R9: FOTOGRAFIA SISTEMA DE CONTROL
B10: Marca
B11: Fecha Fabricación
B12: Tío de Ducto
B13: Tipo de Combustible
B14: Horas operación/día
A17: MANTENIMIENTO PREVENTIVO 2025 Marque con "0" los tiempos en los que se programará el mantenimiento; marque "1" cuando los mantenimientos se hayan cumplido | AC17: CARGUE DE EVIDENCIAS
A19: ACTIIDAD | I19: ENE | K19: FEB | M19: MAR | O19: ABR | Q19: MAY | S19: JUN | U19: JUL | W19: AGO | Y19: SEP | AA19: OCT | AC19: NOV | AE19: DIC
A20: Engase de rodamientos | G20: Semanal | I20: S1 | J20: S2 | K20: S1 | L20: S2 | M20: S1 | N20: S2 | O20: 0 | P20: 0 | Q20: 0 | R20: 0 | S20: 0 | T20: 0 | U20: 0 | V20: 0 | W20: 0 | X20: 0 | Y20: 0 | Z20: 0 | AA20: 0 | AB20: 0 | AC20: 0 | AD20: 0 | AE20: 0 | AF20: 0
I21: S3 | J21: S4 | K21: S3 | L21: S4 | M21: S3 | N21: S4 | O21: 0 | P21: 0 | Q21: 0 | R21: 0 | S21: 0 | T21: 0 | U21: 0 | V21: 0 | W21: 0 | X21: 0 | Y21: 0 | Z21: 0 | AA21: 0 | AB21: 0 | AC21: 0 | AD21: 0 | AE21: 0 | AF21: 0
A22: Revisión y limpieza del circuito electrico | G22: Cada dos dias | I22: S1 | J22: S2 | K22: S1 | L22: S2 | M22: S1 | N22: S2 | O22: 0 | P22: 0 | Q22: 0 | R22: 0 | S22: 0 | T22: 0 | U22: 0 | V22: 0 | W22: 0 | X22: 0 | Y22: 0 | Z22: 0 | AA22: 0 | AB22: 0 | AC22: 0 | AD22: 0 | AE22: 0 | AF22: 0
I23: S3 | J23: S4 | K23: S3 | L23: S4 | M23: S3 | N23: S4 | O23: 0 | P23: 0 | Q23: 0 | R23: 0 | S23: 0 | T23: 0 | U23: 0 | V23: 0 | W23: 0 | X23: 0 | Y23: 0 | Z23: 0 | AA23: 0 | AB23: 0 | AC23: 0 | AD23: 0 | AE23: 0 | AF23: 0
A24: Cambio de martillos | G24: Semestral | I24: S1 | J24: S2 | K24: S1 | L24: S2 | M24: S1 | N24: S2 | O24: S1 | P24: S2 | Q24: S1 | R24: 0 | S24: S1 | T24: S2 | U24: S1 | V24: S2 | W24: S1 | X24: S2 | Y24: S1 | Z24: S2 | AA24: S1 | AB24: S2 | AC24: S1 | AD24: 0 | AE24: S1 | AF24: S2
I25: S3 | J25: S4 | K25: S3 | L25: S4 | M25: S3 | N25: S4 | O25: S3 | P25: S4 | Q25: S3 | R25: S4 | S25: S3 | T25: S4 | U25: S3 | V25: S4 | W25: S3 | X25: S4 | Y25: S3 | Z25: S4 | AA25: S3 | AB25: S4 | AC25: S3 | AD25: S4 | AE25: S3 | AF25: S4
A26: Limpieza de criba | G26: Semanal | I26: S1 | J26: S2 | K26: S1 | L26: S2 | M26: S1 | N26: S2 | O26: 0 | P26: 0 | Q26: 0 | R26: 0 | S26: 0 | T26: 0 | U26: 0 | V26: 0 | W26: 0 | X26: 0 | Y26: 0 | Z26: 0 | AA26: 0 | AB26: 0 | AC26: 0 | AD26: 0 | AE26: 0 | AF26: 0
I27: S3 | J27: S4 | K27: S3 | L27: S4 | M27: S3 | N27: S4 | O27: 0 | P27: 0 | Q27: 0 | R27: 0 | S27: 0 | T27: 0 | U27: 0 | V27: 0 | W27: 0 | X27: 0 | Y27: 0 | Z27: 0 | AA27: 0 | AB27: 0 | AC27: 0 | AD27: 0 | AE27: 0 | AF27: 0
I28: S1 | J28: S2 | K28: S1 | L28: S2 | M28: S1 | N28: S2 | O28: S1 | P28: S2 | Q28: S1 | R28: S2 | S28: S1 | T28: S2 | U28: S1 | V28: S2 | W28: S1 | X28: S2 | Y28: S1 | Z28: S2 | AA28: S1 | AB28: S2 | AC28: S1 | AD28: S2 | AE28: S1 | AF28: S2
I29: S3 | J29: S4 | K29: S3 | L29: S4 | M29: S3 | N29: S4 | O29: S3 | P29: S4 | Q29: S3 | R29: S4 | S29: S3 | T29: S4 | U29: S3 | V29: S4 | W29: S3 | X29: S4 | Y29: S3 | Z29: S4 | AA29: S3 | AB29: S4 | AC29: S3 | AD29: S4 | AE29: S3 | AF29: S4
I30: S1 | J30: S2 | K30: S1 | L30: S2 | M30: S1 | N30: S2 | O30: S1 | P30: S2 | Q30: S1 | R30: S2 | S30: S1 | T30: S2 | U30: S1 | V30: S2 | W30: S1 | X30: S2 | Y30: S1 | Z30: S2 | AA30: S1 | AB30: S2 | AC30: S1 | AD30: S2 | AE30: S1 | AF30: S2
I31: S3 | J31: S4 | K31: S3 | L31: S4 | M31: S3 | N31: S4 | O31: S3 | P31: S4 | Q31: S3 | R31: S4 | S31: S3 | T31: S4 | U31: S3 | V31: S4 | W31: S3 | X31: S4 | Y31: S3 | Z31: S4 | AA31: S3 | AB31: S4 | AC31: S3 | AD31: S4 | AE31: S3 | AF31: S4
I32: S1 | J32: S2 | K32: S1 | L32: S2 | M32: S1 | N32: S2 | O32: S1 | P32: S2 | Q32: S1 | R32: S2 | S32: S1 | T32: S2 | U32: S1 | V32: S2 | W32: S1 | X32: S2 | Y32: S1 | Z32: S2 | AA32: S1 | AB32: S2 | AC32: S1 | AD32: S2 | AE32: S1 | AF32: S2
I33: S3 | J33: S4 | K33: S3 | L33: S4 | M33: S3 | N33: S4 | O33: S3 | P33: S4 | Q33: S3 | R33: S4 | S33: S3 | T33: S4 | U33: S3 | V33: S4 | W33: S3 | X33: S4 | Y33: S3 | Z33: S4 | AA33: S3 | AB33: S4 | AC33: S3 | AD33: S4 | AE33: S3 | AF33: S4
I34: S1 | J34: S2 | K34: S1 | L34: S2 | M34: S1 | N34: S2 | O34: S1 | P34: S2 | Q34: S1 | R34: S2 | S34: S1 | T34: S2 | U34: S1 | V34: S2 | W34: S1 | X34: S2 | Y34: S1 | Z34: S2 | AA34: S1 | AB34: S2 | AC34: S1 | AD34: S2 | AE34: S1 | AF34: S2
I35: S3 | J35: S4 | K35: S3 | L35: S4 | M35: S3 | N35: S4 | O35: S3 | P35: S4 | Q35: S3 | R35: S4 | S35: S3 | T35: S4 | U35: S3 | V35: S4 | W35: S3 | X35: S4 | Y35: S3 | Z35: S4 | AA35: S3 | AB35: S4 | AC35: S3 | AD35: S4 | AE35: S3 | AF35: S4
B37: RELACION DEL MANTENIMIENTOS CORRECTIVOS / PREVENTIVOS
B38: N° | C38: FECHA | D38: PROVEEDOR | G38: TIPO MTO | I38: INTERVENCIÓN | M38: DETALLES DEL MANTENIIMIENTO | AA38: RESPONSABLE
G39: PV | H39: CT | I39: Int. | K39: Ext.
B40: M1
B41: M2
B42: M3
B43: M4
B44: M5
B45: M6
B46: M7
B47: M8

Sheet 09
D1: SISTEMA DE GESTIÓN INTEGRAL HOJA DE VIDA Y MANTENIMIENTO DE SISTEMAS DE CONTROL DE EMISIONES | AE1: SC
AE2: SS
D3: CODIGO: RC-SI55 | P3: VERSIÓN: 0
B6: ID. SISTEMA | E6: 09 | F6: TUBO ENFRIADOR - PLANTA 1 | AC6: =AVERAGE(I20:AF27) -> 0
A8: INFORMACION GENERAL
R9: FOTOGRAFIA SISTEMA DE CONTROL
B10: Marca
B11: Fecha Fabricación
B12: Tío de Ducto
B13: Tipo de Combustible
B14: Horas operación/día
A17: MANTENIMIENTO PREVENTIVO 2025 Marque con "0" los tiempos en los que se programará el mantenimiento; marque "1" cuando los mantenimientos se hayan cumplido | AC17: CARGUE DE EVIDENCIAS
A19: ACTIIDAD | I19: ENE | K19: FEB | M19: MAR | O19: ABR | Q19: MAY | S19: JUN | U19: JUL | W19: AGO | Y19: SEP | AA19: OCT | AC19: NOV | AE19: DIC
A20: Engase de rodamientos | G20: Semanal | I20: S1 | J20: S2 | K20: S1 | L20: S2 | M20: S1 | N20: S2 | O20: 0 | P20: 0 | Q20: 0 | R20: 0 | S20: 0 | T20: 0 | U20: 0 | V20: 0 | W20: 0 | X20: 0 | Y20: 0 | Z20: 0 | AA20: 0 | AB20: 0 | AC20: 0 | AD20: 0 | AE20: 0 | AF20: 0
I21: S3 | J21: S4 | K21: S3 | L21: S4 | M21: S3 | N21: S4 | O21: 0 | P21: 0 | Q21: 0 | R21: 0 | S21: 0 | T21: 0 | U21: 0 | V21: 0 | W21: 0 | X21: 0 | Y21: 0 | Z21: 0 | AA21: 0 | AB21: 0 | AC21: 0 | AD21: 0 | AE21: 0 | AF21: 0
A22: Revisión y limpieza del circuito electrico | G22: Semanal | I22: S1 | J22: S2 | K22: S1 | L22: S2 | M22: S1 | N22: S2 | O22: 0 | P22: 0 | Q22: 0 | R22: 0 | S22: 0 | T22: 0 | U22: 0 | V22: 0 | W22: 0 | X22: 0 | Y22: 0 | Z22: 0 | AA22: 0 | AB22: 0 | AC22: 0 | AD22: 0 | AE22: 0 | AF22: 0
I23: S3 | J23: S4 | K23: S3 | L23: S4 | M23: S3 | N23: S4 | O23: 0 | P23: 0 | Q23: 0 | R23: 0 | S23: 0 | T23: 0 | U23: 0 | V23: 0 | W23: 0 | X23: 0 | Y23: 0 | Z23: 0 | AA23: 0 | AB23: 0 | AC23: 0 | AD23: 0 | AE23: 0 | AF23: 0
A24: Cambio de pista de tubo enfriador | G24: PENDIENTE PROGRAMAR | I24: S1 | J24: S2 | K24: S1 | L24: S2 | M24: S1 | N24: S2 | O24: S1 | P24: S2 | Q24: S1 | R24: S2 | S24: S1 | T24: S2 | U24: S1 | V24: S2 | W24: S1 | X24: S2 | Y24: S1 | Z24: S2 | AA24: S1 | AB24: S2 | AC24: S1 | AD24: S2 | AE24: S1 | AF24: S2
I25: S3 | J25: S4 | K25: S3 | L25: S4 | M25: S3 | N25: S4 | O25: S3 | P25: S4 | Q25: S3 | R25: S4 | S25: S3 | T25: S4 | U25: S3 | V25: S4 | W25: S3 | X25: S4 | Y25: S3 | Z25: S4 | AA25: S3 | AB25: S4 | AC25: S3 | AD25: S4 | AE25: S3 | AF25: S4
A26: Limpieza y engase de rodillos y patines | G26: Semanal | I26: S1 | J26: S2 | K26: S1 | L26: S2 | M26: S1 | N26: S2 | O26: 0 | P26: 0 | Q26: 0 | R26: 0 | S26: 0 | T26: 0 | U26: 0 | V26: 0 | W26: 0 | X26: 0 | Y26: 0 | Z26: 0 | AA26: 0 | AB26: 0 | AC26: 0 | AD26: 0 | AE26: 0 | AF26: 0
I27: S3 | J27: S4 | K27: S3 | L27: S4 | M27: S3 | N27: S4 | O27: 0 | P27: 0 | Q27: 0 | R27: 0 | S27: 0 | T27: 0 | U27: 0 | V27: 0 | W27: 0 | X27: 0 | Y27: 0 | Z27: 0 | AA27: 0 | AB27: 0 | AC27: 0 | AD27: 0 | AE27: 0 | AF27: 0
I28: S1 | J28: S2 | K28: S1 | L28: S2 | M28: S1 | N28: S2 | O28: S1 | P28: S2 | Q28: S1 | R28: S2 | S28: S1 | T28: S2 | U28: S1 | V28: S2 | W28: S1 | X28: S2 | Y28: S1 | Z28: S2 | AA28: S1 | AB28: S2 | AC28: S1 | AD28: S2 | AE28: S1 | AF28: S2
I29: S3 | J29: S4 | K29: S3 | L29: S4 | M29: S3 | N29: S4 | O29: S3 | P29: S4 | Q29: S3 | R29: S4 | S29: S3 | T29: S4 | U29: S3 | V29: S4 | W29: S3 | X29: S4 | Y29: S3 | Z29: S4 | AA29: S3 | AB29: S4 | AC29: S3 | AD29: S4 | AE29: S3 | AF29: S4
I30: S1 | J30: S2 | K30: S1 | L30: S2 | M30: S1 | N30: S2 | O30: S1 | P30: S2 | Q30: S1 | R30: S2 | S30: S1 | T30: S2 | U30: S1 | V30: S2 | W30: S1 | X30: S2 | Y30: S1 | Z30: S2 | AA30: S1 | AB30: S2 | AC30: S1 | AD30: S2 | AE30: S1 | AF30: S2
I31: S3 | J31: S4 | K31: S3 | L31: S4 | M31: S3 | N31: S4 | O31: S3 | P31: S4 | Q31: S3 | R31: S4 | S31: S3 | T31: S4 | U31: S3 | V31: S4 | W31: S3 | X31: S4 | Y31: S3 | Z31: S4 | AA31: S3 | AB31: S4 | AC31: S3 | AD31: S4 | AE31: S3 | AF31: S4
I32: S1 | J32: S2 | K32: S1 | L32: S2 | M32: S1 | N32: S2 | O32: S1 | P32: S2 | Q32: S1 | R32: S2 | S32: S1 | T32: S2 | U32: S1 | V32: S2 | W32: S1 | X32: S2 | Y32: S1 | Z32: S2 | AA32: S1 | AB32: S2 | AC32: S1 | AD32: S2 | AE32: S1 | AF32: S2
I33: S3 | J33: S4 | K33: S3 | L33: S4 | M33: S3 | N33: S4 | O33: S3 | P33: S4 | Q33: S3 | R33: S4 | S33: S3 | T33: S4 | U33: S3 | V33: S4 | W33: S3 | X33: S4 | Y33: S3 | Z33: S4 | AA33: S3 | AB33: S4 | AC33: S3 | AD33: S4 | AE33: S3 | AF33: S4
I34: S1 | J34: S2 | K34: S1 | L34: S2 | M34: S1 | N34: S2 | O34: S1 | P34: S2 | Q34: S1 | R34: S2 | S34: S1 | T34: S2 | U34: S1 | V34: S2 | W34: S1 | X34: S2 | Y34: S1 | Z34: S2 | AA34: S1 | AB34: S2 | AC34: S1 | AD34: S2 | AE34: S1 | AF34: S2
I35: S3 | J35: S4 | K35: S3 | L35: S4 | M35: S3 | N35: S4 | O35: S3 | P35: S4 | Q35: S3 | R35: S4 | S35: S3 | T35: S4 | U35: S3 | V35: S4 | W35: S3 | X35: S4 | Y35: S3 | Z35: S4 | AA35: S3 | AB35: S4 | AC35: S3 | AD35: S4 | AE35: S3 | AF35: S4
I36: S1 | J36: S2 | K36: S1 | L36: S2 | M36: S1 | N36: S2 | O36: S1 | P36: S2 | Q36: S1 | R36: S2 | S36: S1 | T36: S2 | U36: S1 | V36: S2 | W36: S1 | X36: S2 | Y36: S1 | Z36: S2 | AA36: S1 | AB36: S2 | AC36: S1 | AD36: S2 | AE36: S1 | AF36: S2
I37: S3 | J37: S4 | K37: S3 | L37: S4 | M37: S3 | N37: S4 | O37: S3 | P37: S4 | Q37: S3 | R37: S4 | S37: S3 | T37: S4 | U37: S3 | V37: S4 | W37: S3 | X37: S4 | Y37: S3 | Z37: S4 | AA37: S3 | AB37: S4 | AC37: S3 | AD37: S4 | AE37: S3 | AF37: S4
B39: RELACION DEL MANTENIMIENTOS CORRECTIVOS / PREVENTIVOS
B40: N° | C40: FECHA | D40: PROVEEDOR | G40: TIPO MTO | I40: INTERVENCIÓN | M40: DETALLES DEL MANTENIIMIENTO | AA40: RESPONSABLE
G41: PV | H41: CT | I41: Int. | K41: Ext.
B42: M1
B43: M2
B44: M3
B45: M4
B46: M5
B47: M6
...

Sheet 10
D1: SISTEMA DE GESTIÓN INTEGRAL HOJA DE VIDA Y MANTENIMIENTO DE SISTEMAS DE CONTROL DE EMISIONES | AE1: SC
AE2: SS
D3: CODIGO: RC-SI55 | P3: VERSIÓN: 0
B6: ID. SISTEMA | E6: 10 | F6: BANDAS TRANSPORTADORAS - PLANTA 1 | AC6: =AVERAGE(I20:AF27) -> 0
A8: INFORMACION GENERAL
R9: FOTOGRAFIA SISTEMA DE CONTROL
B10: Marca
B11: Fecha Fabricación
B12: Tío de Ducto
B13: Tipo de Combustible
B14: Horas operación/día
A17: MANTENIMIENTO PREVENTIVO 2025 Marque con "0" los tiempos en los que se programará el mantenimiento; marque "1" cuando los mantenimientos se hayan cumplido | AC17: CARGUE DE EVIDENCIAS
A19: ACTIIDAD | I19: ENE | K19: FEB | M19: MAR | O19: ABR | Q19: MAY | S19: JUN | U19: JUL | W19: AGO | Y19: SEP | AA19: OCT | AC19: NOV | AE19: DIC
A20: Engase de rodamientos | G20: Semanal | I20: S1 | J20: S2 | K20: S1 | L20: S2 | M20: S1 | N20: S2 | O20: 0 | P20: 0 | Q20: 0 | R20: 0 | S20: 0 | T20: 0 | U20: 0 | V20: 0 | W20: 0 | X20: 0 | Y20: 0 | Z20: 0 | AA20: 0 | AB20: 0 | AC20: 0 | AD20: 0 | AE20: 0 | AF20: 0
I21: S3 | J21: S4 | K21: S3 | L21: S4 | M21: S3 | N21: S4 | O21: 0 | P21: 0 | Q21: 0 | R21: 0 | S21: 0 | T21: 0 | U21: 0 | V21: 0 | W21: 0 | X21: 0 | Y21: 0 | Z21: 0 | AA21: 0 | AB21: 0 | AC21: 0 | AD21: 0 | AE21: 0 | AF21: 0
A22: Revisión del caucho de la banda | G22: Diario | I22: S1 | J22: S2 | K22: S1 | L22: S2 | M22: S1 | N22: S2 | O22: 0 | P22: 0 | Q22: 0 | R22: 0 | S22: 0 | T22: 0 | U22: 0 | V22: 0 | W22: 0 | X22: 0 | Y22: 0 | Z22: 0 | AA22: 0 | AB22: 0 | AC22: 0 | AD22: 0 | AE22: 0 | AF22: 0
I23: S3 | J23: S4 | K23: S3 | L23: S4 | M23: S3 | N23: S4 | O23: 0 | P23: 0 | Q23: 0 | R23: 0 | S23: 0 | T23: 0 | U23: 0 | V23: 0 | W23: 0 | X23: 0 | Y23: 0 | Z23: 0 | AA23: 0 | AB23: 0 | AC23: 0 | AD23: 0 | AE23: 0 | AF23: 0
A24: Ajuste de tensores | G24: Diario | I24: S1 | J24: S2 | K24: S1 | L24: S2 | M24: S1 | N24: S2 | O24: 0 | P24: 0 | Q24: 0 | R24: 0 | S24: 0 | T24: 0 | U24: 0 | V24: 0 | W24: 0 | X24: 0 | Y24: 0 | Z24: 0 | AA24: 0 | AB24: 0 | AC24: 0 | AD24: 0 | AE24: 0 | AF24: 0
I25: S3 | J25: S4 | K25: S3 | L25: S4 | M25: S3 | N25: S4 | O25: 0 | P25: 0 | Q25: 0 | R25: 0 | S25: 0 | T25: 0 | U25: 0 | V25: 0 | W25: 0 | X25: 0 | Y25: 0 | Z25: 0 | AA25: 0 | AB25: 0 | AC25: 0 | AD25: 0 | AE25: 0 | AF25: 0
A26: Limpieza general de la banda | G26: Diario | I26: S1 | J26: S2 | K26: S1 | L26: S2 | M26: S1 | N26: S2 | O26: 0 | P26: 0 | Q26: 0 | R26: 0 | S26: 0 | T26: 0 | U26: 0 | V26: 0 | W26: 0 | X26: 0 | Y26: 0 | Z26: 0 | AA26: 0 | AB26: 0 | AC26: 0 | AD26: 0 | AE26: 0 | AF26: 0
I27: S3 | J27: S4 | K27: S3 | L27: S4 | M27: S3 | N27: S4 | O27: 0 | P27: 0 | Q27: 0 | R27: 0 | S27: 0 | T27: 0 | U27: 0 | V27: 0 | W27: 0 | X27: 0 | Y27: 0 | Z27: 0 | AA27: 0 | AB27: 0 | AC27: 0 | AD27: 0 | AE27: 0 | AF27: 0
I28: S1 | J28: S2 | K28: S1 | L28: S2 | M28: S1 | N28: S2 | O28: S1 | P28: S2 | Q28: S1 | R28: S2 | S28: S1 | T28: S2 | U28: S1 | V28: S2 | W28: S1 | X28: S2 | Y28: S1 | Z28: S2 | AA28: S1 | AB28: S2 | AC28: S1 | AD28: S2 | AE28: S1 | AF28: S2
I29: S3 | J29: S4 | K29: S3 | L29: S4 | M29: S3 | N29: S4 | O29: S3 | P29: S4 | Q29: S3 | R29: S4 | S29: S3 | T29: S4 | U29: S3 | V29: S4 | W29: S3 | X29: S4 | Y29: S3 | Z29: S4 | AA29: S3 | AB29: S4 | AC29: S3 | AD29: S4 | AE29: S3 | AF29: S4
I30: S1 | J30: S2 | K30: S1 | L30: S2 | M30: S1 | N30: S2 | O30: S1 | P30: S2 | Q30: S1 | R30: S2 | S30: S1 | T30: S2 | U30: S1 | V30: S2 | W30: S1 | X30: S2 | Y30: S1 | Z30: S2 | AA30: S1 | AB30: S2 | AC30: S1 | AD30: S2 | AE30: S1 | AF30: S2
I31: S3 | J31: S4 | K31: S3 | L31: S4 | M31: S3 | N31: S4 | O31: S3 | P31: S4 | Q31: S3 | R31: S4 | S31: S3 | T31: S4 | U31: S3 | V31: S4 | W31: S3 | X31: S4 | Y31: S3 | Z31: S4 | AA31: S3 | AB31: S4 | AC31: S3 | AD31: S4 | AE31: S3 | AF31: S4
I32: S1 | J32: S2 | K32: S1 | L32: S2 | M32: S1 | N32: S2 | O32: S1 | P32: S2 | Q32: S1 | R32: S2 | S32: S1 | T32: S2 | U32: S1 | V32: S2 | W32: S1 | X32: S2 | Y32: S1 | Z32: S2 | AA32: S1 | AB32: S2 | AC32: S1 | AD32: S2 | AE32: S1 | AF32: S2
I33: S3 | J33: S4 | K33: S3 | L33: S4 | M33: S3 | N33: S4 | O33: S3 | P33: S4 | Q33: S3 | R33: S4 | S33: S3 | T33: S4 | U33: S3 | V33: S4 | W33: S3 | X33: S4 | Y33: S3 | Z33: S4 | AA33: S3 | AB33: S4 | AC33: S3 | AD33: S4 | AE33: S3 | AF33: S4
I34: S1 | J34: S2 | K34: S1 | L34: S2 | M34: S1 | N34: S2 | O34: S1 | P34: S2 | Q34: S1 | R34: S2 | S34: S1 | T34: S2 | U34: S1 | V34: S2 | W34: S1 | X34: S2 | Y34: S1 | Z34: S2 | AA34: S1 | AB34: S2 | AC34: S1 | AD34: S2 | AE34: S1 | AF34: S2
I35: S3 | J35: S4 | K35: S3 | L35: S4 | M35: S3 | N35: S4 | O35: S3 | P35: S4 | Q35: S3 | R35: S4 | S35: S3 | T35: S4 | U35: S3 | V35: S4 | W35: S3 | X35: S4 | Y35: S3 | Z35: S4 | AA35: S3 | AB35: S4 | AC35: S3 | AD35: S4 | AE35: S3 | AF35: S4
B37: RELACION DEL MANTENIMIENTOS CORRECTIVOS / PREVENTIVOS
B38: N° | C38: FECHA | D38: PROVEEDOR | G38: TIPO MTO | I38: INTERVENCIÓN | M38: DETALLES DEL MANTENIIMIENTO | AA38: RESPONSABLE
G39: PV | H39: CT | I39: Int. | K39: Ext.
B40: M1
B41: M2
B42: M3
B43: M4
B44: M5
B45: M6
B46: M7
B47: M8

Sheet 11
D1: SISTEMA DE GESTIÓN INTEGRAL HOJA DE VIDA Y MANTENIMIENTO DE SISTEMAS DE CONTROL DE EMISIONES | AE1: SC
AE2: SS
D3: CODIGO: RC-SI55 | P3: VERSIÓN: 0
B6: ID. SISTEMA | E6: 11 | F6: MEZCLADORA - PLANTA 2 | AC6: =AVERAGE(I20:AF25) -> 0
A8: INFORMACION GENERAL
R9: FOTOGRAFIA SISTEMA DE CONTROL
B10: Marca
B11: Fecha Fabricación
B12: Tío de Ducto
B13: Tipo de Combustible
B14: Horas operación/día
A17: MANTENIMIENTO PREVENTIVO 2025 Marque con "0" los tiempos en los que se programará el mantenimiento; marque "1" cuando los mantenimientos se hayan cumplido | AC17: CARGUE DE EVIDENCIAS
A19: ACTIIDAD | I19: ENE | K19: FEB | M19: MAR | O19: ABR | Q19: MAY | S19: JUN | U19: JUL | W19: AGO | Y19: SEP | AA19: OCT | AC19: NOV | AE19: DIC
A20: Engrase de Rodamientos | G20: Semanal | I20: S1 | J20: S2 | K20: S1 | L20: S2 | M20: S1 | N20: S2 | O20: 0 | P20: 0 | Q20: 0 | R20: 0 | S20: 0 | T20: 0 | U20: 0 | V20: 0 | W20: 0 | X20: 0 | Y20: 0 | Z20: 0 | AA20: 0 | AB20: 0 | AC20: 0 | AD20: 0 | AE20: 0 | AF20: 0
I21: S3 | J21: S4 | K21: S3 | L21: S4 | M21: S3 | N21: S4 | O21: 0 | P21: 0 | Q21: 0 | R21: 0 | S21: 0 | T21: 0 | U21: 0 | V21: 0 | W21: 0 | X21: 0 | Y21: 0 | Z21: 0 | AA21: 0 | AB21: 0 | AC21: 0 | AD21: 0 | AE21: 0 | AF21: 0
A22: Limpieza de Aspas | G22: Semanal | I22: S1 | J22: S2 | K22: S1 | L22: S2 | M22: S1 | N22: S2 | O22: 0 | P22: 0 | Q22: 0 | R22: 0 | S22: 0 | T22: 0 | U22: 0 | V22: 0 | W22: 0 | X22: 0 | Y22: 0 | Z22: 0 | AA22: 0 | AB22: 0 | AC22: 0 | AD22: 0 | AE22: 0 | AF22: 0
I23: S3 | J23: S4 | K23: S3 | L23: S4 | M23: S3 | N23: S4 | O23: 0 | P23: 0 | Q23: 0 | R23: 0 | S23: 0 | T23: 0 | U23: 0 | V23: 0 | W23: 0 | X23: 0 | Y23: 0 | Z23: 0 | AA23: 0 | AB23: 0 | AC23: 0 | AD23: 0 | AE23: 0 | AF23: 0
A24: Revisión y limpieza del circuito electrico | G24: Diario | I24: S1 | J24: S2 | K24: S1 | L24: S2 | M24: S1 | N24: S2 | O24: 0 | P24: 0 | Q24: 0 | R24: 0 | S24: 0 | T24: 0 | U24: 0 | V24: 0 | W24: 0 | X24: 0 | Y24: 0 | Z24: 0 | AA24: 0 | AB24: 0 | AC24: 0 | AD24: 0 | AE24: 0 | AF24: 0
I25: S3 | J25: S4 | K25: S3 | L25: S4 | M25: S3 | N25: S4 | O25: 0 | P25: 0 | Q25: 0 | R25: 0 | S25: 0 | T25: 0 | U25: 0 | V25: 0 | W25: 0 | X25: 0 | Y25: 0 | Z25: 0 | AA25: 0 | AB25: 0 | AC25: 0 | AD25: 0 | AE25: 0 | AF25: 0
I26: S1 | J26: S2 | K26: S1 | L26: S2 | M26: S1 | N26: S2 | O26: S1 | P26: S2 | Q26: S1 | R26: S2 | S26: S1 | T26: S2 | U26: S1 | V26: S2 | W26: S1 | X26: S2 | Y26: S1 | Z26: S2 | AA26: S1 | AB26: S2 | AC26: S1 | AD26: S2 | AE26: S1 | AF26: S2
I27: S3 | J27: S4 | K27: S3 | L27: S4 | M27: S3 | N27: S4 | O27: S3 | P27: S4 | Q27: S3 | R27: S4 | S27: S3 | T27: S4 | U27: S3 | V27: S4 | W27: S3 | X27: S4 | Y27: S3 | Z27: S4 | AA27: S3 | AB27: S4 | AC27: S3 | AD27: S4 | AE27: S3 | AF27: S4
I28: S1 | J28: S2 | K28: S1 | L28: S2 | M28: S1 | N28: S2 | O28: S1 | P28: S2 | Q28: S1 | R28: S2 | S28: S1 | T28: S2 | U28: S1 | V28: S2 | W28: S1 | X28: S2 | Y28: S1 | Z28: S2 | AA28: S1 | AB28: S2 | AC28: S1 | AD28: S2 | AE28: S1 | AF28: S2
I29: S3 | J29: S4 | K29: S3 | L29: S4 | M29: S3 | N29: S4 | O29: S3 | P29: S4 | Q29: S3 | R29: S4 | S29: S3 | T29: S4 | U29: S3 | V29: S4 | W29: S3 | X29: S4 | Y29: S3 | Z29: S4 | AA29: S3 | AB29: S4 | AC29: S3 | AD29: S4 | AE29: S3 | AF29: S4
I30: S1 | J30: S2 | K30: S1 | L30: S2 | M30: S1 | N30: S2 | O30: S1 | P30: S2 | Q30: S1 | R30: S2 | S30: S1 | T30: S2 | U30: S1 | V30: S2 | W30: S1 | X30: S2 | Y30: S1 | Z30: S2 | AA30: S1 | AB30: S2 | AC30: S1 | AD30: S2 | AE30: S1 | AF30: S2
I31: S3 | J31: S4 | K31: S3 | L31: S4 | M31: S3 | N31: S4 | O31: S3 | P31: S4 | Q31: S3 | R31: S4 | S31: S3 | T31: S4 | U31: S3 | V31: S4 | W31: S3 | X31: S4 | Y31: S3 | Z31: S4 | AA31: S3 | AB31: S4 | AC31: S3 | AD31: S4 | AE31: S3 | AF31: S4
I32: S9 | J32: S10 | K32: S9 | L32: S10 | M32: S9 | N32: S10 | O32: S9 | P32: S10 | Q32: S9 | R32: S10 | S32: S9 | T32: S10 | U32: S9 | V32: S10 | W32: S9 | X32: S10 | Y32: S9 | Z32: S10 | AA32: S9 | AB32: S10 | AC32: S9 | AD32: S10 | AE32: S9 | AF32: S10
I33: S11 | J33: S12 | K33: S11 | L33: S12 | M33: S11 | N33: S12 | O33: S11 | P33: S12 | Q33: S11 | R33: S12 | S33: S11 | T33: S12 | U33: S11 | V33: S12 | W33: S11 | X33: S12 | Y33: S11 | Z33: S12 | AA33: S11 | AB33: S12 | AC33: S11 | AD33: S12 | AE33: S11 | AF33: S12
I34: S1 | J34: S2 | K34: S1 | L34: S2 | M34: S1 | N34: S2 | O34: S1 | P34: S2 | Q34: S1 | R34: S2 | S34: S1 | T34: S2 | U34: S1 | V34: S2 | W34: S1 | X34: S2 | Y34: S1 | Z34: S2 | AA34: S1 | AB34: S2 | AC34: S1 | AD34: S2 | AE34: S1 | AF34: S2
I35: S3 | J35: S4 | K35: S3 | L35: S4 | M35: S3 | N35: S4 | O35: S3 | P35: S4 | Q35: S3 | R35: S4 | S35: S3 | T35: S4 | U35: S3 | V35: S4 | W35: S3 | X35: S4 | Y35: S3 | Z35: S4 | AA35: S3 | AB35: S4 | AC35: S3 | AD35: S4 | AE35: S3 | AF35: S4
B37: RELACION DEL MANTENIMIENTOS CORRECTIVOS / PREVENTIVOS
B38: N° | C38: FECHA | D38: PROVEEDOR | G38: TIPO MTO | I38: INTERVENCIÓN | M38: DETALLES DEL MANTENIIMIENTO | AA38: RESPONSABLE
G39: PV | H39: CT | I39: Int. | K39: Ext.
B40: M1
B41: M2
B42: M3
B43: M4
B44: M5
B45: M6
B46: M7
B47: M8

Sheet 12
D1: SISTEMA DE GESTIÓN INTEGRAL HOJA DE VIDA Y MANTENIMIENTO DE SISTEMAS DE CONTROL DE EMISIONES | AE1: SC
AE2: SS
D3: CODIGO: RC-SI55 | P3: VERSIÓN: 0
B6: ID. SISTEMA | E6: 12 | F6: OLLA GRANULADORA - PLANTA 2 | AC6: =AVERAGE(I20:AF27) -> 0
A8: INFORMACION GENERAL
R9: FOTOGRAFIA SISTEMA DE CONTROL
B10: Marca
B11: Fecha Fabricación
B12: Tío de Ducto
B13: Tipo de Combustible
B14: Horas operación/día
A17: MANTENIMIENTO PREVENTIVO 2025 Marque con "0" los tiempos en los que se programará el mantenimiento; marque "1" cuando los mantenimientos se hayan cumplido | AC17: CARGUE DE EVIDENCIAS
A19: ACTIIDAD | I19: ENE | K19: FEB | M19: MAR | O19: ABR | Q19: MAY | S19: JUN | U19: JUL | W19: AGO | Y19: SEP | AA19: OCT | AC19: NOV | AE19: DIC
A20: Engrase de rodamientos | G20: Semanal | I20: S1 | J20: S2 | K20: S1 | L20: S2 | M20: S1 | N20: S2 | O20: 0 | P20: 0 | Q20: 0 | R20: 0 | S20: 0 | T20: 0 | U20: 0 | V20: 0 | W20: 0 | X20: 0 | Y20: 0 | Z20: 0 | AA20: 0 | AB20: 0 | AC20: 0 | AD20: 0 | AE20: 0 | AF20: 0
I21: S3 | J21: S4 | K21: S3 | L21: S4 | M21: S3 | N21: S4 | O21: 0 | P21: 0 | Q21: 0 | R21: 0 | S21: 0 | T21: 0 | U21: 0 | V21: 0 | W21: 0 | X21: 0 | Y21: 0 | Z21: 0 | AA21: 0 | AB21: 0 | AC21: 0 | AD21: 0 | AE21: 0 | AF21: 0
A22: Limpieza interna y externa de la olla | G22: Diario | I22: S1 | J22: S2 | K22: S1 | L22: S2 | M22: S1 | N22: S2 | O22: 0 | P22: 0 | Q22: 0 | R22: 0 | S22: 0 | T22: 0 | U22: 0 | V22: 0 | W22: 0 | X22: 0 | Y22: 0 | Z22: 0 | AA22: 0 | AB22: 0 | AC22: 0 | AD22: 0 | AE22: 0 | AF22: 0
I23: S3 | J23: S4 | K23: S3 | L23: S4 | M23: S3 | N23: S4 | O23: 0 | P23: 0 | Q23: 0 | R23: 0 | S23: 0 | T23: 0 | U23: 0 | V23: 0 | W23: 0 | X23: 0 | Y23: 0 | Z23: 0 | AA23: 0 | AB23: 0 | AC23: 0 | AD23: 0 | AE23: 0 | AF23: 0
