Workbook
Name CID: '[1]Lista de Materias Primas'!$D:$D

Sheet tolerancias
A1: Elemento | B1: N-tot | C1: P-as | D1: K-sol | E1: CaO-tot | F1: MgO-tot | G1: S-tot | H1: B | I1: Co | J1: Cu-sol | K1: Fe-sol | L1: Mn-sol | M1: Mo-sol | N1: SiO2-tot | O1: SiO2-sol | P1: Zn-tot
A2: npk | B2: 0.03 | C2: 0.03 | D2: 0.03 | E2: NA | F2: NA | G2: NA | H2: NA | I2: NA | J2: NA | K2: NA | L2: NA | M2: NA | N2: NA | O2: NA | P2: NA
A3: sec-solo | B3: NA | C3: NA | D3: NA | E3: 0.05 | F3: 0.05 | G3: 0.05 | H3: NA | I3: NA | J3: NA | K3: NA | L3: NA | M3: NA | N3: NA | O3: NA | P3: NA
A4: micro-solo | B4: NA | C4: NA | D4: NA | E4: NA | F4: NA | G4: NA | H4: 0.005 | I4: 0.0002 | J4: 0.002 | K4: 0.002 | L4: 0.002 | M4: 0.0002 | N4: 0.002 | O4: NA | P4: 0.005
A5: micro-mezcla | B5: NA | C5: NA | D5: NA | E5: NA | F5: NA | G5: NA | H5: 0.0002 | I5: 2e-05 | J5: 0.0001 | K5: 0.0001 | L5: 0.0001 | M5: 5e-05 | N5: 0.0002 | O5: NA | P5: 0.0002

Sheet sulafto_calcioP
B5: MATERIA PRIMA | C5: kg / Ton | D5: %/100 kg | E5: C | F5: N | G5: N-NH4 | H5: N-NO3 | I5: N-org | J5: N-ur | K5: P | L5: K | M5: CaO | N5: MgO | O5: S | P5: B | Q5: Co | R5: Cu | S5: Fe | T5: Mn | U5: Mo | V5: SiO2 | W5: Zn | X5: Na
B6: SULFATO CALCIO_ANIBAL ARANGO_P | C6: 750 | D6: 75 | M6: 0.26 | N6: 0 | O6: 0.13
B7: KIESERITA_MANUCHAR_P | C7: 50 | D7: 5 | M7: 0 | N7: 0.25 | O7: 0.2
B8: CARBONATO CALCIO_AGROCALES_P | C8: 150 | D8: 15 | M8: 0.44 | N8: 0 | O8: 0
B9: BENTONITA GRIS_HENRY CORONADO_P | C9: 50 | D9: 5 | M9: 0.062 | N9: 0.04 | O9: 0 | V9: 0.569
B13: SUMA | C13: =SUM(C6:C12) -> 1000 | D13: 100
B14: TOTAL
B16: MATERIA PRIMA | C16: kg / Ton | D16: %/100 kg | E16: Carbono organico total oxidable C | F16: Nitrogeno Total N | G16: Nitrogeno amoniacal | H16: Nitrogeno nitrico | I16: Nitrogeno organico | J16: Nitrogeno ureico | K16: Fosforo asimilable P2O5 | L16: Potasio soluble K2O | M16: Calcio CaO | N16: Magnesio MgO | O16: Azufre S | P16: Boro B | Q16: Cobalto Co | R16: Cobre Cu | S16: Hierro Fe | T16: Manganeso Mn | U16: Molibdeno Mo | V16: Silicio SiO2 | W16: Zinc Zn | X16: Sodio Na
B17: =B6 -> SULFATO CALCIO_ANIBAL ARANGO_P | C17: =C6 -> 750 | D17: =D6 -> 75 | E17: =IF(E6="","",E6*$D6/$D$13) | F17: =IF(F6="","",SUM(G17:J17)) | G17: =IF(G6="","",G6*$D6/$D$13) | H17: =IF(H6="","",H6*$D6/$D$13) | I17: =IF(I6="","",I6*$D6/$D$13) | J17: =IF(J6="","",J6*$D6/$D$13) | K17: =IF(K6="","",K6*$D6/$D$13) | L17: =IF(L6="","",L6*$D6/$D$13) | M17: =IF(M6="","",M6*$D6/$D$13) -> 0.195 | N17: =IF(N6="","",N6*$D6/$D$13) -> 0 | ... X17: =IF(X6="","",X6*$D6/$D$13)
B18: =B7 -> KIESERITA_MANUCHAR_P | C18: =C7 -> 50 | D18: =D7 -> 5 | E18: =IF(E7="","",E7*$D7/$D$13) | F18: =IF(F7="","",SUM(G18:J18)) | G18: =IF(G7="","",G7*$D7/$D$13) | H18: =IF(H7="","",H7*$D7/$D$13) | I18: =IF(I7="","",I7*$D7/$D$13) | J18: =IF(J7="","",J7*$D7/$D$13) | K18: =IF(K7="","",K7*$D7/$D$13) | L18: =IF(L7="","",L7*$D7/$D$13) | M18: =IF(M7="","",M7*$D7/$D$13) -> 0 | N18: =IF(N7="","",N7*$D7/$D$13) -> 0.0125 | ... X18: =IF(X7="","",X7*$D7/$D$13)
B19: =B8 -> CARBONATO CALCIO_AGROCALES_P | C19: =C8 -> 150 | D19: =D8 -> 15 | E19: =IF(E8="","",E8*$D8/$D$13) | F19: =IF(F8="","",SUM(G19:J19)) | G19: =IF(G8="","",G8*$D8/$D$13) | H19: =IF(H8="","",H8*$D8/$D$13) | I19: =IF(I8="","",I8*$D8/$D$13) | J19: =IF(J8="","",J8*$D8/$D$13) | K19: =IF(K8="","",K8*$D8/$D$13) | L19: =IF(L8="","",L8*$D8/$D$13) | M19: =IF(M8="","",M8*$D8/$D$13) -> 0.066 | N19: =IF(N8="","",N8*$D8/$D$13) -> 0 | ... X19: =IF(X8="","",X8*$D8/$D$13)
B20: =B9 -> BENTONITA GRIS_HENRY CORONADO_P | C20: =C9 -> 50 | D20: =D9 -> 5 | E20: =IF(E9="","",E9*$D9/$D$13) | F20: =IF(F9="","",SUM(G20:J20)) | G20: =IF(G9="","",G9*$D9/$D$13) | H20: =IF(H9="","",H9*$D9/$D$13) | I20: =IF(I9="","",I9*$D9/$D$13) | J20: =IF(J9="","",J9*$D9/$D$13) | K20: =IF(K9="","",K9*$D9/$D$13) | L20: =IF(L9="","",L9*$D9/$D$13) | M20: =IF(M9="","",M9*$D9/$D$13) -> 0.0031 | N20: =IF(N9="","",N9*$D9/$D$13) -> 0.002 | ... X20: =IF(X9="","",X9*$D9/$D$13)
E21: =IF(E10="","",E10*$D10/$D$13) | F21: =IF(F10="","",SUM(G21:J21)) | G21: =IF(G10="","",G10*$D10/$D$13) | H21: =IF(H10="","",H10*$D10/$D$13) | I21: =IF(I10="","",I10*$D10/$D$13) | J21: =IF(J10="","",J10*$D10/$D$13) | K21: =IF(K10="","",K10*$D10/$D$13) | L21: =IF(L10="","",L10*$D10/$D$13) | M21: =IF(M10="","",M10*$D10/$D$13) | N21: =IF(N10="","",N10*$D10/$D$13) | ... X21: =IF(X10="","",X10*$D10/$D$13)
E22: =IF(E11="","",E11*$D11/$D$13) | F22: =IF(F11="","",SUM(G22:J22)) | G22: =IF(G11="","",G11*$D11/$D$13) | H22: =IF(H11="","",H11*$D11/$D$13) | I22: =IF(I11="","",I11*$D11/$D$13) | J22: =IF(J11="","",J11*$D11/$D$13) | K22: =IF(K11="","",K11*$D11/$D$13) | L22: =IF(L11="","",L11*$D11/$D$13) | M22: =IF(M11="","",M11*$D11/$D$13) | N22: =IF(N11="","",N11*$D11/$D$13) | ... X22: =IF(X11="","",X11*$D11/$D$13)
E23: =IF(E12="","",E12*$D12/$D$13) | F23: =IF(F12="","",SUM(G23:J23)) | G23: =IF(G12="","",G12*$D12/$D$13) | H23: =IF(H12="","",H12*$D12/$D$13) | I23: =IF(I12="","",I12*$D12/$D$13) | J23: =IF(J12="","",J12*$D12/$D$13) | K23: =IF(K12="","",K12*$D12/$D$13) | L23: =IF(L12="","",L12*$D12/$D$13) | M23: =IF(M12="","",M12*$D12/$D$13) | N23: =IF(N12="","",N12*$D12/$D$13) | ... X23: =IF(X12="","",X12*$D12/$D$13)
B24: SUMA | C24: =SUM(C17:C23) -> 1000 | D24: 100
B25: TOTAL | E25: =SUM(E17:E23) -> 0 | F25: =SUM(F17:F23) -> 0 | G25: =SUM(G17:G23) -> 0 | H25: =SUM(H17:H23) -> 0 | I25: =SUM(I17:I23) -> 0 | J25: =SUM(J17:J23) -> 0 | K25: =SUM(K17:K23) -> 0 | L25: =SUM(L17:L23) -> 0 | ... P25: =SUM(P17:P23) -> 0 | Q25: 0 | R25: =SUM(R17:R23) -> 0 | S25: =SUM(S17:S23) -> 0 | T25: =SUM(T17:T23) -> 0 | U25: =SUM(U17:U23) -> 0 | V25: =SUM(V17:V23) -> 0.02845 | W25: =SUM(W17:W23) -> 0 | X25: =SUM(X17:X23) -> 0
B27: SOLICITUD REGISTRO | M27: 0.23 | O27: 0.12 | V27: 0.245
B28: CERTIFICADO DE ANALISIS | M28: 0.2106 | O28: 0.1518 | V28: 0.2491
B30: CONTENIDOS MINIMOS*1
B31: NPK (Formula sola o en mezcla con micronutrientes) | F31: =IF(F25=0,"",IF(F25<tolerancias!B2,"SI","NO")) | K31: =IF(K25=0,"",IF(K25<tolerancias!C2,"SI","NO")) | L31: =IF(L25=0,"",IF(L25<tolerancias!D2,"SI","NO"))
B32: Secundarios (Formula UNICAMENTE con Ca, Mg, S)
B33: Micronutrientes: Unicamente micronutrientes
B34: Micronutrientes: Mezcla con NPK o secundarios | P34: =IF(P25=0,"",IF(P25>tolerancias!H5,"SI","NO")) | Q34: =IF(Q25=0,"",IF(Q25>tolerancias!I5,"SI","NO")) | R34: =IF(R25=0,"",IF(R25>tolerancias!J5,"SI","NO")) | S34: =IF(S25=0,"",IF(S25>tolerancias!K5,"SI","NO")) | T34: =IF(T25=0,"",IF(T25>tolerancias!L5,"SI","NO")) | U34: =IF(U25=0,"",IF(U25>tolerancias!M5,"SI","NO")) | V34: =IF(V25=0,"",IF(V25>tolerancias!N5,"SI","NO")) -> SI | W34: =IF(W25=0,"",IF(W25>tolerancias!P5,"SI","NO"))
B35: *1 Resolución ICA 150 de 2003 ANEXO 11
B37: TOLERANCIAS*2
B38: Calculo | F38: =IF(F25=0,"",((-0.0005*100*100*F$25*F$25+0.0413*100*F$25+0.6533)/100)) | K38: =IF(K25=0,"",((-0.0005*100*100*K$25*K$25+0.0413*100*K$25+0.6533)/100)) | L38: =IF(L25=0,"",((-0.0007*10000*L$25*L$25+0.0769*100*L$25+0.3941)/100)) | M38: =M39 -> 0.0319305 | N38: =N39 -> 0.0068125 | O38: =O39 -> 0.0110625
B39: NPK ¿El contenido está fuera de rango [4%-32%]?*3 | F39: =IF(F25=0,"",IF(OR(F25<4.001%,F25>32.001%),"SI","NO")) | K39: =IF(K25=0,"",IF(OR(K25<4.001%,K25>32.001%),"SI","NO")) | L39: =IF(L25=0,"",IF(OR(L25<4.001%,L25>32.001%),"SI","NO")) | M39: =IF(M25=0,"",((0.42+0.105*100*M$25)/100)) -> 0.0319305 | N39: =IF(N25=0,"",((0.5+0.125*100*N$25)/100)) -> 0.0068125 | O39: =IF(O25=0,"",((0.3+0.075*100*O$25)/100)) -> 0.0110625 | P39: =IF(P25=0,"",((0.005+0.25*100*P$25)/100)) | Q39: =IF(Q25=0,"",((0.000125+0.375*100*Q$25)/100)) | R39: =IF(R25=0,"",((0.015+0.3*100*R$25)/100)) | S39: =IF(S25=0,"",((0.015+0.3*100*S$25)/100)) | T39: =IF(T25=0,"",((0.015+0.3*100*T$25)/100)) | U39: =IF(U25=0,"",((0.000125+0.375*100*U$25)/100)) | W39: =IF(W25=0,"",((0.015+0.3*100*W$25)/100)) | X39: =IF(X25=0,"",((0.015+0.3*100*X$25)/100))
B40: Secundarios y menores ¿La tolerancia supera el 50% o 1.5pp?*4 | M40: =IF(M25=0,"",IF(OR(M39>M25/2,M39>1.501%),"SI","NO")) -> SI | N40: =IF(N25=0,"",IF(OR(N39>N25/2,N39>1.501%),"SI","NO")) -> NO | O40: =IF(O25=0,"",IF(OR(O39>O25/2,O39>1.501%),"SI","NO")) -> NO | P40: =IF(P25=0,"",IF(OR(P39>P25/2,P39>1.501%),"SI","NO")) | Q40: =IF(Q25=0,"",IF(OR(Q39>Q25/2,Q39>1.501%),"SI","NO")) | R40: =IF(R25=0,"",IF(OR(R39>R25/2,R39>1.501%),"SI","NO")) | S40: =IF(S25=0,"",IF(OR(S39>S25/2,S39>1.501%),"SI","NO")) | T40: =IF(T25=0,"",IF(OR(T39>T25/2,T39>1.501%),"SI","NO")) | U40: =IF(U25=0,"",IF(OR(U39>U25/2,U39>1.501%),"SI","NO")) | V40: =IF(V5="SiO2","",IF(V25=0,"",IF(OR(V39>V25/2,V39>1.501%),"SI","NO"))) | W40: =IF(W25=0,"",IF(OR(W39>W25/2,W39>1.501%),"SI","NO")) | X40: =IF(X25=0,"",IF(OR(X39>X25/2,X39>1.501%),"SI","NO"))
B41: Tolerancia permitida | F41: =IF(F25=0,"",IF(F39="NO",F38,IF(F25<4%,0.81%,1.46%))) | K41: =IF(K25=0,"",IF(K39="NO",K38,IF(K25<4%,0.81%,1.46%))) | L41: =IF(L25=0,"",IF(L39="NO",L38,IF(L25<4%,0.69%,2.14%))) | M41: =IF(M25=0,"",IF(M40="NO",M39,1.5%)) -> 0.015 | N41: =IF(N25=0,"",IF(N40="NO",N39,1.5%)) -> 0.0068125 | O41: =IF(O25=0,"",IF(O40="NO",O39,1.5%)) -> 0.0110625 | P41: =IF(P25=0,"",IF(P39="NO",P38,1.5%)) | Q41: =IF(Q25=0,"",IF(Q39="NO",Q38,1.5%)) | R41: =IF(R25=0,"",IF(R39="NO",R38,1.5%)) | S41: =IF(S25=0,"",IF(S39="NO",S38,1.5%)) | T41: =IF(T25=0,"",IF(T39="NO",T38,1.5%)) | U41: =IF(U25=0,"",IF(U39="NO",U38,1.5%)) | V41: =IF(V5="SiO2","",IF(V25=0,"",IF(V39="NO",V38,1.5%))) | W41: =IF(W25=0,"",IF(W39="NO",W38,1.5%)) | X41: =IF(X25=0,"",IF(X39="NO",X38,1.5%))
B42: *2 NTC 1061:2020 ALCANCE: no aplica para organicos
B43: *3 NTC 1061:2020 4.1
B44: *4 NTC 1061:2020 4.2.1 - 4.2.2
B46: Tolerancia Mínima NTC | E46: =IF(E5="C","",IF(E25=0,"",E47-E41)) | F46: =IF(F25=0,"",F47-F41) | G46: =IF(G25=0,"",G47-G41) | H46: =IF(H25=0,"",H47-H41) | I46: =IF(I25=0,"",I47-I41) | J46: =IF(J25=0,"",J47-J41) | K46: =IF(K25=0,"",K47-K41) | L46: =IF(L25=0,"",L47-L41) | M46: =IF(M25=0,"",M47-M41) -> 0.215 | O46: =IF(O25=0,"",O47-O41) -> 0.1089375 | P46: =IF(P25=0,"",P47-P41) | Q46: =IF(Q25=0,"",Q47-Q41) | R46: =IF(R25=0,"",R47-R41) | S46: =IF(S25=0,"",S47-S41) | T46: =IF(T25=0,"",T47-T41) | U46: =IF(U25=0,"",U47-U41) | V46: =IF(V5="SiO2","",IF(V25=0,"",V47-V41)) | W46: =IF(W25=0,"",W47-W41) | X46: =IF(X25=0,"",X47-X41)
B47: =_xlfn.CONCAT("SOLICITUD DE REGISTRO ICA: ",B5) -> SOLICITUD DE REGISTRO ICA: MATERIA PRIMA | E47: =IF(E25=0,"",E25) | F47: =IF(F25=0,"",F25) | G47: =IF(G25=0,"",G25) | H47: =IF(H25=0,"",H25) | I47: =IF(I25=0,"",I25) | J47: =IF(J25=0,"",J25) | K47: =IF(K25=0,"",K25) | L47: =IF(L25=0,"",L25) | M47: =M27 -> 0.23 | N47: =N27 -> 0 | O47: =O27 -> 0.12 | P47: =IF(P25=0,"",P25) | Q47: =IF(Q25=0,"",Q25) | R47: =IF(R25=0,"",R25) | S47: =IF(S25=0,"",S25) | T47: =IF(T25=0,"",T25) | U47: =IF(U25=0,"",U25) | V47: =V27 -> 0.245 | W47: =IF(W25=0,"",W25) | X47: =IF(X25=0,"",X25)
B48: Tolerancia Máxima NTC | E48: =IF(E5="C","",IF(E25=0,"",E47+E41)) | F48: =IF(F25=0,"",F47+F41) | G48: =IF(G25=0,"",G47+G41) | H48: =IF(H25=0,"",H47+H41) | I48: =IF(I25=0,"",I47+I41) | J48: =IF(J25=0,"",J47+J41) | K48: =IF(K25=0,"",K47+K41) | L48: =IF(L25=0,"",L47+L41) | M48: =IF(M25=0,"",M47+M41) -> 0.245 | O48: =IF(O25=0,"",O47+O41) -> 0.1310625 | P48: =IF(P25=0,"",P47+P41) | Q48: =IF(Q25=0,"",Q47+Q41) | R48: =IF(R25=0,"",R47+R41) | S48: =IF(S25=0,"",S47+S41) | T48: =IF(T25=0,"",T47+T41) | U48: =IF(U25=0,"",U47+U41) | V48: =IF(V5="SiO2","",IF(V25=0,"",V47+V41)) | W48: =IF(W25=0,"",W47+W41) | X48: =IF(X25=0,"",X47+X41)

Sheet camasi
B5: MATERIA PRIMA | C5: kg / Ton | D5: %/100 kg | E5: C | F5: N | G5: N-NH4 | H5: N-NO3 | I5: N-org | J5: N-ur | K5: P | L5: K | M5: CaO | N5: MgO | O5: S | P5: B | Q5: Co | R5: Cu | S5: Fe | T5: Mn | U5: Mo | V5: SiO2 | W5: Zn | X5: Na
B6: KIESERITA_MANUCHAR_P | C6: 50 | D6: 5 | N6: 0.25 | O6: 0.2 | V6: 0
B7: CARBONATO CALCIO_AGROCALES_P | C7: 350 | D7: 35 | M7: 0.44 | V7: 0
B8: BENTONITA GRIS_DIDIER HOYOS_P | C8: 600 | D8: 60 | M8: 0.062 | N8: 0.04 | V8: 0.569
B13: SUMA | C13: =SUM(C6:C12) -> 1000 | D13: 100
B14: TOTAL
B16: MATERIA PRIMA | C16: kg / Ton | D16: %/100 kg | E16: Carbono organico total oxidable C | F16: Nitrogeno Total N | G16: Nitrogeno amoniacal | H16: Nitrogeno nitrico | I16: Nitrogeno organico | J16: Nitrogeno ureico | K16: Fosforo asimilable P2O5 | L16: Potasio soluble K2O | M16: Calcio CaO | N16: Magnesio MgO | O16: Azufre S | P16: Boro B | Q16: Cobalto Co | R16: Cobre Cu | S16: Hierro Fe | T16: Manganeso Mn | U16: Molibdeno Mo | V16: Silicio SiO2 | W16: Zinc Zn | X16: Sodio Na
B17: =B6 -> KIESERITA_MANUCHAR_P | C17: =C6 -> 50 | D17: =D6 -> 5 | E17: =IF(E6="","",E6*$D6/$D$13) | F17: =IF(F6="","",SUM(G17:J17)) | G17: =IF(G6="","",G6*$D6/$D$13) | H17: =IF(H6="","",H6*$D6/$D$13) | I17: =IF(I6="","",I6*$D6/$D$13) | J17: =IF(J6="","",J6*$D6/$D$13) | K17: =IF(K6="","",K6*$D6/$D$13) | L17: =IF(L6="","",L6*$D6/$D$13) | M17: =IF(M6="","",M6*$D6/$D$13) | N17: =IF(N6="","",N6*$D6/$D$13) -> 0.0125 | ... U17: =IF(U6="","",U6*$D6/$D$13) | W17: =IF(W6="","",W6*$D6/$D$13) | X17: =IF(X6="","",X6*$D6/$D$13)
B18: =B7 -> CARBONATO CALCIO_AGROCALES_P | C18: =C7 -> 350 | D18: =D7 -> 35 | E18: =IF(E7="","",E7*$D7/$D$13) | F18: =IF(F7="","",SUM(G18:J18)) | G18: =IF(G7="","",G7*$D7/$D$13) | H18: =IF(H7="","",H7*$D7/$D$13) | I18: =IF(I7="","",I7*$D7/$D$13) | J18: =IF(J7="","",J7*$D7/$D$13) | K18: =IF(K7="","",K7*$D7/$D$13) | L18: =IF(L7="","",L7*$D7/$D$13) | M18: =IF(M7="","",M7*$D7/$D$13) -> 0.154 | N18: =IF(N7="","",N7*$D7/$D$13) | ... U18: =IF(U7="","",U7*$D7/$D$13) | W18: =IF(W7="","",W7*$D7/$D$13) | X18: =IF(X7="","",X7*$D7/$D$13)
B19: =B8 -> BENTONITA GRIS_DIDIER HOYOS_P | C19: =C8 -> 600 | D19: =D8 -> 60 | E19: =IF(E8="","",E8*$D8/$D$13) | F19: =IF(F8="","",SUM(G19:J19)) | G19: =IF(G8="","",G8*$D8/$D$13) | H19: =IF(H8="","",H8*$D8/$D$13) | I19: =IF(I8="","",I8*$D8/$D$13) | J19: =IF(J8="","",J8*$D8/$D$13) | K19: =IF(K8="","",K8*$D8/$D$13) | L19: =IF(L8="","",L8*$D8/$D$13) | M19: =IF(M8="","",M8*$D8/$D$13) -> 0.0372 | N19: =IF(N8="","",N8*$D8/$D$13) -> 0.024 | ... X19: =IF(X8="","",X8*$D8/$D$13)
E20: =IF(E9="","",E9*$D9/$D$13) | F20: =IF(F9="","",SUM(G20:J20)) | G20: =IF(G9="","",G9*$D9/$D$13) | H20: =IF(H9="","",H9*$D9/$D$13) | I20: =IF(I9="","",I9*$D9/$D$13) | J20: =IF(J9="","",J9*$D9/$D$13) | K20: =IF(K9="","",K9*$D9/$D$13) | L20: =IF(L9="","",L9*$D9/$D$13) | M20: =IF(M9="","",M9*$D9/$D$13) | N20: =IF(N9="","",N9*$D9/$D$13) | ... X20: =IF(X9="","",X9*$D9/$D$13)
E21: =IF(E10="","",E10*$D10/$D$13) | F21: =IF(F10="","",SUM(G21:J21)) | G21: =IF(G10="","",G10*$D10/$D$13) | H21: =IF(H10="","",H10*$D10/$D$13) | I21: =IF(I10="","",I10*$D10/$D$13) | J21: =IF(J10="","",J10*$D10/$D$13) | K21: =IF(K10="","",K10*$D10/$D$13) | L21: =IF(L10="","",L10*$D10/$D$13) | M21: =IF(M10="","",M10*$D10/$D$13) | N21: =IF(N10="","",N10*$D10/$D$13) | ... X21: =IF(X10="","",X10*$D10/$D$13)
E22: =IF(E11="","",E11*$D11/$D$13) | F22: =IF(F11="","",SUM(G22:J22)) | G22: =IF(G11="","",G11*$D11/$D$13) | H22: =IF(H11="","",H11*$D11/$D$13) | I22: =IF(I11="","",I11*$D11/$D$13) | J22: =IF(J11="","",J11*$D11/$D$13) | K22: =IF(K11="","",K11*$D11/$D$13) | L22: =IF(L11="","",L11*$D11/$D$13) | M22: =IF(M11="","",M11*$D11/$D$13) | N22: =IF(N11="","",N11*$D11/$D$13) | ... X22: =IF(X11="","",X11*$D11/$D$13)
E23: =IF(E12="","",E12*$D12/$D$13) | F23: =IF(F12="","",SUM(G23:J23)) | G23: =IF(G12="","",G12*$D12/$D$13) | H23: =IF(H12="","",H12*$D12/$D$13) | I23: =IF(I12="","",I12*$D12/$D$13) | J23: =IF(J12="","",J12*$D12/$D$13) | K23: =IF(K12="","",K12*$D12/$D$13) | L23: =IF(L12="","",L12*$D12/$D$13) | M23: =IF(M12="","",M12*$D12/$D$13) | N23: =IF(N12="","",N12*$D12/$D$13) | ... X23: =IF(X12="","",X12*$D12/$D$13)
B24: SUMA | C24: =SUM(C17:C23) -> 1000 | D24: 100
B25: TOTAL | E25: =SUM(E17:E23) -> 0 | F25: =SUM(F17:F23) -> 0 | G25: =SUM(G17:G23) -> 0 | H25: =SUM(H17:H23) -> 0 | I25: =SUM(I17:I23) -> 0 | J25: =SUM(J17:J23) -> 0 | K25: =SUM(K17:K23) -> 0 | L25: =SUM(L17:L23) -> 0 | ... P25: =SUM(P17:P23) -> 0 | Q25: 0 | R25: =SUM(R17:R23) -> 0 | S25: =SUM(S17:S23) -> 0 | T25: =SUM(T17:T23) -> 0 | U25: =SUM(U17:U23) -> 0 | V25: =SUM(V17:V23) -> 0.3414 | W25: =SUM(W17:W23) -> 0 | X25: =SUM(X17:X23) -> 0
B27: SOLICITUD REGISTRO | M27: 0.19 | N27: 0.04 | O27: 0.01 | V27: 0.34
B28: CERTIFICADO DE ANALISIS | M28: 0.1225 | N28: 0.0252 | O28: 0.0128 | V28: 0.3492
B30: CONTENIDOS MINIMOS*1
B31: NPK (Formula sola o en mezcla con micronutrientes) | F31: =IF(F25=0,"",IF(F25<tolerancias!B2,"SI","NO")) | K31: =IF(K25=0,"",IF(K25<tolerancias!C2,"SI","NO")) | L31: =IF(L25=0,"",IF(L25<tolerancias!D2,"SI","NO"))
B32: Secundarios (Formula UNICAMENTE con Ca, Mg, S)
B33: Micronutrientes: Unicamente micronutrientes
B34: Micronutrientes: Mezcla con NPK o secundarios | P34: =IF(P25=0,"",IF(P25>tolerancias!H5,"SI","NO")) | Q34: =IF(Q25=0,"",IF(Q25>tolerancias!I5,"SI","NO")) | R34: =IF(R25=0,"",IF(R25>tolerancias!J5,"SI","NO")) | S34: =IF(S25=0,"",IF(S25>tolerancias!K5,"SI","NO")) | T34: =IF(T25=0,"",IF(T25>tolerancias!L5,"SI","NO")) | U34: =IF(U25=0,"",IF(U25>tolerancias!M5,"SI","NO")) | V34: =IF(V25=0,"",IF(V25>tolerancias!N5,"SI","NO")) -> SI | W34: =IF(W25=0,"",IF(W25>tolerancias!P5,"SI","NO"))
B35: *1 Resolución ICA 150 de 2003 ANEXO 11
B37: TOLERANCIAS*2
B38: Calculo | F38: =IF(F25=0,"",((-0.0005*100*100*F$25*F$25+0.0413*100*F$25+0.6533)/100)) | K38: =IF(K25=0,"",((-0.0005*100*100*K$25*K$25+0.0413*100*K$25+0.6533)/100)) | L38: =IF(L25=0,"",((-0.0007*10000*L$25*L$25+0.0769*100*L$25+0.3941)/100)) | M38: =M39 -> 0.024276 | N38: =N39 -> 0.0095625 | O38: =O39 -> 0.00375
B39: NPK ¿El contenido está fuera de rango [4%-32%]?*3 | F39: =IF(F25=0,"",IF(OR(F25<4.001%,F25>32.001%),"SI","NO")) | K39: =IF(K25=0,"",IF(OR(K25<4.001%,K25>32.001%),"SI","NO")) | L39: =IF(L25=0,"",IF(OR(L25<4.001%,L25>32.001%),"SI","NO")) | M39: =IF(M25=0,"",((0.42+0.105*100*M$25)/100)) -> 0.024276 | N39: =IF(N25=0,"",((0.5+0.125*100*N$25)/100)) -> 0.0095625 | O39: =IF(O25=0,"",((0.3+0.075*100*O$25)/100)) -> 0.00375 | P39: =IF(P25=0,"",((0.005+0.25*100*P$25)/100)) | Q39: =IF(Q25=0,"",((0.000125+0.375*100*Q$25)/100)) | R39: =IF(R25=0,"",((0.015+0.3*100*R$25)/100)) | S39: =IF(S25=0,"",((0.015+0.3*100*S$25)/100)) | T39: =IF(T25=0,"",((0.015+0.3*100*T$25)/100)) | U39: =IF(U25=0,"",((0.000125+0.375*100*U$25)/100)) | W39: =IF(W25=0,"",((0.015+0.3*100*W$25)/100)) | X39: =IF(X25=0,"",((0.015+0.3*100*X$25)/100))
B40: Secundarios y menores ¿La tolerancia supera el 50% o 1.5pp?*4 | M40: =IF(M25=0,"",IF(OR(M39>M25/2,M39>1.501%),"SI","NO")) -> SI | N40: =IF(N25=0,"",IF(OR(N39>N25/2,N39>1.501%),"SI","NO")) -> NO | O40: =IF(O25=0,"",IF(OR(O39>O25/2,O39>1.501%),"SI","NO")) -> NO | P40: =IF(P25=0,"",IF(OR(P39>P25/2,P39>1.501%),"SI","NO")) | Q40: =IF(Q25=0,"",IF(OR(Q39>Q25/2,Q39>1.501%),"SI","NO")) | R40: =IF(R25=0,"",IF(OR(R39>R25/2,R39>1.501%),"SI","NO")) | S40: =IF(S25=0,"",IF(OR(S39>S25/2,S39>1.501%),"SI","NO")) | T40: =IF(T25=0,"",IF(OR(T39>T25/2,T39>1.501%),"SI","NO")) | U40: =IF(U25=0,"",IF(OR(U39>U25/2,U39>1.501%),"SI","NO")) | V40: =IF(V5="SiO2","",IF(V25=0,"",IF(OR(V39>V25/2,V39>1.501%),"SI","NO"))) | W40: =IF(W25=0,"",IF(OR(W39>W25/2,W39>1.501%),"SI","NO")) | X40: =IF(X25=0,"",IF(OR(X39>X25/2,X39>1.501%),"SI","NO"))
B41: Tolerancia permitida | F41: =IF(F25=0,"",IF(F39="NO",F38,IF(F25<4%,0.81%,1.46%))) | K41: =IF(K25=0,"",IF(K39="NO",K38,IF(K25<4%,0.81%,1.46%))) | L41: =IF(L25=0,"",IF(L39="NO",L38,IF(L25<4%,0.69%,2.14%))) | M41: =IF(M25=0,"",IF(M40="NO",M39,1.5%)) -> 0.015 | N41: =IF(N25=0,"",IF(N40="NO",N39,1.5%)) -> 0.0095625 | O41: =IF(O25=0,"",IF(O40="NO",O39,1.5%)) -> 0.00375 | P41: =IF(P25=0,"",IF(P39="NO",P38,1.5%)) | Q41: =IF(Q25=0,"",IF(Q39="NO",Q38,1.5%)) | R41: =IF(R25=0,"",IF(R39="NO",R38,1.5%)) | S41: =IF(S25=0,"",IF(S39="NO",S38,1.5%)) | T41: =IF(T25=0,"",IF(T39="NO",T38,1.5%)) | U41: =IF(U25=0,"",IF(U39="NO",U38,1.5%)) | V41: =IF(V5="SiO2","",IF(V25=0,"",IF(V39="NO",V38,1.5%))) | W41: =IF(W25=0,"",IF(W39="NO",W38,1.5%)) | X41: =IF(X25=0,"",IF(X39="NO",X38,1.5%))
B42: *2 NTC 1061:2020 ALCANCE: no aplica para organicos
B43: *3 NTC 1061:2020 4.1
B44: *4 NTC 1061:2020 4.2.1 - 4.2.2
B46: Tolerancia Mínima NTC | E46: =IF(E5="C","",IF(E25=0,"",E47-E41)) | F46: =IF(F25=0,"",F47-F41) | G46: =IF(G25=0,"",G47-G41) | H46: =IF(H25=0,"",H47-H41) | I46: =IF(I25=0,"",I47-I41) | J46: =IF(J25=0,"",J47-J41) | K46: =IF(K25=0,"",K47-K41) | L46: =IF(L25=0,"",L47-L41) | M46: =IF(M25=0,"",M47-M41) -> 0.175 | ... U46: =IF(U25=0,"",U47-U41) | V46: =IF(V5="SiO2","",IF(V25=0,"",V47-V41)) | W46: =IF(W25=0,"",W47-W41) | X46: =IF(X25=0,"",X47-X41)
B47: =_xlfn.CONCAT("SOLICITUD DE REGISTRO ICA: ",B5) -> SOLICITUD DE REGISTRO ICA: MATERIA PRIMA | E47: =IF(E25=0,"",E25) | F47: =IF(F25=0,"",F25) | G47: =IF(G25=0,"",G25) | H47: =IF(H25=0,"",H25) | I47: =IF(I25=0,"",I25) | J47: =IF(J25=0,"",J25) | K47: =IF(K25=0,"",K25) | L47: =IF(L25=0,"",L25) | M47: =M27 -> 0.19 | N47: =N27 -> 0.04 | O47: =O27 -> 0.01 | P47: =IF(P25=0,"",P25) | Q47: =IF(Q25=0,"",Q25) | R47: =IF(R25=0,"",R25) | S47: =IF(S25=0,"",S25) | T47: =IF(T25=0,"",T25) | U47: =IF(U25=0,"",U25) | V47: =V27 -> 0.34 | W47: =IF(W25=0,"",W25) | X47: =IF(X25=0,"",X25)
B48: Tolerancia Máxima NTC | E48: =IF(E5="C","",IF(E25=0,"",E47+E41)) | F48: =IF(F25=0,"",F47+F41) | G48: =IF(G25=0,"",G47+G41) | H48: =IF(H25=0,"",H47+H41) | I48: =IF(I25=0,"",I47+I41) | J48: =IF(J25=0,"",J47+J41) | K48: =IF(K25=0,"",K47+K41) | L48: =IF(L25=0,"",L47+L41) | M48: =IF(M25=0,"",M47+M41) -> 0.205 | ... U48: =IF(U25=0,"",U47+U41) | V48: =IF(V5="SiO2","",IF(V25=0,"",V47+V41)) | W48: =IF(W25=0,"",W47+W41) | X48: =IF(X25=0,"",X47+X41)

Sheet nucleo_mg
B5: MATERIA PRIMA | C5: kg / Ton | D5: %/100 kg | E5: C | F5: N | G5: N-NH4 | H5: N-NO3 | I5: N-org | J5: N-ur | K5: P | L5: K | M5: CaO | N5: MgO | O5: S | P5: B | Q5: Co | R5: Cu | S5: Fe | T5: Mn | U5: Mo | V5: SiO2 | W5: Zn | X5: Na
B6: SULFATO CALCIO_ANIBAL ARANGO_P | C6: 440 | D6: 44 | M6: 0.26 | O6: 0.13
B7: KIESERITA_MANUCHAR_P | C7: 180 | D7: 18 | N7: 0.25 | O7: 0.2
B8: BENTONITA ROJA_HYM_P | C8: 70 | D8: 7 | N8: 0.006 | V8: 0.47
B9: SILICATO MAGNESIO_JULIAN SALDARRIAGA_P | C9: 310 | D9: 31 | N9: 0.36 | V9: 0.396
B13: SUMA | C13: =SUM(C6:C12) -> 1000 | D13: 100
B14: TOTAL
B16: MATERIA PRIMA | C16: kg / Ton | D16: %/100 kg | E16: Carbono organico total oxidable C | F16: Nitrogeno Total N | G16: Nitrogeno amoniacal | H16: Nitrogeno nitrico | I16: Nitrogeno organico | J16: Nitrogeno ureico | K16: Fosforo asimilable P2O5 | L16: Potasio soluble K2O | M16: Calcio CaO | N16: Magnesio MgO | O16: Azufre S | P16: Boro B | Q16: Cobalto Co | R16: Cobre Cu | S16: Hierro Fe | T16: Manganeso Mn | U16: Molibdeno Mo | V16: Silicio SiO2 | W16: Zinc Zn | X16: Sodio Na
B17: =B6 -> SULFATO CALCIO_ANIBAL ARANGO_P | C17: =C6 -> 440 | D17: =D6 -> 44 | E17: =IF(E6="","",E6*$D6/$D$13) | F17: =IF(F6="","",SUM(G17:J17)) | G17: =IF(G6="","",G6*$D6/$D$13) | H17: =IF(H6="","",H6*$D6/$D$13) | I17: =IF(I6="","",I6*$D6/$D$13) | J17: =IF(J6="","",J6*$D6/$D$13) | K17: =IF(K6="","",K6*$D6/$D$13) | L17: =IF(L6="","",L6*$D6/$D$13) | M17: =IF(M6="","",M6*$D6/$D$13) -> 0.1144 | N17: =IF(N6="","",N6*$D6/$D$13) | ... X17: =IF(X6="","",X6*$D6/$D$13)
B18: =B7 -> KIESERITA_MANUCHAR_P | C18: =C7 -> 180 | D18: =D7 -> 18 | E18: =IF(E7="","",E7*$D7/$D$13) | F18: =IF(F7="","",SUM(G18:J18)) | G18: =IF(G7="","",G7*$D7/$D$13) | H18: =IF(H7="","",H7*$D7/$D$13) | I18: =IF(I7="","",I7*$D7/$D$13) | J18: =IF(J7="","",J7*$D7/$D$13) | K18: =IF(K7="","",K7*$D7/$D$13) | L18: =IF(L7="","",L7*$D7/$D$13) | M18: =IF(M7="","",M7*$D7/$D$13) | N18: =IF(N7="","",N7*$D7/$D$13) -> 0.045 | ... X18: =IF(X7="","",X7*$D7/$D$13)
B19: =B8 -> BENTONITA ROJA_HYM_P | C19: =C8 -> 70 | D19: =D8 -> 7 | E19: =IF(E8="","",E8*$D8/$D$13) | F19: =IF(F8="","",SUM(G19:J19)) | G19: =IF(G8="","",G8*$D8/$D$13) | H19: =IF(H8="","",H8*$D8/$D$13) | I19: =IF(I8="","",I8*$D8/$D$13) | J19: =IF(J8="","",J8*$D8/$D$13) | K19: =IF(K8="","",K8*$D8/$D$13) | L19: =IF(L8="","",L8*$D8/$D$13) | M19: =IF(M8="","",M8*$D8/$D$13) | N19: =IF(N8="","",N8*$D8/$D$13) -> 0.00042 | ... X19: =IF(X8="","",X8*$D8/$D$13)
B20: =B9 -> SILICATO MAGNESIO_JULIAN SALDARRIAGA_P | C20: =C9 -> 310 | D20: =D9 -> 31 | E20: =IF(E9="","",E9*$D9/$D$13) | F20: =IF(F9="","",SUM(G20:J20)) | G20: =IF(G9="","",G9*$D9/$D$13) | H20: =IF(H9="","",H9*$D9/$D$13) | I20: =IF(I9="","",I9*$D9/$D$13) | J20: =IF(J9="","",J9*$D9/$D$13) | K20: =IF(K9="","",K9*$D9/$D$13) | L20: =IF(L9="","",L9*$D9/$D$13) | M20: =IF(M9="","",M9*$D9/$D$13) | N20: =IF(N9="","",N9*$D9/$D$13) -> 0.1116 | ... X20: =IF(X9="","",X9*$D9/$D$13)
B21: =B10 -> 0 | C21: =C10 -> 0 | D21: =D10 -> 0 | E21: =IF(E10="","",E10*$D10/$D$13) | F21: =IF(F10="","",SUM(G21:J21)) | G21: =IF(G10="","",G10*$D10/$D$13) | H21: =IF(H10="","",H10*$D10/$D$13) | I21: =IF(I10="","",I10*$D10/$D$13) | J21: =IF(J10="","",J10*$D10/$D$13) | K21: =IF(K10="","",K10*$D10/$D$13) | L21: =IF(L10="","",L10*$D10/$D$13) | M21: =IF(M10="","",M10*$D10/$D$13) | N21: =IF(N10="","",N10*$D10/$D$13) | ... X21: =IF(X10="","",X10*$D10/$D$13)
B22: =B11 -> 0 | C22: =C11 -> 0 | D22: =D11 -> 0 | E22: =IF(E11="","",E11*$D11/$D$13) | F22: =IF(F11="","",SUM(G22:J22)) | G22: =IF(G11="","",G11*$D11/$D$13) | H22: =IF(H11="","",H11*$D11/$D$13) | I22: =IF(I11="","",I11*$D11/$D$13) | J22: =IF(J11="","",J11*$D11/$D$13) | K22: =IF(K11="","",K11*$D11/$D$13) | L22: =IF(L11="","",L11*$D11/$D$13) | M22: =IF(M11="","",M11*$D11/$D$13) | N22: =IF(N11="","",N11*$D11/$D$13) | ... X22: =IF(X11="","",X11*$D11/$D$13)
E23: =IF(E12="","",E12*$D12/$D$13) | F23: =IF(F12="","",SUM(G23:J23)) | G23: =IF(G12="","",G12*$D12/$D$13) | H23: =IF(H12="","",H12*$D12/$D$13) | I23: =IF(I12="","",I12*$D12/$D$13) | J23: =IF(J12="","",J12*$D12/$D$13) | K23: =IF(K12="","",K12*$D12/$D$13) | L23: =IF(L12="","",L12*$D12/$D$13) | M23: =IF(M12="","",M12*$D12/$D$13) | N23: =IF(N12="","",N12*$D12/$D$13) | ... X23: =IF(X12="","",X12*$D12/$D$13)
B24: SUMA | C24: =SUM(C17:C23) -> 1000 | D24: 100
B25: TOTAL | E25: =SUM(E17:E23) -> 0 | F25: =SUM(F17:F23) -> 0 | G25: =SUM(G17:G23) -> 0 | H25: =SUM(H17:H23) -> 0 | I25: =SUM(I17:I23) -> 0 | J25: =SUM(J17:J23) -> 0 | K25: =SUM(K17:K23) -> 0 | L25: =SUM(L17:L23) -> 0 | N25: =SUM(N17:N23) -> 0.15702 | O25: =SUM(O17:O23) -> 0.0932 | P25: =SUM(P17:P23) -> 0 | Q25: 0 | R25: =SUM(R17:R23) -> 0 | S25: =SUM(S17:S23) -> 0 | T25: =SUM(T17:T23) -> 0 | U25: =SUM(U17:U23) -> 0 | V25: =SUM(V17:V23) -> 0.15566 | W25: =SUM(W17:W23) -> 0 | X25: =SUM(X17:X23) -> 0
B27: SOLICITUD REGISTRO | N27: 0.16 | O27: 0.08 | V27: 0.3
B28: CERTIFICADO DE ANALISIS | N28: 0.165 | O28: 0.0596
B30: CONTENIDOS MINIMOS*1
B31: NPK (Formula sola o en mezcla con micronutrientes) | F31: =IF(F25=0,"",IF(F25<tolerancias!B2,"SI","NO")) | K31: =IF(K25=0,"",IF(K25<tolerancias!C2,"SI","NO")) | L31: =IF(L25=0,"",IF(L25<tolerancias!D2,"SI","NO"))
B32: Secundarios (Formula UNICAMENTE con Ca, Mg, S)
B33: Micronutrientes: Unicamente micronutrientes
B34: Micronutrientes: Mezcla con NPK o secundarios | P34: =IF(P25=0,"",IF(P25>tolerancias!H5,"SI","NO")) | Q34: =IF(Q25=0,"",IF(Q25>tolerancias!I5,"SI","NO")) | R34: =IF(R25=0,"",IF(R25>tolerancias!J5,"SI","NO")) | S34: =IF(S25=0,"",IF(S25>tolerancias!K5,"SI","NO")) | T34: =IF(T25=0,"",IF(T25>tolerancias!L5,"SI","NO")) | U34: =IF(U25=0,"",IF(U25>tolerancias!M5,"SI","NO")) | V34: =IF(V25=0,"",IF(V25>tolerancias!N5,"SI","NO")) -> SI | W34: =IF(W25=0,"",IF(W25>tolerancias!P5,"SI","NO"))
B35: *1 Resolución ICA 150 de 2003 ANEXO 11
B37: TOLERANCIAS*2
B38: Calculo | F38: =IF(F25=0,"",((-0.0005*100*100*F$25*F$25+0.0413*100*F$25+0.6533)/100)) | K38: =IF(K25=0,"",((-0.0005*100*100*K$25*K$25+0.0413*100*K$25+0.6533)/100)) | L38: =IF(L25=0,"",((-0.0007*10000*L$25*L$25+0.0769*100*L$25+0.3941)/100)) | M38: =M39 | N38: =N39 -> 0.0246275 | O38: =O39 -> 0.00999
B39: NPK ¿El contenido está fuera de rango [4%-32%]?*3 | F39: =IF(F25=0,"",IF(OR(F25<4.001%,F25>32.001%),"SI","NO")) | K39: =IF(K25=0,"",IF(OR(K25<4.001%,K25>32.001%),"SI","NO")) | L39: =IF(L25=0,"",IF(OR(L25<4.001%,L25>32.001%),"SI","NO")) | M39: =IF(M25=0,"",((0.42+0.105*100*M$25)/100)) | N39: =IF(N25=0,"",((0.5+0.125*100*N$25)/100)) -> 0.0246275 | O39: =IF(O25=0,"",((0.3+0.075*100*O$25)/100)) -> 0.00999 | P39: =IF(P25=0,"",((0.005+0.25*100*P$25)/100)) | Q39: =IF(Q25=0,"",((0.000125+0.375*100*Q$25)/100)) | R39: =IF(R25=0,"",((0.015+0.3*100*R$25)/100)) | S39: =IF(S25=0,"",((0.015+0.3*100*S$25)/100)) | T39: =IF(T25=0,"",((0.015+0.3*100*T$25)/100)) | U39: =IF(U25=0,"",((0.000125+0.375*100*U$25)/100)) | W39: =IF(W25=0,"",((0.015+0.3*100*W$25)/100)) | X39: =IF(X25=0,"",((0.015+0.3*100*X$25)/100))
B40: Secundarios y menores ¿La tolerancia supera el 50% o 1.5pp?*4 | M40: =IF(M25=0,"",IF(OR(M39>M25/2,M39>1.501%),"SI","NO")) | N40: =IF(N25=0,"",IF(OR(N39>N25/2,N39>1.501%),"SI","NO")) -> SI | O40: =IF(O25=0,"",IF(OR(O39>O25/2,O39>1.501%),"SI","NO")) -> NO | P40: =IF(P25=0,"",IF(OR(P39>P25/2,P39>1.501%),"SI","NO")) | Q40: =IF(Q25=0,"",IF(OR(Q39>Q25/2,Q39>1.501%),"SI","NO")) | R40: =IF(R25=0,"",IF(OR(R39>R25/2,R39>1.501%),"SI","NO")) | S40: =IF(S25=0,"",IF(OR(S39>S25/2,S39>1.501%),"SI","NO")) | T40: =IF(T25=0,"",IF(OR(T39>T25/2,T39>1.501%),"SI","NO")) | U40: =IF(U25=0,"",IF(OR(U39>U25/2,U39>1.501%),"SI","NO")) | V40: =IF(V5="SiO2","",IF(V25=0,"",IF(OR(V39>V25/2,V39>1.501%),"SI","NO"))) | W40: =IF(W25=0,"",IF(OR(W39>W25/2,W39>1.501%),"SI","NO")) | X40: =IF(X25=0,"",IF(OR(X39>X25/2,X39>1.501%),"SI","NO"))
B41: Tolerancia permitida | F41: =IF(F25=0,"",IF(F39="NO",F38,IF(F25<4%,0.81%,1.46%))) | K41: =IF(K25=0,"",IF(K39="NO",K38,IF(K25<4%,0.81%,1.46%))) | L41: =IF(L25=0,"",IF(L39="NO",L38,IF(L25<4%,0.69%,2.14%))) | M41: =IF(M25=0,"",IF(M40="NO",M39,1.5%)) | N41: =IF(N25=0,"",IF(N40="NO",N39,1.5%)) -> 0.015 | O41: =IF(O25=0,"",IF(O40="NO",O39,1.5%)) -> 0.00999 | P41: =IF(P25=0,"",IF(P39="NO",P38,1.5%)) | Q41: =IF(Q25=0,"",IF(Q39="NO",Q38,1.5%)) | R41: =IF(R25=0,"",IF(R39="NO",R38,1.5%)) | S41: =IF(S25=0,"",IF(S39="NO",S38,1.5%)) | T41: =IF(T25=0,"",IF(T39="NO",T38,1.5%)) | U41: =IF(U25=0,"",IF(U39="NO",U38,1.5%)) | V41: =IF(V5="SiO2","",IF(V25=0,"",IF(V39="NO",V38,1.5%))) | W41: =IF(W25=0,"",IF(W39="NO",W38,1.5%)) | X41: =IF(X25=0,"",IF(X39="NO",X38,1.5%))
B42: *2 NTC 1061:2020 ALCANCE: no aplica para organicos
B43: *3 NTC 1061:2020 4.1
B44: *4 NTC 1061:2020 4.2.1 - 4.2.2
B46: Tolerancia Mínima NTC | E46: =IF(E5="C","",IF(E25=0,"",E47-E41)) | F46: =IF(F25=0,"",F47-F41) | G46: =IF(G25=0,"",G47-G41) | H46: =IF(H25=0,"",H47-H41) | I46: =IF(I25=0,"",I47-I41) | J46: =IF(J25=0,"",J47-J41) | K46: =IF(K25=0,"",K47-K41) | L46: =IF(L25=0,"",L47-L41) | M46: =IF(M25=0,"",M47-M41) | ... U46: =IF(U25=0,"",U47-U41) | V46: =IF(V5="SiO2","",IF(V25=0,"",V47-V41)) | W46: =IF(W25=0,"",W47-W41) | X46: =IF(X25=0,"",X47-X41)
B47: =_xlfn.CONCAT("SOLICITUD DE REGISTRO ICA: ",B5) -> SOLICITUD DE REGISTRO ICA: MATERIA PRIMA | E47: =IF(E25=0,"",E25) | F47: =IF(F25=0,"",F25) | G47: =IF(G25=0,"",G25) | H47: =IF(H25=0,"",H25) | I47: =IF(I25=0,"",I25) | J47: =IF(J25=0,"",J25) | K47: =IF(K25=0,"",K25) | L47: =IF(L25=0,"",L25) | M47: =M27 -> 0 | N47: =N27 -> 0.16 | O47: =O27 -> 0.08 | P47: =IF(P25=0,"",P25) | Q47: =IF(Q25=0,"",Q25) | R47: =IF(R25=0,"",R25) | S47: =IF(S25=0,"",S25) | T47: =IF(T25=0,"",T25) | U47: =IF(U25=0,"",U25) | V47: =V27 -> 0.3 | W47: =IF(W25=0,"",W25) | X47: =IF(X25=0,"",X25)
B48: Tolerancia Máxima NTC | E48: =IF(E5="C","",IF(E25=0,"",E47+E41)) | F48: =IF(F25=0,"",F47+F41) | G48: =IF(G25=0,"",G47+G41) | H48: =IF(H25=0,"",H47+H41) | I48: =IF(I25=0,"",I47+I41) | J48: =IF(J25=0,"",J47+J41) | K48: =IF(K25=0,"",K47+K41) | L48: =IF(L25=0,"",L47+L41) | M48: =IF(M25=0,"",M47+M41) | ... U48: =IF(U25=0,"",U47+U41) | V48: =IF(V5="SiO2","",IF(V25=0,"",V47+V41)) | W48: =IF(W25=0,"",W47+W41) | X48: =IF(X25=0,"",X47+X41)

Sheet calferzinc-p
B5: MATERIA PRIMA | C5: kg / Ton | D5: %/100 kg | E5: C | F5: N | G5: N-NH4 | H5: N-NO3 | I5: N-org | J5: N-ur | K5: P | L5: K | M5: CaO | N5: MgO | O5: S | P5: B | Q5: Co | R5: Cu | S5: Fe | T5: Mn | U5: Mo | V5: SiO2 | W5: Zn | X5: Na
B6: SULFATO ZINC_ATEQUIMICOS_P | C6: 675 | D6: 67.5 | M6: 0.26 | O6: 0.13 | W6: 0.35
B7: CARBONATO CALCIO_AGROCALES_P | C7: 75 | D7: 7.5 | M7: 0.44
B8: KIESERITA_MANUCHAR_P | C8: 50 | D8: 5 | N8: 0.25 | O8: 0.2
B9: BENTONITA GRIS_FERTICAUCA_P | C9: 200 | D9: 20 | L9: 0.024 | M9: 0.062 | N9: 0.04 | V9: 0.569
B13: SUMA | C13: =SUM(C6:C12) -> 1000 | D13: 100
B14: TOTAL
B16: MATERIA PRIMA | C16: kg / Ton | D16: %/100 kg | E16: Carbono organico total oxidable C | F16: Nitrogeno Total N | G16: Nitrogeno amoniacal | H16: Nitrogeno nitrico | I16: Nitrogeno organico | J16: Nitrogeno ureico | K16: Fosforo asimilable P2O5 | L16: Potasio soluble K2O | M16: Calcio CaO | N16: Magnesio MgO | O16: Azufre S | P16: Boro B | Q16: Cobalto Co | R16: Cobre Cu | S16: Hierro Fe | T16: Manganeso Mn | U16: Molibdeno Mo | V16: Silicio SiO2 | W16: Zinc Zn | X16: Sodio Na
B17: =B6 -> SULFATO ZINC_ATEQUIMICOS_P | C17: =C6 -> 675 | D17: =D6 -> 67.5 | E17: =IF(E6="","",E6*$D6/$D$13) | F17: =IF(F6="","",SUM(G17:J17)) | G17: =IF(G6="","",G6*$D6/$D$13) | H17: =IF(H6="","",H6*$D6/$D$13) | I17: =IF(I6="","",I6*$D6/$D$13) | J17: =IF(J6="","",J6*$D6/$D$13) | K17: =IF(K6="","",K6*$D6/$D$13) | L17: =IF(L6="","",L6*$D6/$D$13) | M17: =IF(M6="","",M6*$D6/$D$13) -> 0.1755 | N17: =IF(N6="","",N6*$D6/$D$13) | ... X17: =IF(X6="","",X6*$D6/$D$13)
B18: =B7 -> CARBONATO CALCIO_AGROCALES_P | C18: =C7 -> 75 | D18: =D7 -> 7.5 | E18: =IF(E7="","",E7*$D7/$D$13) | F18: =IF(F7="","",SUM(G18:J18)) | G18: =IF(G7="","",G7*$D7/$D$13) | H18: =IF(H7="","",H7*$D7/$D$13) | I18: =IF(I7="","",I7*$D7/$D$13) | J18: =IF(J7="","",J7*$D7/$D$13) | K18: =IF(K7="","",K7*$D7/$D$13) | L18: =IF(L7="","",L7*$D7/$D$13) | M18: =IF(M7="","",M7*$D7/$D$13) -> 0.033 | N18: =IF(N7="","",N7*$D7/$D$13) | ... X18: =IF(X7="","",X7*$D7/$D$13)
B19: =B8 -> KIESERITA_MANUCHAR_P | C19: =C8 -> 50 | D19: =D8 -> 5 | E19: =IF(E8="","",E8*$D8/$D$13) | F19: =IF(F8="","",SUM(G19:J19)) | G19: =IF(G8="","",G8*$D8/$D$13) | H19: =IF(H8="","",H8*$D8/$D$13) | I19: =IF(I8="","",I8*$D8/$D$13) | J19: =IF(J8="","",J8*$D8/$D$13) | K19: =IF(K8="","",K8*$D8/$D$13) | L19: =IF(L8="","",L8*$D8/$D$13) | M19: =IF(M8="","",M8*$D8/$D$13) | N19: =IF(N8="","",N8*$D8/$D$13) -> 0.0125 | ... X19: =IF(X8="","",X8*$D8/$D$13)
B20: =B9 -> BENTONITA GRIS_FERTICAUCA_P | C20: =C9 -> 200 | D20: =D9 -> 20 | E20: =IF(E9="","",E9*$D9/$D$13) | F20: =IF(F9="","",SUM(G20:J20)) | G20: =IF(G9="","",G9*$D9/$D$13) | H20: =IF(H9="","",H9*$D9/$D$13) | I20: =IF(I9="","",I9*$D9/$D$13) | J20: =IF(J9="","",J9*$D9/$D$13) | K20: =IF(K9="","",K9*$D9/$D$13) | L20: =IF(L9="","",L9*$D9/$D$13) -> 0.0048 | M20: =IF(M9="","",M9*$D9/$D$13) -> 0.0124 | N20: =IF(N9="","",N9*$D9/$D$13) -> 0.008 | ... X20: =IF(X9="","",X9*$D9/$D$13)
B21: =B10 -> 0 | C21: =C10 -> 0 | D21: =D10 -> 0 | E21: =IF(E10="","",E10*$D10/$D$13) | F21: =IF(F10="","",SUM(G21:J21)) | G21: =IF(G10="","",G10*$D10/$D$13) | H21: =IF(H10="","",H10*$D10/$D$13) | I21: =IF(I10="","",I10*$D10/$D$13) | J21: =IF(J10="","",J10*$D10/$D$13) | K21: =IF(K10="","",K10*$D10/$D$13) | L21: =IF(L10="","",L10*$D10/$D$13) | M21: =IF(M10="","",M10*$D10/$D$13) | N21: =IF(N10="","",N10*$D10/$D$13) | ... X21: =IF(X10="","",X10*$D10/$D$13)
B22: =B11 -> 0 | C22: =C11 -> 0 | D22: =D11 -> 0 | E22: =IF(E11="","",E11*$D11/$D$13) | F22: =IF(F11="","",SUM(G22:J22)) | G22: =IF(G11="","",G11*$D11/$D$13) | H22: =IF(H11="","",H11*$D11/$D$13) | I22: =IF(I11="","",I11*$D11/$D$13) | J22: =IF(J11="","",J11*$D11/$D$13) | K22: =IF(K11="","",K11*$D11/$D$13) | L22: =IF(L11="","",L11*$D11/$D$13) | M22: =IF(M11="","",M11*$D11/$D$13) | N22: =IF(N11="","",N11*$D11/$D$13) | ... X22: =IF(X11="","",X11*$D11/$D$13)
E23: =IF(E12="","",E12*$D12/$D$13) | F23: =IF(F12="","",SUM(G23:J23)) | G23: =IF(G12="","",G12*$D12/$D$13) | H23: =IF(H12="","",H12*$D12/$D$13) | I23: =IF(I12="","",I12*$D12/$D$13) | J23: =IF(J12="","",J12*$D12/$D$13) | K23: =IF(K12="","",K12*$D12/$D$13) | L23: =IF(L12="","",L12*$D12/$D$13) | M23: =IF(M12="","",M12*$D12/$D$13) | N23: =IF(N12="","",N12*$D12/$D$13) | ... X23: =IF(X12="","",X12*$D12/$D$13)
B24: SUMA | C24: =SUM(C17:C23) -> 1000 | D24: 100
B25: TOTAL | E25: =SUM(E17:E23) -> 0 | F25: =SUM(F17:F23) -> 0 | G25: =SUM(G17:G23) -> 0 | H25: =SUM(H17:H23) -> 0 | I25: =SUM(I17:I23) -> 0 | J25: =SUM(J17:J23) -> 0 | K25: =SUM(K17:K23) -> 0 | L25: =SUM(L17:L23) -> 0.0048 | O25: =SUM(O17:O23) -> 0.09775 | P25: =SUM(P17:P23) -> 0 | Q25: 0 | R25: =SUM(R17:R23) -> 0 | S25: =SUM(S17:S23) -> 0 | T25: =SUM(T17:T23) -> 0 | U25: =SUM(U17:U23) -> 0 | W25: =SUM(W17:W23) -> 0.23625 | X25: =SUM(X17:X23) -> 0
B27: SOLICITUD REGISTRO | K27: 0.03 | O27: 0.07 | W27: 0.21
B28: CERTIFICADO DE ANALISIS | K28: 0.0023 | O28: 0.0629 | W28: 0.1281
B30: CONTENIDOS MINIMOS*1
B31: NPK (Formula sola o en mezcla con micronutrientes) | F31: =IF(F25=0,"",IF(F25<tolerancias!B2,"SI","NO")) | K31: =IF(K25=0,"",IF(K25<tolerancias!C2,"SI","NO")) | L31: =IF(L25=0,"",IF(L25<tolerancias!D2,"SI","NO")) -> SI
B32: Secundarios (Formula UNICAMENTE con Ca, Mg, S)
B33: Micronutrientes: Unicamente micronutrientes
B34: Micronutrientes: Mezcla con NPK o secundarios | P34: =IF(P25=0,"",IF(P25>tolerancias!H5,"SI","NO")) | Q34: =IF(Q25=0,"",IF(Q25>tolerancias!I5,"SI","NO")) | R34: =IF(R25=0,"",IF(R25>tolerancias!J5,"SI","NO")) | S34: =IF(S25=0,"",IF(S25>tolerancias!K5,"SI","NO")) | T34: =IF(T25=0,"",IF(T25>tolerancias!L5,"SI","NO")) | U34: =IF(U25=0,"",IF(U25>tolerancias!M5,"SI","NO")) | V34: =IF(V25=0,"",IF(V25>tolerancias!N5,"SI","NO")) | W34: =IF(W25=0,"",IF(W25>tolerancias!P5,"SI","NO")) -> SI
B35: *1 Resolución ICA 150 de 2003 ANEXO 11
B37: TOLERANCIAS*2
B38: Calculo | F38: =IF(F25=0,"",((-0.0005*100*100*F$25*F$25+0.0413*100*F$25+0.6533)/100)) | K38: =IF(K25=0,"",((-0.0005*100*100*K$25*K$25+0.0413*100*K$25+0.6533)/100)) | L38: =IF(L25=0,"",((-0.0007*10000*L$25*L$25+0.0769*100*L$25+0.3941)/100)) -> 0.0043085072 | M38: =M39 | N38: =N39 | O38: =O39 -> 0.01033125
B39: NPK ¿El contenido está fuera de rango [4%-32%]?*3 | F39: =IF(F25=0,"",IF(OR(F25<4.001%,F25>32.001%),"SI","NO")) | K39: =IF(K25=0,"",IF(OR(K25<4.001%,K25>32.001%),"SI","NO")) | L39: =IF(L25=0,"",IF(OR(L25<4.001%,L25>32.001%),"SI","NO")) -> SI | M39: =IF(M25=0,"",((0.42+0.105*100*M$25)/100)) | N39: =IF(N25=0,"",((0.5+0.125*100*N$25)/100)) | O39: =IF(O25=0,"",((0.3+0.075*100*O$25)/100)) -> 0.01033125 | P39: =IF(P25=0,"",((0.005+0.25*100*P$25)/100)) | Q39: =IF(Q25=0,"",((0.000125+0.375*100*Q$25)/100)) | R39: =IF(R25=0,"",((0.015+0.3*100*R$25)/100)) | S39: =IF(S25=0,"",((0.015+0.3*100*S$25)/100)) | T39: =IF(T25=0,"",((0.015+0.3*100*T$25)/100)) | U39: =IF(U25=0,"",((0.000125+0.375*100*U$25)/100)) | W39: =IF(W25=0,"",((0.015+0.3*100*W$25)/100)) -> 0.071025 | X39: =IF(X25=0,"",((0.015+0.3*100*X$25)/100))
B40: Secundarios y menores ¿La tolerancia supera el 50% o 1.5pp?*4 | M40: =IF(M25=0,"",IF(OR(M39>M25/2,M39>1.501%),"SI","NO")) | N40: =IF(N25=0,"",IF(OR(N39>N25/2,N39>1.501%),"SI","NO")) | O40: =IF(O25=0,"",IF(OR(O39>O25/2,O39>1.501%),"SI","NO")) -> NO | P40: =IF(P25=0,"",IF(OR(P39>P25/2,P39>1.501%),"SI","NO")) | Q40: =IF(Q25=0,"",IF(OR(Q39>Q25/2,Q39>1.501%),"SI","NO")) | R40: =IF(R25=0,"",IF(OR(R39>R25/2,R39>1.501%),"SI","NO")) | S40: =IF(S25=0,"",IF(OR(S39>S25/2,S39>1.501%),"SI","NO")) | T40: =IF(T25=0,"",IF(OR(T39>T25/2,T39>1.501%),"SI","NO")) | U40: =IF(U25=0,"",IF(OR(U39>U25/2,U39>1.501%),"SI","NO")) | V40: =IF(V5="SiO2","",IF(V25=0,"",IF(OR(V39>V25/2,V39>1.501%),"SI","NO"))) | W40: =IF(W25=0,"",IF(OR(W39>W25/2,W39>1.501%),"SI","NO")) -> SI | X40: =IF(X25=0,"",IF(OR(X39>X25/2,X39>1.501%),"SI","NO"))
B41: Tolerancia permitida | F41: =IF(F25=0,"",IF(F39="NO",F38,IF(F25<4%,0.81%,1.46%))) | K41: =IF(K25=0,"",IF(K39="NO",K38,IF(K25<4%,0.81%,1.46%))) | L41: =IF(L25=0,"",IF(L39="NO",L38,IF(L25<4%,0.69%,2.14%))) -> 0.0069 | M41: =IF(M25=0,"",IF(M40="NO",M39,1.5%)) | N41: =IF(N25=0,"",IF(N40="NO",N39,1.5%)) | O41: =IF(O25=0,"",IF(O40="NO",O39,1.5%)) -> 0.01033125 | P41: =IF(P25=0,"",IF(P39="NO",P38,1.5%)) | Q41: =IF(Q25=0,"",IF(Q39="NO",Q38,1.5%)) | R41: =IF(R25=0,"",IF(R39="NO",R38,1.5%)) | S41: =IF(S25=0,"",IF(S39="NO",S38,1.5%)) | T41: =IF(T25=0,"",IF(T39="NO",T38,1.5%)) | U41: =IF(U25=0,"",IF(U39="NO",U38,1.5%)) | V41: =IF(V5="SiO2","",IF(V25=0,"",IF(V39="NO",V38,1.5%))) | W41: =IF(W25=0,"",IF(W39="NO",W38,1.5%)) -> 0.015 | X41: =IF(X25=0,"",IF(X39="NO",X38,1.5%))
B42: *2 NTC 1061:2020 ALCANCE: no aplica para organicos
B43: *3 NTC 1061:2020 4.1
B44: *4 NTC 1061:2020 4.2.1 - 4.2.2
B46: Tolerancia Mínima NTC | E46: =IF(E5="C","",IF(E25=0,"",E47-E41)) | F46: =IF(F25=0,"",F47-F41) | G46: =IF(G25=0,"",G47-G41) | H46: =IF(H25=0,"",H47-H41) | I46: =IF(I25=0,"",I47-I41) | J46: =IF(J25=0,"",J47-J41) | K46: =IF(K25=0,"",K47-K41) | L46: =IF(L25=0,"",L47-L41) -> -0.0021 | M46: =IF(M25=0,"",M47-M41) | ... U46: =IF(U25=0,"",U47-U41) | V46: =IF(V5="SiO2","",IF(V25=0,"",V47-V41)) | W46: =IF(W25=0,"",W47-W41) -> 0.195 | X46: =IF(X25=0,"",X47-X41)
B47: =_xlfn.CONCAT("SOLICITUD DE REGISTRO ICA: ",B5) -> SOLICITUD DE REGISTRO ICA: MATERIA PRIMA | E47: =IF(E25=0,"",E25) | F47: =IF(F25=0,"",F25) | G47: =IF(G25=0,"",G25) | H47: =IF(H25=0,"",H25) | I47: =IF(I25=0,"",I25) | J47: =IF(J25=0,"",J25) | K47: =IF(K25=0,"",K25) | L47: =IF(L25=0,"",L25) -> 0.0048 | M47: =M27 -> 0 | N47: =N27 -> 0 | O47: =O27 -> 0.07 | P47: =IF(P25=0,"",P25) | Q47: =IF(Q25=0,"",Q25) | R47: =IF(R25=0,"",R25) | S47: =IF(S25=0,"",S25) | T47: =IF(T25=0,"",T25) | U47: =IF(U25=0,"",U25) | V47: =V27 -> 0 | W47: 0.21 | X47: =IF(X25=0,"",X25)
B48: Tolerancia Máxima NTC | E48: =IF(E5="C","",IF(E25=0,"",E47+E41)) | F48: =IF(F25=0,"",F47+F41) | G48: =IF(G25=0,"",G47+G41) | H48: =IF(H25=0,"",H47+H41) | I48: =IF(I25=0,"",I47+I41) | J48: =IF(J25=0,"",J47+J41) | K48: =IF(K25=0,"",K47+K41) | L48: =IF(L25=0,"",L47+L41) -> 0.0117 | M48: =IF(M25=0,"",M47+M41) | ... U48: =IF(U25=0,"",U47+U41) | V48: =IF(V5="SiO2","",IF(V25=0,"",V47+V41)) | W48: =IF(W25=0,"",W47+W41) -> 0.225 | X48: =IF(X25=0,"",X47+X41)

Sheet Hoja3 (2)
A1: Sulfato de Calcio-P - Muestra 13-03-2025 | F1: CAMASI - Muestra 13-03-2025 | M1: Nucleo Magnesio - Muestra 12-12-2024 | R1: Calferzinc P - Muestra 13-03-2025
A2: MATERIA PRIMA | B2: kg / Ton | C2: MgO | D2: S | F2: MATERIA PRIMA | G2: kg / Ton | H2: CaO | I2: MgO | J2: S | K2: SiO2 | M2: MATERIA PRIMA | N2: kg / Ton | O2: MgO | P2: S | R2: MATERIA PRIMA | S2: kg / Ton | T2: Zn | U2: S | V2: P
A3: SULFATO CALCIO | B3: 750 | C3: 0.195 | D3: 0.0975 | F3: KIESERITA_MANUCHAR | G3: 750 | I3: 0.25 | J3: 0.2 | M3: SULFATO CALCIO | N3: 440 | P3: 0.0572 | R3: SULFATO ZINC | S3: 675 | T3: 0.23625 | U3: 0.08775
A4: KIESERITA | B4: 50 | D4: 0.01 | F4: CARBONATO CALCIO_AGROCALES | G4: 50 | H4: 0.44 | J4: 0 | M4: KIESERITA | N4: 180 | O4: 0.045 | P4: 0.036 | R4: CARBONATO CALCIO | S4: 75
A5: CARBONATO CALCIO | B5: 150 | C5: 0.066 | F5: BENTONITA GRIS DIDIER HOYOS | G5: 150 | H5: 0.062 | I5: 0.04 | K5: 0.569 | M5: BENTONITA ROJA | N5: 70 | R5: KIESERITA | S5: 50 | U5: 0.01
A6: BENTONITA GRIS | B6: 50 | C6: 0.0031 | M6: SILICATO MAGNESIO | N6: 310 | O6: 0.1116 | R6: BENTONITA GRIS | S6: 200
A8: TOTAL BALANCE | C8: 0.2641 | D8: 0.1075 | F8: TOTAL BALANCE | H8: 0.1912 | I8: 0.0365 | J8: 0.01 | K8: 0.3414 | M8: TOTAL BALANCE | O8: 0.15702 | P8: 0.0932 | R8: TOTAL BALANCE | T8: 0.15702 | U8: 0.0932
A9: CERTIFICADO LABORATORIO | C9: 0.2106 | D9: 0.1518 | F9: CERTIFICADO LABORATORIO | H9: 0.1225 | I9: 0.0252 | J9: 0.0128 | K9: 0.3482 | M9: CERTIFICADO LABORATORIO | O9: 0.165 | P9: 0.0596 | R9: CERTIFICADO LABORATORIO | T9: 0.1281 | U9: 0.0629 | V9: 0.0023
A10: GRADO | C10: 0.26 | D10: 0.1 | F10: GRADO | H10: 0.16 | I10: 0.01 | J10: 0.01 | K10: 0.3 | M10: GRADO | O10: 0.16 | P10: 0.08 | R10: GRADO | T10: 0.21 | U10: 0.07 | V10: 0.03
A12: Tolerancia Máxima | C12: 0.015 | D12: 0.0110625 | F12: Tolerancia Máxima | H12: 0.015 | I12: 0.0095625 | J12: 0.00375 | K12: NA | M12: Tolerancia Máxima | O12: 0.015 | P12: 0.00999 | R12: Tolerancia Máxima | T12: 0.015 | U12: 0.01033125 | V12: 0.015
A14: Límite Inferior | C14: 0.245 | D14: 0.0889375 | F14: Límite Inferior | H14: =H15-H12 -> 0.145 | I14: 0.0304375 | J14: 0.00625 | M14: Límite Inferior | O14: 0.145 | P14: 0.07001 | R14: Límite Inferior | T14: 0.195 | U14: 0.05966875 | V14: =V15-V12 -> 0.015
A15: GRADO | C15: 0.26 | D15: 0.1 | F15: GRADO | H15: =H10 -> 0.16 | I15: =I10 -> 0.01 | J15: =J10 -> 0.01 | K15: =K10 -> 0.3 | M15: GRADO | O15: 0.16 | P15: 0.08 | R15: GRADO | T15: 0.21 | U15: 0.07 | V15: 0.03
A16: Límite Superior | C16: 0.275 | D16: 0.1110625 | F16: Límite Superior | H16: =H15+H12 -> 0.175 | I16: 0.0495625 | J16: 0.01375 | M16: Límite Superior | O16: 0.175 | P16: 0.08999 | R16: Límite Superior | T16: 0.225 | U16: 0.08033125 | V16: =V15+V12 -> 0.045
A18: Dentro de rangos? | C18: =IF(C9<C14,"NO",IF(C9>C16,"NO","SI")) -> NO | D18: =IF(D9<D14,"NO",IF(D9>D16,"NO","SI")) -> NO | F18: Dentro de rangos? | H18: =IF(H9<H14,"NO",IF(I9>H16,"NO","SI")) -> NO | I18: =IF(I9<I14,"NO",IF(J9>I16,"NO","SI")) -> NO | J18: =IF(K9<J14,"NO",IF(K9>J16,"NO","SI")) -> NO | M18: Dentro de rangos? | O18: =IF(O9<O14,"NO",IF(O9>O16,"NO","SI")) -> SI | P18: =IF(P9<P14,"NO",IF(P9>P16,"NO","SI")) -> NO | R18: Dentro de rangos? | T18: =IF(T9<T14,"NO",IF(T9>T16,"NO","SI")) -> NO | U18: =IF(U9<U14,"NO",IF(U9>U16,"NO","SI")) -> SI | V18: =IF(V9<V14,"NO",IF(V9>V16,"NO","SI")) -> NO
A19: CERTIFICADO LABORATORIO | C19: 0.2106 | D19: 0.1518 | F19: CERTIFICADO LABORATORIO | H19: 0.1225 | I19: 0.01 | J19: 0.0128 | K19: 0.3482 | M19: CERTIFICADO LABORATORIO | O19: =O9 -> 0.165 | P19: =P9 -> 0.0596 | R19: CERTIFICADO LABORATORIO | T19: =T9 -> 0.1281 | U19: =U9 -> 0.0629 | V19: =V9 -> 0.0023

Sheet Hoja3
A1: Sulfato de Calcio-P - Muestra 13-03-2025 | F1: Sulfato de Calcio-P - Muestra 13-03-2025 | M1: Nucleo Magnesio - Muestra 12-12-2024 | R1: Calferzinc P - Muestra 13-03-2025
A2: MATERIA PRIMA | B2: kg / Ton | C2: MgO | D2: S | F2: MATERIA PRIMA | G2: kg / Ton | H2: CaO | I2: MgO | J2: S | K2: SiO2 | M2: MATERIA PRIMA | N2: kg / Ton | O2: MgO | P2: S | R2: MATERIA PRIMA | S2: kg / Ton | T2: Zn | U2: S | V2: P
A3: SULFATO CALCIO | B3: 750 | C3: 0.195 | D3: 0.0975 | F3: KIESERITA_MANUCHAR | G3: 750 | I3: 0.25 | J3: 0.2 | M3: SULFATO CALCIO | N3: 440 | P3: 0.0572 | R3: SULFATO ZINC | S3: 675 | T3: 0.23625 | U3: 0.08775
A4: KIESERITA | B4: 50 | D4: 0.01 | F4: CARBONATO CALCIO_AGROCALES | G4: 50 | H4: 0.44 | J4: 0 | M4: KIESERITA | N4: 180 | O4: 0.045 | P4: 0.036 | R4: CARBONATO CALCIO | S4: 75
A5: CARBONATO CALCIO | B5: 150 | C5: 0.066 | F5: BENTONITA GRIS DIDIER HOYOS | G5: 150 | H5: 0.062 | I5: 0.04 | K5: 0.569 | M5: BENTONITA ROJA | N5: 70 | R5: KIESERITA | S5: 50 | U5: 0.01
A6: BENTONITA GRIS | B6: 50 | C6: 0.0031 | M6: SILICATO MAGNESIO | N6: 310 | O6: 0.1116 | R6: BENTONITA GRIS | S6: 200
A8: TOTAL BALANCE | C8: 0.2641 | D8: 0.1075 | F8: TOTAL BALANCE | H8: 0.1912 | I8: 0.0365 | J8: 0.01 | K8: 0.3414 | M8: TOTAL BALANCE | O8: 0.15702 | P8: 0.0932 | R8: TOTAL BALANCE | T8: 0.15702 | U8: 0.0932
A9: CERTIFICADO LABORATORIO | C9: 0.2106 | D9: 0.1518 | F9: CERTIFICADO LABORATORIO | H9: 0.1225 | I9: 0.0252 | J9: 0.0128 | K9: 0.3482 | M9: CERTIFICADO LABORATORIO | O9: 0.165 | P9: 0.0596 | R9: CERTIFICADO LABORATORIO | T9: 0.1281 | U9: 0.0629 | V9: 0.0023
A10: GRADO | C10: 0.26 | D10: 0.1 | F10: GRADO | H10: 0.16 | I10: 0.01 | J10: 0.01 | K10: 0.3 | M10: GRADO | O10: 0.16 | P10: 0.08 | R10: GRADO | T10: 0.16 | U10: 0.08
A12: Tolerancia Máxima | C12: 0.015 | D12: 0.0110625 | F12: Tolerancia Máxima | H12: 0.015 | I12: 0.0095625 | J12: 0.00375 | K12: NA | M12: Tolerancia Máxima | O12: 0.015 | P12: 0.00999 | R12: Tolerancia Máxima | T12: 0.015 | U12: 0.01033125 | V12: 0.015
A14: Límite Inferior | C14: 0.245 | D14: 0.0889375 | F14: Límite Inferior | H14: =H15-H12 -> 0.145 | I14: 0.0304375 | J14: 0.00625 | M14: Límite Inferior | O14: 0.145 | P14: 0.07001 | R14: Límite Inferior | T14: 0.195 | U14: 0.05966875 | V14: =V15-V12 -> 0.015
A15: GRADO | C15: 0.26 | D15: 0.1 | F15: GRADO | H15: =H10 -> 0.16 | I15: =I10 -> 0.01 | J15: =J10 -> 0.01 | K15: =K10 -> 0.3 | M15: GRADO | O15: 0.16 | P15: 0.08 | R15: GRADO | T15: 0.21 | U15: 0.07 | V15: 0.03
A16: Límite Superior | C16: 0.275 | D16: 0.1110625 | F16: Límite Superior | H16: =H15+H12 -> 0.175 | I16: 0.0495625 | J16: 0.01375 | M16: Límite Superior | O16: 0.175 | P16: 0.08999 | R16: Límite Superior | T16: 0.225 | U16: 0.08033125 | V16: =V15+V12 -> 0.045
A18: Dentro de rangos? | C18: =IF(C9<C14,"NO",IF(C9>C16,"NO","SI")) -> NO | D18: =IF(D9<D14,"NO",IF(D9>D16,"NO","SI")) -> NO | F18: Dentro de rangos? | H18: =IF(H9<H14,"NO",IF(I9>H16,"NO","SI")) -> NO | I18: =IF(I9<I14,"NO",IF(J9>I16,"NO","SI")) -> NO | J18: =IF(K9<J14,"NO",IF(K9>J16,"NO","SI")) -> NO | M18: Dentro de rangos? | O18: =IF(O9<O14,"NO",IF(O9>O16,"NO","SI")) -> SI | P18: =IF(P9<P14,"NO",IF(P9>P16,"NO","SI")) -> NO | R18: Dentro de rangos? | T18: =IF(T9<T14,"NO",IF(T9>T16,"NO","SI")) -> NO | U18: =IF(U9<U14,"NO",IF(U9>U16,"NO","SI")) -> SI | V18: =IF(V9<V14,"NO",IF(V9>V16,"NO","SI")) -> NO
A19: CERTIFICADO LABORATORIO | C19: 0.2106 | D19: 0.1518 | F19: CERTIFICADO LABORATORIO | H19: 0.1225 | I19: 0.01 | J19: 0.0128 | K19: 0.3482 | M19: CERTIFICADO LABORATORIO | O19: =O9 -> 0.165 | P19: =P9 -> 0.0596 | R19: CERTIFICADO LABORATORIO | T19: =T9 -> 0.1281 | U19: =U9 -> 0.0629 | V19: =V9 -> 0.0023

Sheet balance materias primas
F2: BALANCE DE MATERIAS PRIMAS | S2: ##
F3: SISTEMA DE GESTION INTEGRAL | S3: ##
F4: CODIGO:
B6: FORMULACION: | C6: FERTICORRECTIVO
B8: =IF(OR(camasi!B16=0,camasi!B16=""),"",camasi!B16) -> MATERIA PRIMA | C8: =IF(OR(camasi!C16=0,camasi!C16=""),"",camasi!C16) -> kg / Ton | D8: =IF(OR(camasi!D16=0,camasi!D16=""),"",camasi!D16) -> %/100 kg | E8: =IF(OR(camasi!E16=0,camasi!E16=""),"",camasi!E16) -> Carbono organico total oxidable C | F8: =IF(OR(camasi!F16=0,camasi!F16=""),"",camasi!F16) -> Nitrogeno Total N | G8: =IF(OR(camasi!G16=0,camasi!G16=""),"",camasi!G16) -> Nitrogeno amoniacal | H8: =IF(OR(camasi!H16=0,camasi!H16=""),"",camasi!H16) -> Nitrogeno nitrico | I8: =IF(OR(camasi!I16=0,camasi!I16=""),"",camasi!I16) -> Nitrogeno organico | ... X8: =IF(OR(camasi!X16=0,camasi!X16=""),"",camasi!X16) -> Sodio Na
B9: =IF(OR(camasi!B17=0,camasi!B17=""),"",camasi!B17) -> KIESERITA_MANUCHAR_P | C9: =IF(OR(camasi!C17=0,camasi!C17=""),"",camasi!C17) -> 50 | D9: =IF(OR(camasi!D17=0,camasi!D17=""),"",camasi!D17) -> 5 | E9: =IF(OR(camasi!E17=0,camasi!E17=""),"",camasi!E17) | F9: =IF(OR(camasi!F17=0,camasi!F17=""),"",camasi!F17) | G9: =IF(OR(camasi!G17=0,camasi!G17=""),"",camasi!G17) | H9: =IF(OR(camasi!H17=0,camasi!H17=""),"",camasi!H17) | I9: =IF(OR(camasi!I17=0,camasi!I17=""),"",camasi!I17) | ... X9: =IF(OR(camasi!X17=0,camasi!X17=""),"",camasi!X17)
B10: =IF(OR(camasi!B18=0,camasi!B18=""),"",camasi!B18) -> CARBONATO CALCIO_AGROCALES_P | C10: =IF(OR(camasi!C18=0,camasi!C18=""),"",camasi!C18) -> 350 | D10: =IF(OR(camasi!D18=0,camasi!D18=""),"",camasi!D18) -> 35 | E10: =IF(OR(camasi!E18=0,camasi!E18=""),"",camasi!E18) | F10: =IF(OR(camasi!F18=0,camasi!F18=""),"",camasi!F18) | G10: =IF(OR(camasi!G18=0,camasi!G18=""),"",camasi!G18) | H10: =IF(OR(camasi!H18=0,camasi!H18=""),"",camasi!H18) | I10: =IF(OR(camasi!I18=0,camasi!I18=""),"",camasi!I18) | ... X10: =IF(OR(camasi!X18=0,camasi!X18=""),"",camasi!X18)
B11: =IF(OR(camasi!B19=0,camasi!B19=""),"",camasi!B19) -> BENTONITA GRIS_DIDIER HOYOS_P | C11: =IF(OR(camasi!C19=0,camasi!C19=""),"",camasi!C19) -> 600 | D11: =IF(OR(camasi!D19=0,camasi!D19=""),"",camasi!D19) -> 60 | E11: =IF(OR(camasi!E19=0,camasi!E19=""),"",camasi!E19) | F11: =IF(OR(camasi!F19=0,camasi!F19=""),"",camasi!F19) | G11: =IF(OR(camasi!G19=0,camasi!G19=""),"",camasi!G19) | H11: =IF(OR(camasi!H19=0,camasi!H19=""),"",camasi!H19) | I11: =IF(OR(camasi!I19=0,camasi!I19=""),"",camasi!I19) | ... X11: =IF(OR(camasi!X19=0,camasi!X19=""),"",camasi!X19)
B12: =IF(OR(camasi!B20=0,camasi!B20=""),"",camasi!B20) | C12: =IF(OR(camasi!C20=0,camasi!C20=""),"",camasi!C20) | D12: =IF(OR(camasi!D20=0,camasi!D20=""),"",camasi!D20) | E12: =IF(OR(camasi!E20=0,camasi!E20=""),"",camasi!E20) | F12: =IF(OR(camasi!F20=0,camasi!F20=""),"",camasi!F20) | G12: =IF(OR(camasi!G20=0,camasi!G20=""),"",camasi!G20) | H12: =IF(OR(camasi!H20=0,camasi!H20=""),"",camasi!H20) | I12: =IF(OR(camasi!I20=0,camasi!I20=""),"",camasi!I20) | ... X12: =IF(OR(camasi!X20=0,camasi!X20=""),"",camasi!X20)
B13: =IF(OR(camasi!B21=0,camasi!B21=""),"",camasi!B21) | C13: =IF(OR(camasi!C21=0,camasi!C21=""),"",camasi!C21) | D13: =IF(OR(camasi!D21=0,camasi!D21=""),"",camasi!D21) | E13: =IF(OR(camasi!E21=0,camasi!E21=""),"",camasi!E21) | F13: =IF(OR(camasi!F21=0,camasi!F21=""),"",camasi!F21) | G13: =IF(OR(camasi!G21=0,camasi!G21=""),"",camasi!G21) | H13: =IF(OR(camasi!H21=0,camasi!H21=""),"",camasi!H21) | I13: =IF(OR(camasi!I21=0,camasi!I21=""),"",camasi!I21) | ... X13: =IF(OR(camasi!X21=0,camasi!X21=""),"",camasi!X21)
B14: =IF(OR(camasi!B22=0,camasi!B22=""),"",camasi!B22) | C14: =IF(OR(camasi!C22=0,camasi!C22=""),"",camasi!C22) | D14: =IF(OR(camasi!D22=0,camasi!D22=""),"",camasi!D22) | E14: =IF(OR(camasi!E22=0,camasi!E22=""),"",camasi!E22) | F14: =IF(OR(camasi!F22=0,camasi!F22=""),"",camasi!F22) | G14: =IF(OR(camasi!G22=0,camasi!G22=""),"",camasi!G22) | H14: =IF(OR(camasi!H22=0,camasi!H22=""),"",camasi!H22) | I14: =IF(OR(camasi!I22=0,camasi!I22=""),"",camasi!I22) | ... X14: =IF(OR(camasi!X22=0,camasi!X22=""),"",camasi!X22)
B15: =IF(OR(camasi!B23=0,camasi!B23=""),"",camasi!B23) | C15: =IF(OR(camasi!C23=0,camasi!C23=""),"",camasi!C23) | D15: =IF(OR(camasi!D23=0,camasi!D23=""),"",camasi!D23) | E15: =IF(OR(camasi!E23=0,camasi!E23=""),"",camasi!E23) | F15: =IF(OR(camasi!F23=0,camasi!F23=""),"",camasi!F23) | G15: =IF(OR(camasi!G23=0,camasi!G23=""),"",camasi!G23) | H15: =IF(OR(camasi!H23=0,camasi!H23=""),"",camasi!H23) | I15: =IF(OR(camasi!I23=0,camasi!I23=""),"",camasi!I23) | ... X15: =IF(OR(camasi!X23=0,camasi!X23=""),"",camasi!X23)
B16: ADITIVOS
B19: =IF(OR(camasi!B25=0,camasi!B25=""),"",camasi!B25) -> TOTAL | C19: =IF(OR(camasi!C24=0,camasi!C24=""),"",camasi!C24) -> 1000 | D19: =IF(OR(camasi!D24=0,camasi!D24=""),"",camasi!D24) -> 100 | E19: =IF(OR(camasi!E25=0,camasi!E25=""),"",camasi!E25) | F19: =IF(OR(camasi!F25=0,camasi!F25=""),"",camasi!F25) | G19: =IF(OR(camasi!G25=0,camasi!G25=""),"",camasi!G25) | H19: =IF(OR(camasi!H25=0,camasi!H25=""),"",camasi!H25) | I19: =IF(OR(camasi!I25=0,camasi!I25=""),"",camasi!I25) | J19: =IF(OR(camasi!J25=0,camasi!J25=""),"",camasi!J25) | K19: =IF(OR(camasi!K25=0,camasi!K25=""),"",camasi!K25) | L19: =IF(OR(camasi!L25=0,camasi!L25=""),"",camasi!L25) | ... X19: =IF(OR(camasi!X25=0,camasi!X25=""),"",camasi!X25)
B20: =IF(OR(camasi!B26=0,camasi!B26=""),"",camasi!B26) | C20: =IF(OR(camasi!C26=0,camasi!C26=""),"",camasi!C26) | D20: =IF(OR(camasi!D26=0,camasi!D26=""),"",camasi!D26)
B21: =IF(OR(camasi!B28=0,camasi!B28=""),"",camasi!B28) -> CERTIFICADO DE ANALISIS | C21: =IF(OR(camasi!C28=0,camasi!C28=""),"",camasi!C28) | D21: =IF(OR(camasi!D28=0,camasi!D28=""),"",camasi!D28) | E21: =IF(OR(camasi!E28=0,camasi!E28=""),"",camasi!E28) | F21: =IF(OR(camasi!F28=0,camasi!F28=""),"",camasi!F28) | G21: =IF(OR(camasi!G28=0,camasi!G28=""),"",camasi!G28) | H21: =IF(OR(camasi!H28=0,camasi!H28=""),"",camasi!H28) | I21: =IF(OR(camasi!I28=0,camasi!I28=""),"",camasi!I28) | ... X21: =IF(OR(camasi!X28=0,camasi!X28=""),"",camasi!X28)
B22: =IF(OR(camasi!B29=0,camasi!B29=""),"",camasi!B29) | C22: =IF(OR(camasi!C29=0,camasi!C29=""),"",camasi!C29) | D22: =IF(OR(camasi!D29=0,camasi!D29=""),"",camasi!D29) | E22: =IF(OR(camasi!E29=0,camasi!E29=""),"",camasi!E29) | F22: =IF(OR(camasi!F29=0,camasi!F29=""),"",camasi!F29) | G22: =IF(OR(camasi!G29=0,camasi!G29=""),"",camasi!G29) | H22: =IF(OR(camasi!H29=0,camasi!H29=""),"",camasi!H29) | I22: =IF(OR(camasi!I29=0,camasi!I29=""),"",camasi!I29) | ... X22: =IF(OR(camasi!X29=0,camasi!X29=""),"",camasi!X29)
B23: =IF(OR(camasi!B30=0,camasi!B30=""),"",camasi!B30) -> CONTENIDOS MINIMOS*1 | E23: =IF(OR(camasi!E30=0,camasi!E30=""),"",camasi!E30) | F23: =IF(OR(camasi!F30=0,camasi!F30=""),"",camasi!F30) | G23: =IF(OR(camasi!G30=0,camasi!G30=""),"",camasi!G30) | H23: =IF(OR(camasi!H30=0,camasi!H30=""),"",camasi!H30) | I23: =IF(OR(camasi!I30=0,camasi!I30=""),"",camasi!I30) | J23: =IF(OR(camasi!J30=0,camasi!J30=""),"",camasi!J30) | K23: =IF(OR(camasi!K30=0,camasi!K30=""),"",camasi!K30) | L23: =IF(OR(camasi!L30=0,camasi!L30=""),"",camasi!L30) | ... X23: =IF(OR(camasi!X30=0,camasi!X30=""),"",camasi!X30)
B24: =IF(OR(camasi!B31=0,camasi!B31=""),"",camasi!B31) -> NPK (Formula sola o en mezcla con micronutrientes) | C24: =IF(OR(camasi!C31=0,camasi!C31=""),"",camasi!C31) | D24: =IF(OR(camasi!D31=0,camasi!D31=""),"",camasi!D31) | E24: =IF(OR(camasi!E31=0,camasi!E31=""),"",camasi!E31) | F24: =IF(OR(camasi!F31=0,camasi!F31=""),"",camasi!F31) | K24: =IF(OR(camasi!K31=0,camasi!K31=""),"",camasi!K31) | L24: =IF(OR(camasi!L31=0,camasi!L31=""),"",camasi!L31) | M24: =IF(OR(camasi!M31=0,camasi!M31=""),"",camasi!M31) | N24: =IF(OR(camasi!N31=0,camasi!N31=""),"",camasi!N31) | O24: =IF(OR(camasi!O31=0,camasi!O31=""),"",camasi!O31) | P24: =IF(OR(camasi!P31=0,camasi!P31=""),"",camasi!P31) | Q24: =IF(OR(camasi!Q31=0,camasi!Q31=""),"",camasi!Q31) | R24: =IF(OR(camasi!R31=0,camasi!R31=""),"",camasi!R31) | ... X24: =IF(OR(camasi!X31=0,camasi!X31=""),"",camasi!X31)
B25: =IF(OR(camasi!B32=0,camasi!B32=""),"",camasi!B32) -> Secundarios (Formula UNICAMENTE con Ca, Mg, S) | C25: =IF(OR(camasi!C32=0,camasi!C32=""),"",camasi!C32) | D25: =IF(OR(camasi!D32=0,camasi!D32=""),"",camasi!D32) | E25: =IF(OR(camasi!E32=0,camasi!E32=""),"",camasi!E32) | F25: =IF(OR(camasi!F32=0,camasi!F32=""),"",camasi!F32) | K25: =IF(OR(camasi!K32=0,camasi!K32=""),"",camasi!K32) | L25: =IF(OR(camasi!L32=0,camasi!L32=""),"",camasi!L32) | M25: =IF(OR(camasi!M32=0,camasi!M32=""),"",camasi!M32) | N25: =IF(OR(camasi!N32=0,camasi!N32=""),"",camasi!N32) | O25: =IF(OR(camasi!O32=0,camasi!O32=""),"",camasi!O32) | P25: =IF(OR(camasi!P32=0,camasi!P32=""),"",camasi!P32) | Q25: =IF(OR(camasi!Q32=0,camasi!Q32=""),"",camasi!Q32) | R25: =IF(OR(camasi!R32=0,camasi!R32=""),"",camasi!R32) | ... X25: =IF(OR(camasi!X32=0,camasi!X32=""),"",camasi!X32)
B26: =IF(OR(camasi!B33=0,camasi!B33=""),"",camasi!B33) -> Micronutrientes: Unicamente micronutrientes | C26: =IF(OR(camasi!C33=0,camasi!C33=""),"",camasi!C33) | D26: =IF(OR(camasi!D33=0,camasi!D33=""),"",camasi!D33) | E26: =IF(OR(camasi!E33=0,camasi!E33=""),"",camasi!E33) | F26: =IF(OR(camasi!F33=0,camasi!F33=""),"",camasi!F33) | K26: =IF(OR(camasi!K33=0,camasi!K33=""),"",camasi!K33) | L26: =IF(OR(camasi!L33=0,camasi!L33=""),"",camasi!L33) | M26: =IF(OR(camasi!M33=0,camasi!M33=""),"",camasi!M33) | N26: =IF(OR(camasi!N33=0,camasi!N33=""),"",camasi!N33) | O26: =IF(OR(camasi!O33=0,camasi!O33=""),"",camasi!O33) | P26: =IF(OR(camasi!P33=0,camasi!P33=""),"",camasi!P33) | Q26: =IF(OR(camasi!Q33=0,camasi!Q33=""),"",camasi!Q33) | R26: =IF(OR(camasi!R33=0,camasi!R33=""),"",camasi!R33) | ... X26: =IF(OR(camasi!X33=0,camasi!X33=""),"",camasi!X33)
B27: =IF(OR(camasi!B34=0,camasi!B34=""),"",camasi!B34) -> Micronutrientes: Mezcla con NPK o secundarios | C27: =IF(OR(camasi!C34=0,camasi!C34=""),"",camasi!C34) | D27: =IF(OR(camasi!D34=0,camasi!D34=""),"",camasi!D34) | E27: =IF(OR(camasi!E34=0,camasi!E34=""),"",camasi!E34) | F27: =IF(OR(camasi!F34=0,camasi!F34=""),"",camasi!F34) | K27: =IF(OR(camasi!K34=0,camasi!K34=""),"",camasi!K34) | L27: =IF(OR(camasi!L34=0,camasi!L34=""),"",camasi!L34) | M27: =IF(OR(camasi!M34=0,camasi!M34=""),"",camasi!M34) | N27: =IF(OR(camasi!N34=0,camasi!N34=""),"",camasi!N34) | O27: =IF(OR(camasi!O34=0,camasi!O34=""),"",camasi!O34) | P27: =IF(OR(camasi!P34=0,camasi!P34=""),"",camasi!P34) | Q27: =IF(OR(camasi!Q34=0,camasi!Q34=""),"",camasi!Q34) | R27: =IF(OR(camasi!R34=0,camasi!R34=""),"",camasi!R34) | ... X27: =IF(OR(camasi!X34=0,camasi!X34=""),"",camasi!X34)
