Workbook

Sheet Hoja 1
C1: SELECCIÓN DE PROVEEDORES SISTEMA DE GESTIÓN INTEGRAL | P1: SC
P2: SS
C3: CODIGO RC-SI17 | G3: VERSIÓN: 0
A5: NOMBRE PROVEEDOR | D5: PRODUCTO O SERVICIO | E5: PRECIO | G5: TIEMPOS DE ENTREGA | I5: FORMA DE PAGO | K5: TRANSPORTE | M5: CERTIFICADO SGSST | P5: PUNTOS
A6: SL001 | B6: Acerias Paz del rio | D6: Fertilizantes | E6: Buen Precio | F6: =VLOOKUP(E6,'Hoja 3'!A2:B26,2,FALSE) -> 20 | G6: Es considerable | H6: =VLOOKUP(G6,'Hoja 3'!A2:B26,2,FALSE) -> 25 | I6: 30-60 días | J6: =VLOOKUP(I6,'Hoja 3'!A2:B26,2,FALSE) -> 20 | K6: No se Incluye | L6: =VLOOKUP(K6,'Hoja 3'!A2:B26,2,FALSE) -> 1 | M6: No Aporta Certificado | N6: =VLOOKUP(M6,'Hoja 3'!A2:B26,2,FALSE) -> 1 | P6: =(F6+H6+J6+L6+N6) -> 67
A7: SL002 | B7: Alfa Productos Quimicos Sas | D7: Fertilizantes | E7: Buen Precio | F7: =VLOOKUP(E7,'Hoja 3'!A3:B27,2,FALSE) -> 20 | G7: Pronta entrega o inmediata | H7: =VLOOKUP(G7,'Hoja 3'!A3:B27,2,FALSE) -> 30 | I7: 30-60 días | J7: =VLOOKUP(I7,'Hoja 3'!A3:B27,2,FALSE) -> 20 | K7: Se incluye | L7: =VLOOKUP(K7,'Hoja 3'!A3:B27,2,FALSE) -> 10 | M7: No Aporta Certificado | N7: =VLOOKUP(M7,'Hoja 3'!A3:B27,2,FALSE) -> 1 | P7: =(F7+H7+J7+L7+N7) -> 81
A8: SL003 | B8: Alsukar | D8: Fertilizantes | E8: Buen Precio | F8: =VLOOKUP(E8,'Hoja 3'!A4:B28,2,FALSE) -> 20 | G8: Es considerable | H8: =VLOOKUP(G8,'Hoja 3'!A4:B28,2,FALSE) -> 25 | I8: Anticipado | J8: =VLOOKUP(I8,'Hoja 3'!A4:B28,2,FALSE) -> 5 | K8: No se Incluye | L8: =VLOOKUP(K8,'Hoja 3'!A4:B28,2,FALSE) -> 1 | M8: Seleccione | N8: =VLOOKUP(M8,'Hoja 3'!A4:B28,2,FALSE) -> 0 | P8: =(F8+H8+J8+L8+N8) -> 51
A9: SL004 | B9: Arango Jose Anibal | D9: Fertilizantes | E9: Muy Alto | F9: 10 | G9: Es considerable | H9: =VLOOKUP(G9,'Hoja 3'!A5:B29,2,FALSE) -> 25 | I9: 30-60 días | J9: =VLOOKUP(I9,'Hoja 3'!A5:B29,2,FALSE) -> 20 | K9: Se incluye | L9: =VLOOKUP(K9,'Hoja 3'!A5:B29,2,FALSE) -> 10 | M9: No Aporta Certificado | N9: =VLOOKUP(M9,'Hoja 3'!A5:B29,2,FALSE) -> 1 | P9: =(F9+H9+J9+L9+N9) -> 66
A10: SL005 | B10: Asuagro | D10: Fertilizantes | E10: Buen Precio | F10: =VLOOKUP(E10,'Hoja 3'!A2:B27,2,FALSE) -> 20 | G10: Es considerable | H10: =VLOOKUP(G10,'Hoja 3'!A6:B30,2,FALSE) -> 25 | I10: 30-60 días | J10: =VLOOKUP(I10,'Hoja 3'!A6:B30,2,FALSE) -> 20 | K10: Se incluye | L10: =VLOOKUP(K10,'Hoja 3'!A6:B30,2,FALSE) -> 10 | M10: Aporta certificado | N10: =VLOOKUP(M10,'Hoja 3'!A6:B30,2,FALSE) -> 10 | P10: =(F10+H10+J10+L10+N10) -> 85
A11: SL006 | B11: Athertua y quimicos | D11: Fertilizantes | E11: Buen Precio | F11: =VLOOKUP(E11,'Hoja 3'!A2:B27,2,FALSE) -> 20 | G11: Pronta entrega o inmediata | H11: =VLOOKUP(G11,'Hoja 3'!A7:B31,2,FALSE) -> 30 | I11: 30-60 días | J11: =VLOOKUP(I11,'Hoja 3'!A7:B31,2,FALSE) -> 20 | K11: Se incluye | L11: =VLOOKUP(K11,'Hoja 3'!A7:B31,2,FALSE) -> 10 | M11: Aporta certificado | N11: =VLOOKUP(M11,'Hoja 3'!A7:B31,2,FALSE) -> 10 | P11: =(F11+H11+J11+L11+N11) -> 90
A12: SL007 | B12: Agrocales | D12: Fertilizantes | E12: Buen Precio | F12: =VLOOKUP(E12,'Hoja 3'!A2:B26,2,FALSE) -> 20 | G12: Es considerable | H12: =VLOOKUP(G12,'Hoja 3'!A2:B26,2,FALSE) -> 25 | I12: 30-60 días | J12: =VLOOKUP(I12,'Hoja 3'!A2:B26,2,FALSE) -> 20 | K12: No se Incluye | L12: =VLOOKUP(K12,'Hoja 3'!A2:B26,2,FALSE) -> 1 | M12: No Aporta Certificado | N12: =VLOOKUP(M12,'Hoja 3'!A2:B26,2,FALSE) -> 1 | P12: =(F12+H12+J12+L12+N12) -> 67
A13: SL008 | B13: Almacen la finquita | D13: Herramientas | E13: Buen Precio | F13: =VLOOKUP(E13,'Hoja 3'!A3:B27,2,FALSE) -> 20 | G13: Muy demorado | H13: =VLOOKUP(G13,'Hoja 3'!A3:B27,2,FALSE) -> 5 | I13: 30-60 días | J13: =VLOOKUP(I13,'Hoja 3'!A3:B27,2,FALSE) -> 20 | K13: Se incluye | L13: =VLOOKUP(K13,'Hoja 3'!A3:B27,2,FALSE) -> 10 | M13: Aporta certificado | N13: =VLOOKUP(M13,'Hoja 3'!A3:B27,2,FALSE) -> 10 | P13: =(F13+H13+J13+L13+N13) -> 65
A14: SL009 | B14: C i de azucares y mieles | D14: Fertilizantes | E14: Buen Precio | F14: =VLOOKUP(E14,'Hoja 3'!A2:B26,2,FALSE) -> 20 | G14: Es considerable | H14: =VLOOKUP(G14,'Hoja 3'!A4:B28,2,FALSE) -> 25 | I14: 30-60 días | J14: =VLOOKUP(I14,'Hoja 3'!A4:B28,2,FALSE) -> 20 | K14: No se Incluye | L14: =VLOOKUP(K14,'Hoja 3'!A4:B28,2,FALSE) -> 1 | M14: No Aporta Certificado | N14: =VLOOKUP(M14,'Hoja 3'!A4:B28,2,FALSE) -> 1 | P14: =(F14+H14+J14+L14+N14) -> 67
A15: SL010 | B15: Comerecializadora domeq | D15: Tapabocas | E15: Buen Precio | F15: =VLOOKUP(E15, 'Hoja 3'!$A$2:$B$26, 2, FALSE) -> 20 | G15: Pronta entrega o inmediata | H15: =VLOOKUP(G15,'Hoja 3'!A5:B29,2,FALSE) -> 30 | I15: Anticipado | J15: =VLOOKUP(I15,'Hoja 3'!A5:B29,2,FALSE) -> 5 | K15: Se incluye | L15: =VLOOKUP(K15,'Hoja 3'!A5:B29,2,FALSE) -> 10 | M15: No Aporta Certificado | N15: =VLOOKUP(M15,'Hoja 3'!A5:B29,2,FALSE) -> 1 | P15: =(F15+H15+J15+L15+N15) -> 66
A16: SL011 | B16: Comercializadora helvecia | D16: Fertilizantes | E16: Muy Alto | F16: =VLOOKUP(E16, 'Hoja 3'!$A$2:$B$26, 2, FALSE) -> 10 | G16: Es considerable | H16: =VLOOKUP(G16,'Hoja 3'!A6:B30,2,FALSE) -> 25 | I16: 30-60 días | J16: =VLOOKUP(I16,'Hoja 3'!A6:B30,2,FALSE) -> 20 | K16: No se Incluye | L16: =VLOOKUP(K16,'Hoja 3'!A6:B30,2,FALSE) -> 1 | M16: Aporta certificado | N16: =VLOOKUP(M16,'Hoja 3'!A6:B30,2,FALSE) -> 10 | P16: =(F16+H16+J16+L16+N16) -> 66
A17: SL012 | B17: Cooperativa multiactiva uniagro | D17: Servicio de transporte | E17: Buen Precio | F17: =VLOOKUP(E17, 'Hoja 3'!$A$2:$B$26, 2, FALSE) -> 20 | G17: Pronta entrega o inmediata | H17: =VLOOKUP(G17,'Hoja 3'!A7:B31,2,FALSE) -> 30 | I17: Contraentrega | J17: =VLOOKUP(I17,'Hoja 3'!A7:B31,2,FALSE) -> 10 | K17: Se incluye | L17: =VLOOKUP(K17,'Hoja 3'!A7:B31,2,FALSE) -> 10 | M17: No Aporta Certificado | N17: =VLOOKUP(M17,'Hoja 3'!A7:B31,2,FALSE) -> 1 | P17: =(F17+H17+J17+L17+N17) -> 71
A18: SL013 | B18: Henry Coronado | D18: Fertilizantes | E18: Buen Precio | F18: =VLOOKUP(E18,'Hoja 3'!A2:B26,2,FALSE) -> 20 | G18: Muy demorado | H18: =VLOOKUP(G18,'Hoja 3'!A2:B26,2,FALSE) -> 5 | I18: Más de 60 dias | J18: =VLOOKUP(I18,'Hoja 3'!A2:B26,2,FALSE) -> 30 | K18: No se Incluye | L18: =VLOOKUP(K18,'Hoja 3'!A2:B26,2,FALSE) -> 1 | M18: No Aporta Certificado | N18: =VLOOKUP(M18,'Hoja 3'!A2:B26,2,FALSE) -> 1 | P18: =(F18+H18+J18+L18+N18) -> 57
A19: SL014 | B19: Disan Agro | D19: Fertilizantes | E19: Muy Alto | F19: =VLOOKUP(E19,'Hoja 3'!A3:B27,2,FALSE) -> 10 | G19: Pronta entrega o inmediata | H19: =VLOOKUP(G19,'Hoja 3'!A3:B27,2,FALSE) -> 30 | I19: 30-60 días | J19: =VLOOKUP(I19,'Hoja 3'!A3:B27,2,FALSE) -> 20 | K19: No se Incluye | L19: =VLOOKUP(K19,'Hoja 3'!A3:B27,2,FALSE) -> 1 | M19: Aporta certificado | N19: =VLOOKUP(M19,'Hoja 3'!A3:B27,2,FALSE) -> 10 | P19: =(F19+H19+J19+L19+N19) -> 71
A20: SL015 | B20: Empresa de fosfatos del huila | D20: Fertilizantes | E20: Buen Precio | F20: =VLOOKUP(E20,'Hoja 3'!A2:B26,2,FALSE) -> 20 | G20: Pronta entrega o inmediata | H20: =VLOOKUP(G20,'Hoja 3'!A4:B28,2,FALSE) -> 30 | I20: 30-60 días | J20: =VLOOKUP(I20,'Hoja 3'!A4:B28,2,FALSE) -> 20 | K20: No se Incluye | L20: =VLOOKUP(K20,'Hoja 3'!A4:B28,2,FALSE) -> 1 | M20: Aporta certificado | N20: =VLOOKUP(M20,'Hoja 3'!A4:B28,2,FALSE) -> 10 | P20: =(F20+H20+J20+L20+N20) -> 81
A21: SL016 | B21: Florinsumos LTDA | D21: Empaques | E21: Buen Precio | F21: 20 | G21: Es considerable | H21: =VLOOKUP(G21,'Hoja 3'!A5:B29,2,FALSE) -> 25 | I21: 30-60 días | J21: =VLOOKUP(I21,'Hoja 3'!A5:B29,2,FALSE) -> 20 | K21: Se incluye | L21: =VLOOKUP(K21,'Hoja 3'!A5:B29,2,FALSE) -> 10 | M21: No Aporta Certificado | N21: =VLOOKUP(M21,'Hoja 3'!A5:B29,2,FALSE) -> 1 | P21: =(F21+H21+J21+L21+N21) -> 76
A22: SL017 | B22: Gipson | D22: Soluble | E22: Buen Precio | F22: 20 | G22: Es considerable | H22: =VLOOKUP(G22,'Hoja 3'!A6:B30,2,FALSE) -> 25 | I22: Anticipado | J22: =VLOOKUP(I22,'Hoja 3'!A6:B30,2,FALSE) -> 5 | K22: Se incluye | L22: =VLOOKUP(K22,'Hoja 3'!A6:B30,2,FALSE) -> 10 | M22: No Aporta Certificado | N22: =VLOOKUP(M22,'Hoja 3'!A6:B30,2,FALSE) -> 1 | P22: =(F22+H22+J22+L22+N22) -> 61
A23: SL018 | B23: Guantes Tayrona | D23: Guantes | E23: Buen Precio | F23: =VLOOKUP(E23,'Hoja 3'!A2:B26,2,FALSE) -> 20 | G23: Es considerable | H23: =VLOOKUP(G23,'Hoja 3'!A7:B31,2,FALSE) -> 25 | I23: Anticipado | J23: =VLOOKUP(I23,'Hoja 3'!A7:B31,2,FALSE) -> 5 | K23: Se incluye | L23: =VLOOKUP(K23,'Hoja 3'!A7:B31,2,FALSE) -> 10 | M23: No Aporta Certificado | N23: =VLOOKUP(M23,'Hoja 3'!A7:B31,2,FALSE) -> 1 | P23: =(F23+H23+J23+L23+N23) -> 61
A24: SL019 | B24: Hilos y piolas Jaramillo | D24: Hilos | E24: Buen Precio | F24: =VLOOKUP(E24,'Hoja 3'!A2:B26,2,FALSE) -> 20 | G24: Pronta entrega o inmediata | H24: =VLOOKUP(G24,'Hoja 3'!A2:B26,2,FALSE) -> 30 | I24: 30-60 días | J24: =VLOOKUP(I24,'Hoja 3'!A2:B26,2,FALSE) -> 20 | K24: Se incluye | L24: =VLOOKUP(K24,'Hoja 3'!A2:B26,2,FALSE) -> 10 | M24: Aporta certificado | N24: =VLOOKUP(M24,'Hoja 3'!A2:B26,2,FALSE) -> 10 | P24: =(F24+H24+J24+L24+N24) -> 90
A25: SL020 | B25: Hoyos Galindez Didier | D25: Fertilizantes | E25: Buen Precio | F25: =VLOOKUP(E25,'Hoja 3'!A3:B27,2,FALSE) -> 20 | G25: Pronta entrega o inmediata | H25: =VLOOKUP(G25,'Hoja 3'!A3:B27,2,FALSE) -> 30 | I25: 30-60 días | J25: =VLOOKUP(I25,'Hoja 3'!A3:B27,2,FALSE) -> 20 | K25: Se incluye | L25: =VLOOKUP(K25,'Hoja 3'!A3:B27,2,FALSE) -> 10 | M25: No Aporta Certificado | N25: =VLOOKUP(M25,'Hoja 3'!A3:B27,2,FALSE) -> 1 | P25: =(F25+H25+J25+L25+N25) -> 81
A26: SL021 | B26: Manuchar Colombia | D26: Fertilizantes | E26: Buen Precio | F26: =VLOOKUP(E26,'Hoja 3'!A4:B28,2,FALSE) -> 20 | G26: Es considerable | H26: =VLOOKUP(G26,'Hoja 3'!A4:B28,2,FALSE) -> 25 | I26: 30-60 días | J26: =VLOOKUP(I26,'Hoja 3'!A4:B28,2,FALSE) -> 20 | K26: No se Incluye | L26: =VLOOKUP(K26,'Hoja 3'!A4:B28,2,FALSE) -> 1 | M26: Aporta certificado | N26: =VLOOKUP(M26,'Hoja 3'!A4:B28,2,FALSE) -> 10 | P26: =(F26+H26+J26+L26+N26) -> 76
A27: SL022 | B27: Nino Zea German | D27: Fertilizantes | E27: Muy Alto | F27: =VLOOKUP(E27,'Hoja 3'!A2:B26,2,FALSE) -> 10 | G27: Muy demorado | H27: =VLOOKUP(G27,'Hoja 3'!A5:B29,2,FALSE) -> 5 | I27: 30-60 días | J27: =VLOOKUP(I27,'Hoja 3'!A5:B29,2,FALSE) -> 20 | K27: No se Incluye | L27: =VLOOKUP(K27,'Hoja 3'!A5:B29,2,FALSE) -> 1 | M27: No Aporta Certificado | N27: =VLOOKUP(M27,'Hoja 3'!A5:B29,2,FALSE) -> 1 | P27: =(F27+H27+J27+L27+N27) -> 37
A28: SL023 | B28: Nitrofert | D28: Fertilizantes | E28: Buen Precio | F28: 20 | G28: Es considerable | H28: =VLOOKUP(G28,'Hoja 3'!A6:B30,2,FALSE) -> 25 | I28: 30-60 días | J28: =VLOOKUP(I28,'Hoja 3'!A6:B30,2,FALSE) -> 20 | K28: No se Incluye | L28: =VLOOKUP(K28,'Hoja 3'!A6:B30,2,FALSE) -> 1 | M28: No Aporta Certificado | N28: =VLOOKUP(M28,'Hoja 3'!A6:B30,2,FALSE) -> 1 | P28: =(F28+H28+J28+L28+N28) -> 67
A29: SL024 | B29: Nutricion de plantas | D29: Fertilizantes | E29: Buen Precio | F29: 20 | G29: Es considerable | H29: =VLOOKUP(G29,'Hoja 3'!A7:B31,2,FALSE) -> 25 | I29: 30-60 días | J29: =VLOOKUP(I29,'Hoja 3'!A7:B31,2,FALSE) -> 20 | K29: No se Incluye | L29: =VLOOKUP(K29,'Hoja 3'!A7:B31,2,FALSE) -> 1 | M29: No Aporta Certificado | N29: =VLOOKUP(M29,'Hoja 3'!A7:B31,2,FALSE) -> 1 | P29: =(F29+H29+J29+L29+N29) -> 67
A30: SL025 | B30: Poliplastics | D30: Empaques | E30: Buen Precio | F30: =VLOOKUP(E30,'Hoja 3'!A1:B7,2,FALSE) -> 20 | G30: Muy demorado | H30: =VLOOKUP(G30,'Hoja 3'!A8:B11,2,FALSE) -> 5 | I30: Anticipado | J30: =VLOOKUP(I30,'Hoja 3'!A13:B17,2,FALSE) -> 5 | K30: Se incluye | L30: =VLOOKUP(K30,'Hoja 3'!A8:B32,2,FALSE) -> 10 | M30: Aporta certificado | N30: =VLOOKUP(M30,'Hoja 3'!A8:B32,2,FALSE) -> 10 | P30: =(F30+H30+J30+L30+N30) -> 50
A31: SL026 | B31: Productos quimicos panamericanos | D31: Fertilizantes | E31: Buen Precio | F31: =VLOOKUP(E31,'Hoja 3'!A2:B8,2,FALSE) -> 20 | G31: Es considerable | H31: =VLOOKUP(G31,'Hoja 3'!A9:B33,2,FALSE) -> 25 | I31: 30-60 días | J31: =VLOOKUP(I31,'Hoja 3'!A9:B33,2,FALSE) -> 20 | K31: Se incluye | L31: =VLOOKUP(K31,'Hoja 3'!A9:B33,2,FALSE) -> 10 | M31: Aporta certificado | N31: =VLOOKUP(M31,'Hoja 3'!A9:B33,2,FALSE) -> 10 | P31: =(F31+H31+J31+L31+N31) -> 85
A32: SL027 | B32: Reimpex | D32: Bandas | E32: Buen Precio | F32: =VLOOKUP(E32,'Hoja 3'!A3:B9,2,FALSE) -> 20 | G32: Pronta entrega o inmediata | H32: 30 | I32: Anticipado | J32: =VLOOKUP(I32,'Hoja 3'!A10:B34,2,FALSE) -> 5 | K32: Se incluye | L32: =VLOOKUP(K32,'Hoja 3'!A10:B34,2,FALSE) -> 10 | M32: Aporta certificado | N32: =VLOOKUP(M32,'Hoja 3'!A10:B34,2,FALSE) -> 10 | P32: =(F32+H32+J32+L32+N32) -> 75
A33: SL028 | B33: Sqm Colombia | D33: Fertilizantes | E33: Buen Precio | F33: =VLOOKUP(E33,'Hoja 3'!A4:B10,2,FALSE) -> 20 | G33: Es considerable | H33: 25 | I33: 30-60 días | J33: =VLOOKUP(I33,'Hoja 3'!A11:B35,2,FALSE) -> 20 | K33: No se Incluye | L33: =VLOOKUP(K33,'Hoja 3'!A11:B35,2,FALSE) -> 1 | M33: Aporta certificado | N33: =VLOOKUP(M33,'Hoja 3'!A11:B35,2,FALSE) -> 10 | P33: =(F33+H33+J33+L33+N33) -> 76
A34: SL029 | B34: Saldarriaga Delgado Julian | D34: Fertilizantes | E34: Buen Precio | F34: 20 | G34: Pronta entrega o inmediata | H34: 30 | I34: 30-60 días | J34: =VLOOKUP(I34,'Hoja 3'!A12:B36,2,FALSE) -> 20 | K34: Se incluye | L34: =VLOOKUP(K34,'Hoja 3'!A12:B36,2,FALSE) -> 10 | M34: No Aporta Certificado | N34: =VLOOKUP(M34,'Hoja 3'!A12:B36,2,FALSE) -> 1 | P34: =(F34+H34+J34+L34+N34) -> 81
A35: SL030 | B35: Talanu Chemical | D35: Fertilizantes | E35: Buen Precio | F35: 20 | G35: Es considerable | H35: 25 | I35: Anticipado | J35: =VLOOKUP(I35,'Hoja 3'!A13:B37,2,FALSE) -> 5 | K35: Se incluye | L35: =VLOOKUP(K35,'Hoja 3'!A13:B37,2,FALSE) -> 10 | M35: Aporta certificado | N35: =VLOOKUP(M35,'Hoja 3'!A13:B37,2,FALSE) -> 10 | P35: =(F35+H35+J35+L35+N35) -> 70
A36: SL031 | B36: Yara Colombia | D36: Fertilizantes | E36: Buen Precio | F36: 20 | G36: Pronta entrega o inmediata | H36: 30 | I36: 30-60 días | J36: =VLOOKUP(I36,'Hoja 3'!A14:B38,2,FALSE) -> 20 | K36: Se incluye | L36: =VLOOKUP(K36,'Hoja 3'!A14:B38,2,FALSE) -> 10 | M36: No Aporta Certificado | N36: =VLOOKUP(M36,'Hoja 3'!A14:B38,2,FALSE) -> 1 | P36: =(F36+H36+J36+L36+N36) -> 81
A37: SL032 | B37: Mercadeo | D37: Vinaza | E37: Muy Alto | F37: =VLOOKUP(E37,'Hoja 3'!A2:B7,2,FALSE) -> 10 | G37: Pronta entrega o inmediata | H37: 30 | I37: 30-60 días | J37: =VLOOKUP(I37,'Hoja 3'!A15:B39,2,FALSE) -> 20 | K37: No se Incluye | L37: =VLOOKUP(K37,'Hoja 3'!A15:B39,2,FALSE) -> 1 | M37: Aporta certificado | N37: =VLOOKUP(M37,'Hoja 3'!A15:B39,2,FALSE) -> 10 | P37: =(F37+H37+J37+L37+N37) -> 71
A38: SL033 | B38: Hugo Martinez | D38: Fertilizantes | E38: Buen Precio | F38: =VLOOKUP(E38,'Hoja 3'!A3:B8,2,FALSE) -> 20 | G38: Pronta entrega o inmediata | H38: 30 | I38: 30-60 días | J38: =VLOOKUP(I38,'Hoja 3'!A16:B40,2,FALSE) -> 20 | K38: Se incluye | L38: =VLOOKUP(K38,'Hoja 3'!A16:B40,2,FALSE) -> 10 | M38: No Aporta Certificado | N38: =VLOOKUP(M38,'Hoja 3'!A16:B40,2,FALSE) -> 1 | P38: =(F38+H38+J38+L38+N38) -> 81
A39: SL034 | B39: IMPOSEG INDUSTRIAL S.A.S | D39: Elementos de Protección Personal | E39: Buen Precio | F39: =VLOOKUP(E39,'Hoja 3'!A4:B9,2,FALSE) -> 20 | G39: Pronta entrega o inmediata | H39: =VLOOKUP(G39,'Hoja 3'!A17:B41,2,FALSE) -> #N/A | I39: 30-60 días | J39: =VLOOKUP(I39,'Hoja 3'!A17:B41,2,FALSE) -> #N/A | K39: Se incluye | L39: =VLOOKUP(K39,'Hoja 3'!A17:B41,2,FALSE) -> 10 | M39: No Aporta Certificado | N39: =VLOOKUP(M39,'Hoja 3'!A17:B41,2,FALSE) -> 1 | P39: =(F39+H39+J39+L39+N39) -> #N/A
A40: SL035 | B40: CALZAUNICO S.A.S | D40: Botas Pantaneras de Seguridad | E40: Buen Precio | F40: =VLOOKUP(E40,'Hoja 3'!A5:B10,2,FALSE) -> #N/A | G40: Pronta entrega o inmediata | H40: =VLOOKUP(G40,'Hoja 3'!A18:B42,2,FALSE) -> #N/A | I40: Anticipado | J40: =VLOOKUP(I40,'Hoja 3'!A18:B42,2,FALSE) -> #N/A | K40: Se incluye | L40: =VLOOKUP(K40,'Hoja 3'!A18:B42,2,FALSE) -> 10 | M40: No Aporta Certificado | N40: =VLOOKUP(M40,'Hoja 3'!A18:B42,2,FALSE) -> 1 | P40: =(F40+H40+J40+L40+N40) -> #N/A
A41: SL036 | B41: CBCOL SEGURIDAD INDUSTRIAL S.A.S | D41: Guantes | E41: Buen Precio | F41: =VLOOKUP(E41,'Hoja 3'!A6:B11,2,FALSE) -> #N/A | G41: Pronta entrega o inmediata | H41: =VLOOKUP(G41,'Hoja 3'!A19:B43,2,FALSE) -> #N/A | I41: Anticipado | J41: =VLOOKUP(I41,'Hoja 3'!A19:B43,2,FALSE) -> #N/A | K41: Se incluye | L41: =VLOOKUP(K41,'Hoja 3'!A19:B43,2,FALSE) -> 10 | M41: No Aporta Certificado | N41: =VLOOKUP(M41,'Hoja 3'!A19:B43,2,FALSE) -> 1 | P41: =(F41+H41+J41+L41+N41) -> #N/A
...

Sheet Hoja 3
A2: PRECIO | E2: 20 | F2: 30 | G2: 30 | H2: 10 | I2: 10
A3: Muy Alto | B3: 10 | E3: PRECIO | F3: TIEMPOS DE ENTREGA | G3: FORMA DE PAGO | H3: TRANSPORTE | I3: SGSST
A4: Buen Precio | B4: 20
A5: Bajo pero confiable | B5: 20
A6: Bajo y sospechoso | B6: 5
A7: Seleccione | B7: 0
A8: TIEMPOS DE ENTREGA
A9: Pronta entrega o inmediata | B9: 30
A10: Es considerable | B10: 25
A11: Muy demorado | B11: 5
A13: FORMA DE PAGO
A14: Anticipado | B14: 5
A15: Contraentrega | B15: 10
A16: 30-60 días | B16: 20
A17: Más de 60 dias | B17: 30
A19: TRANSPORTE
A20: Se incluye | B20: 10
A21: No se Incluye | B21: 1
A22: No se requiere | B22: 10
A24: SGSST
A25: Aporta certificado | B25: 10
A26: No Aporta Certificado | B26: 1
